Workbook

Sheet 외화예금일일가이드라인

Sheet 승인절차
B2: ■ 외화예금 금리승인 절차
B4: 1 | C4: 신청 세부내용 확인
C5: 고시금리 · 가산금리 · 최종금리 · 상품 · 기간 등 확인
B7: 2 | C7: 결재자 배정
C8: 1차 결재자 체크 → 부장님 체크 → 후결 체크
B10: 3 | C10: 심사의견 작성
C11: 승인조건 및 심사의견 작성 후 [심사의견 저장]
B13: 4 | C13: 결재
C14: 우측 상단 [결재] → [승인] 클릭 (※ "승인완료"가 아니라 "승인")
B16: 반려하는 경우 : [결재] → [불승인] 클릭
B18: 참고 ▸ 우대금리 승인권자 : 1백만불 미만 = 외환사업부장 / 1백만불 이상 = 자금부장

Sheet (1)규정
B2: 외화예금 금리승인 핵심 규정 (담당자용)
B3: 출처 : 내규 ▸ 국제금융/외국환 ▸ 외국환업무지침 제8장 외화예금 / 전반관리 ▸ 종합수익관리지침
B5: 1. 우대금리 승인권자
B6: 기본이율보다 우대하여 적용할 경우 주무부서장 승인을 받아 적용. (외화종합통장 우대이율과 중복 시 높은 이율 하나만 적용)
B7: · 원금 미화 1백만불 상당액 미만 → 외환사업부장
B8: · 원금 미화 1백만불 상당액 이상 → 자금부장
B9: ※ 기본이율 조회 : 넥스피아 7452 (금리주요정보조회)
B11: 2. 지급준비율
B12: · 만기 1개월 이상 외화정기예금 / 만기 30일 이상 외화CD(양도성예금증서) / 만기 6개월 이상 외화정기적금 → 2%
B13: · 기타예금 → 7%
B15: 3. 외화 내부금리 · 자금마진 (자금원가 산정 기준)
B16: · 대표시장금리 : LIBOR 산출 중단(2021~2023)으로 통화별 무위험지표금리(RFR)로 전환
... B28: · 중도해지 : 내부금리 재적용하지 않음 (중도해지수수료·이자차는 국제금융부 귀속)

Sheet (1)예금승인내역
B1: ※ 금리협의시 기준
B2: 1. 외화MMDA | F2: 2. 외화정기예금
B3: (1) ~1주 또는 통지예금 금리 참조하여 협의 | F3: (1) 3개월 이하 : 금리부운용(콜론) vs 비금리부운용(스왑) 비교 (단, 외화제규제비율 및 NIM감안)
F4: (2) 3개월 초과 : 되도록 금리부운용(대여금)으로 매칭
X5: 0.001776
G6: 상세내역 | M6: 외부 참조금리 | V6: 내부 참조금리 | AE6: 승인정보 | AL6: 메모란
I7: 기간 | M7: 타행외화예금금리 | O7: 은행간 운용금리 | V7: 종합수익관리시스템 | Z7: 비용 | AB7: BEP금리
A8: 순번 | B8: 상담일자 | C8: 영업점 | D8: 지점장 | E8: 담당자 | F8: 고객 | G8: 시작일자 | H8: 만기일자 | I8: 일수 | J8: 월수 | K8: 예금종류 | L8: 통화/금액 | M8: 평균 | N8: 최대(은행) | O8: Tenor | P8: SOFR | Q8: LIBOR | R8: 이자(MM) | T8: 비이자(FXSWAP) | V8: 내부금리 | W8: 지준비용 | X8: 자금마진 | Y8: 고시금리 | Z8: 자금원가 | AA8: NIS | AB8: 이자운용 | AC8: 비이자운용 | AD8: 협의금리 | AE8: 고시금리 | AF8: 우대금리 | AG8: 승인금리 | AH8: 승인일자 | AI8: 신청번호 | AJ8: 여부 | AK8: 매칭 운용거래 (비이자 / 이자)
A10: 1 | B10: 42583 | C10: 여의도지점 | D10: 계장 조수현 | F10: 키움자산운용 | G10: 42583 | H10: 42674 | I10: =H10-G10 -> 91 | J10: =TRUNC(I10/30,0) -> 3 | L10: 4 | Q10: 0.007591 | S10: 0.0084 | Y10: 0.005314 | AD10: 0.0065 | AE10: =IF(Y10="","",Y10) -> 0.005314 | AG10: =IF(AF10="","",AE10+AF10) | AJ10: =IF(AG10="","N","Y") -> N
A11: =IF(B11="","",IF((YEAR(B11)-YEAR(B10))=0,A10+1,1)) -> 2 | B11: 42586 | C11: 포항공단점 | D11: 계장 배인영 | F11: 개인 | G11: 42586 | H11: 42678 | I11: =H11-G11 -> 92 | J11: =TRUNC(I11/30,0) -> 3 | K11: 정기예금 | L11: 2.5 | Q11: 0.007776 | S11: 0.0084 | Y11: 0.005495 | AD11: 0.0065 | AE11: =IF(Y11="","",Y11) -> 0.005495 | AF11: 0.001505 | AG11: =IF(AF11="","",AE11+AF11) -> 0.007 | AJ11: =IF(AG11="","N","Y") -> Y
A12: =IF(B12="","",IF((YEAR(B12)-YEAR(B11))=0,A11+1,1)) -> 3 | B12: 42587 | C12: 강남영업부 | D12: 과장 이진아 | F12: 한전 | G12: 42587 | H12: 42618 | I12: =H12-G12 -> 31 | J12: =TRUNC(I12/30,0) -> 1 | K12: MMDA | L12: 50 | Q12: 0.005039 | S12: 0.0055 | Y12: 0.002359 | AD12: 0.0043 | AE12: =IF(Y12="","",Y12) -> 0.002359 | AG12: =IF(AF12="","",AE12+AF12) | AJ12: =IF(AG12="","N","Y") -> N
A13: =IF(B13="","",IF((YEAR(B13)-YEAR(B12))=0,A12+1,1)) -> 4 | B13: 42590 | C13: 울산영업부 | D13: 차장 김정인 | F13: 석유공사 | G13: 42590 | H13: 42654 | I13: =H13-G13 -> 64 | J13: =TRUNC(I13/30,0) -> 2 | K13: 정기예금 | L13: 55 | Q13: 0.006148 | S13: =AVERAGE(0.0064,0.009,0.007) -> 0.0074666667 | Y13: 0.003475 | AD13: 0.0038 | AE13: =IF(Y13="","",Y13) -> 0.003475 | AG13: =IF(AF13="","",AE13+AF13) | AJ13: =IF(AG13="","N","Y") -> N
A14: =IF(B14="","",IF((YEAR(B14)-YEAR(B13))=0,A13+1,1)) -> 5 | B14: 42593 | C14: 울산영업부 | D14: 차장 김정인 | F14: 석유공사 | G14: 42593 | H14: 42641 | I14: =H14-G14 -> 48 | J14: =TRUNC(I14/30,0) -> 1 | K14: 정기예금 | L14: 28 | Q14: 0.0051765 | S14: =AVERAGE(0.0064,0.0085,0.0058) -> 0.0069 | Y14: 0.002547 | AD14: 0.0035 | AE14: =IF(Y14="","",Y14) -> 0.002547 | AG14: =IF(AF14="","",AE14+AF14) | AJ14: =IF(AG14="","N","Y") -> N
A15: =IF(B15="","",IF((YEAR(B15)-YEAR(B14))=0,A14+1,1)) -> 6 | B15: 42606 | C15: 울산영업부 | D15: 차장 김정인 | F15: 석유공사 | G15: 42606 | H15: 42639 | I15: =H15-G15 -> 33 | J15: =TRUNC(I15/30,0) -> 1 | K15: 정기예금 | L15: 60 | Q15: 0.0052439 | S15: =AVERAGE(0.0076,0.008,0.0058) -> 0.0071333333 | Y15: 0.002614 | AD15: 0.004 | AE15: =IF(Y15="","",Y15) -> 0.002614 | AF15: 0.001386 | AG15: =IF(AF15="","",AE15+AF15) -> 0.004 | AJ15: =IF(AG15="","N","Y") -> Y
A16: =IF(B16="","",IF((YEAR(B16)-YEAR(B15))=0,A15+1,1)) -> 7 | B16: 42612 | C16: 강남영업부 | D16: 과장 이진아 | F16: 한전 | G16: 42612 | H16: 42643 | I16: =H16-G16 -> 31 | J16: =TRUNC(I16/30,0) -> 1 | K16: MMDA | L16: 50 | Q16: 0.0052439 | S16: =AVERAGE(0.007,0.0051,0.0058) -> 0.0059666667 | Y16: 0.000852 | AD16: 0.0045 | AE16: =IF(Y16="","",Y16) -> 0.000852 | AG16: =IF(AF16="","",AE16+AF16) | AJ16: =IF(AG16="","N","Y") -> N
A17: =IF(B17="","",IF((YEAR(B17)-YEAR(B16))=0,A16+1,1)) -> 8 | B17: 42612 | C17: 울산영업부 | D17: 차장 김정인 | F17: 석유공사 | G17: 42612 | H17: 42661 | I17: =H17-G17 -> 49 | J17: =TRUNC(I17/30,0) -> 1 | K17: 정기예금 | L17: 40 | Q17: 0.0052439 | S17: =AVERAGE(0.007,0.0051,0.0058) -> 0.0059666667 | Y17: 0.002614 | AD17: 0.0036 | AE17: =IF(Y17="","",Y17) -> 0.002614 | AG17: =IF(AF17="","",AE17+AF17) | AJ17: =IF(AG17="","N","Y") -> N
A18: =IF(B18="","",IF((YEAR(B18)-YEAR(B17))=0,A17+1,1)) -> 9 | B18: 42618 | C18: 서울영업부 | D18: 차장 이순정 | F18: 현대중공업 | G18: 42618 | H18: 42648 | I18: =H18-G18 -> 30 | J18: =TRUNC(I18/30,0) -> 1 | K18: MMDA | L18: 50 | Q18: 0.0052572 | S18: 0.0046 | Y18: 0.000857 | AD18: 0.004 | AE18: =IF(Y18="","",Y18) -> 0.000857 | AG18: =IF(AF18="","",AE18+AF18) | AJ18: =IF(AG18="","N","Y") -> N
A19: =IF(B19="","",IF((YEAR(B19)-YEAR(B18))=0,A18+1,1)) -> 10 | B19: 42620 | C19: 울산영업부 | D19: 계장 고재희 | F19: 석유공사 | G19: 42620 | H19: 42670 | I19: =H19-G19 -> 50 | J19: =TRUNC(I19/30,0) -> 1 | K19: 정기예금 | L19: 90 | Q19: 0.0051656 | S19: 0.005 | Y19: 0.002573 | AD19: 0.0035 | AE19: =IF(Y19="","",Y19) -> 0.002573 | AG19: =IF(AF19="","",AE19+AF19) | AJ19: =IF(AG19="","N","Y") -> N
A20: =IF(B20="","",IF((YEAR(B20)-YEAR(B19))=0,A19+1,1)) -> 11 | B20: 42620 | C20: 성서지점 | D20: 차장 이민 | F20: 법인고객 | G20: 42620 | H20: 42985 | I20: =H20-G20 -> 365 | J20: =TRUNC(I20/30,0) -> 12 | K20: 정기예금 | L20: 2 | Q20: 0.009825 | S20: =AVERAGE(0.0145,0.015,0.013) -> 0.014166667 | Y20: 0.009825 | AD20: 0.0115 | AE20: =IF(Y20="","",Y20) -> 0.009825 | AG20: =IF(AF20="","",AE20+AF20) | AJ20: =IF(AG20="","N","Y") -> N
A21: =IF(B21="","",IF((YEAR(B21)-YEAR(B20))=0,A20+1,1)) -> 12 | B21: 42622 | C21: 울산영업부 | D21: 차장 김정인 | F21: 석유공사 | G21: 42622 | H21: 42652 | I21: =H21-G21 -> 30 | J21: =TRUNC(I21/30,0) -> 1 | K21: MMDA | L21: 0 | Q21: 0.0042211 | S21: =AVERAGE(0.0045,0.0046,0.0047) -> 0.0046 | Y21: 0.000878 | AD21: 0.0025 | AE21: =IF(Y21="","",Y21) -> 0.000878 | AG21: =IF(AF21="","",AE21+AF21) | AJ21: =IF(AG21="","N","Y") -> N
A22: =IF(B22="","",IF((YEAR(B22)-YEAR(B21))=0,A21+1,1)) -> 13 | B22: 42622 | C22: 〃 | D22: 〃 | F22: 〃 | G22: 42622 | H22: 42652 | I22: =H22-G22 -> 30 | J22: =TRUNC(I22/30,0) -> 1 | K22: 정기예금 | L22: 0 | Q22: 0.0051822 | S22: =AVERAGE(0.007,0.0075) -> 0.00725 | Y22: 0.002553 | AD22: 0.0035 | AE22: =IF(Y22="","",Y22) -> 0.002553 | AG22: =IF(AF22="","",AE22+AF22) | AJ22: =IF(AG22="","N","Y") -> N
A23: =IF(B23="","",IF((YEAR(B23)-YEAR(B22))=0,A22+1,1)) -> 14 | B23: 42622 | C23: 〃 | D23: 〃 | F23: 〃 | G23: 42622 | H23: 42683 | I23: =H23-G23 -> 61 | J23: =TRUNC(I23/30,0) -> 2 | K23: 정기예금 | L23: 0 | Q23: 0.0066467 | S23: =AVERAGE(0.0077,0.0082) -> 0.00795 | Y23: 0.003988 | AD23: 0.0045 | AE23: =IF(Y23="","",Y23) -> 0.003988 | AG23: =IF(AF23="","",AE23+AF23) | AJ23: =IF(AG23="","N","Y") -> N
A24: =IF(B24="","",IF((YEAR(B24)-YEAR(B23))=0,A23+1,1)) -> 15 | B24: 42622 | C24: 〃 | D24: 〃 | F24: 〃 | G24: 42622 | H24: 42713 | I24: =H24-G24 -> 91 | J24: =TRUNC(I24/30,0) -> 3 | K24: 정기예금 | L24: 0 | Q24: 0.0084544 | S24: =AVERAGE(0.0115,0.0088,0.012) -> 0.010766667 | Y24: 0.00616 | AD24: 0.0067 | AE24: =IF(Y24="","",Y24) -> 0.00616 | AG24: =IF(AF24="","",AE24+AF24) | AJ24: =IF(AG24="","N","Y") -> N
A25: =IF(B25="","",IF((YEAR(B25)-YEAR(B24))=0,A24+1,1)) -> 16 | B25: 42622 | C25: 〃 | D25: 〃 | F25: 〃 | G25: 42622 | H25: 42803 | I25: =H25-G25 -> 181 | J25: =TRUNC(I25/30,0) -> 6 | K25: 정기예금 | L25: 0 | Q25: 0.0123472 | S25: =AVERAGE(0.0129,0.0116,0.0112) -> 0.0119 | Y25: 0.009675 | AD25: 0.01 | AE25: =IF(Y25="","",Y25) -> 0.009675 | AG25: =IF(AF25="","",AE25+AF25) | AJ25: =IF(AG25="","N","Y") -> N
A26: =IF(B26="","",IF((YEAR(B26)-YEAR(B25))=0,A25+1,1)) -> 17 | B26: 42634 | C26: 울산영업부 | D26: 차장 김정인 | F26: 석유공사 | G26: 42634 | H26: 42670 | I26: =H26-G26 -> 36 | J26: =TRUNC(I26/30,0) -> 1 | K26: 정기예금 | L26: 80 | Q26: 0.0054306 | S26: =AVERAGE(0.0065,0.0057,0.004) -> 0.0054 | Y26: 0.002796 | AD26: 0.0035 | AE26: =IF(Y26="","",Y26) -> 0.002796 | AG26: =IF(AF26="","",AE26+AF26) | AJ26: =IF(AG26="","N","Y") -> N
A27: =IF(B27="","",IF((YEAR(B27)-YEAR(B26))=0,A26+1,1)) -> 18 | B27: 42636 | C27: 강남영업부 | D27: 과장 이진아 | F27: 한전 | G27: 42636 | H27: 42666 | I27: =H27-G27 -> 30 | J27: =TRUNC(I27/30,0) -> 1 | K27: MMDA | L27: 50 | Q27: 0.0042322 | S27: =AVERAGE(0.0065,0.0057,0.004) -> 0.0054 | Y27: 0.000977 | AD27: 0.0047 | AE27: =IF(Y27="","",Y27) -> 0.000977 | AG27: =IF(AF27="","",AE27+AF27) | AJ27: =IF(AG27="","N","Y") -> N
A28: =IF(B28="","",IF((YEAR(B28)-YEAR(B27))=0,A27+1,1)) -> 19 | B28: 42649 | C28: 강남영업부 | D28: 차장 황수덕 | F28: SK하이닉스 | G28: 42649 | H28: 42680 | I28: =H28-G28 -> 31 | J28: =TRUNC(I28/30,0) -> 1 | K28: MMDA | L28: 50 | Q28: 0.0042822 | Y28: 0.000977 | AE28: =IF(Y28="","",Y28) -> 0.000977 | AG28: =IF(AF28="","",AE28+AF28) | AJ28: =IF(AG28="","N","Y") -> N
A29: =IF(B29="","",IF((YEAR(B29)-YEAR(B28))=0,A28+1,1)) -> 20 | B29: 42649 | C29: 성서지점 | D29: 대리 홍지현 | F29: 법인고객 | G29: 42649 | H29: 43014 | I29: =H29-G29 -> 365 | J29: =TRUNC(I29/30,0) -> 12 | K29: 정기예금 | L29: 2 | Q29: 0.0157267 | S29: =AVERAGE(0.015,0.014,0.0135) -> 0.014166667 | Y29: 0.011434 | AD29: 0.0125 | AE29: =IF(Y29="","",Y29) -> 0.011434 | AG29: =IF(AF29="","",AE29+AF29) | AJ29: =IF(AG29="","N","Y") -> N
A30: =IF(B30="","",IF((YEAR(B30)-YEAR(B29))=0,A29+1,1)) -> 21 | B30: 42650 | C30: 성서지점 | D30: 행원 이현경 | F30: ㈜나인플러스 | G30: 42650 | H30: 42742 | I30: =H30-G30 -> 92 | J30: =TRUNC(I30/30,0) -> 3 | K30: 정기예금 | L30: 1 | Q30: 0.0087156 | S30: =AVERAGE(0.0115,0.011,0.0089) -> 0.010466667 | Y30: 0.0064 | AD30: 0.007 | AE30: =IF(Y30="","",Y30) -> 0.0064 | AG30: 0.0071 | AJ30: =IF(AG30="","N","Y") -> Y
A31: =IF(B31="","",IF((YEAR(B31)-YEAR(B30))=0,A30+1,1)) -> 22 | B31: 42661 | C31: 울산영업부 | D31: 차장 김정인 | F31: 석유공사 | G31: 42661 | H31: 42695 | I31: =H31-G31 -> 34 | J31: =TRUNC(I31/30,0) -> 1 | K31: 정기예금 | L31: 70 | Q31: 0.0052789 | S31: =AVERAGE(0.0077,0.008) -> 0.00785 | Y31: 0.002647 | AD31: 0.0036 | AE31: =IF(Y31="","",Y31) -> 0.002647 | AJ31: =IF(AG31="","N","Y") -> N
A32: =IF(B32="","",IF((YEAR(B32)-YEAR(B31))=0,A31+1,1)) -> 23 | B32: 42668 | C32: 울산영업부 | D32: 차장 김정인 | F32: 석유공사 | G32: 42668 | H32: 42684 | I32: =H32-G32 -> 16 | J32: =TRUNC(I32/30,0) -> 0 | K32: 정기예금 | L32: 45 | Q32: 0.0045589 | S32: =AVERAGE(0.006,0.005) -> 0.0055 | Y32: 0.001577 | AD32: 0.002 | AE32: =IF(Y32="","",Y32) -> 0.001577 | AJ32: =IF(AG32="","N","Y") -> N
A33: =IF(B33="","",IF((YEAR(B33)-YEAR(B32))=0,A32+1,1)) -> 24 | B33: 42668 | C33: 〃 | D33: 〃 | F33: 〃 | G33: 42668 | H33: 42690 | I33: =H33-G33 -> 22 | J33: =TRUNC(I33/30,0) -> 0 | K33: 〃 | L33: 35 | Q33: 0.0045589 | S33: =AVERAGE(0.006,0.005) -> 0.0055 | Y33: 0.001577 | AD33: 0.002 | AE33: =IF(Y33="","",Y33) -> 0.001577 | AJ33: =IF(AG33="","N","Y") -> N
A34: =IF(B34="","",IF((YEAR(B34)-YEAR(B33))=0,A33+1,1)) -> 25 | B34: 42668 | C34: 〃 | D34: 〃 | F34: 〃 | G34: 42668 | H34: 42704 | I34: =H34-G34 -> 36 | J34: =TRUNC(I34/30,0) -> 1 | K34: 〃 | L34: 70 | Q34: 0.00534 | S34: =AVERAGE(0.0058,0.0065) -> 0.00615 | Y34: 0.002708 | AD34: 0.004 | AE34: =IF(Y34="","",Y34) -> 0.002708 | AG34: 0.004 | AJ34: =IF(AG34="","N","Y") -> Y
A35: =IF(B35="","",IF((YEAR(B35)-YEAR(B34))=0,A34+1,1)) -> 26 | B35: 42678 | C35: 〃 | D35: 〃 | F35: 〃 | G35: 42678 | H35: 42711 | I35: =H35-G35 -> 33 | J35: =TRUNC(I35/30,0) -> 1 | K35: 〃 | L35: 20 | Q35: 0.0053256 | AD35: 0.0036 | AE35: =IF(Y35="","",Y35) | AG35: 0 | AJ35: =IF(AG35="","N","Y") -> Y
A36: =IF(B36="","",IF((YEAR(B36)-YEAR(B35))=0,A35+1,1)) -> 27 | B36: 42678 | C36: 〃 | D36: 〃 | F36: 〃 | G36: 42678 | H36: 42711 | I36: =H36-G36 -> 33 | J36: =TRUNC(I36/30,0) -> 1 | K36: 〃 | L36: 30 | Q36: 0.0053256 | AD36: 0.0036 | AE36: =IF(Y36="","",Y36) | AJ36: =IF(AG36="","N","Y") -> N
A37: =IF(B37="","",IF((YEAR(B37)-YEAR(B36))=0,A36+1,1)) -> 28 | B37: 42682 | C37: 반월공단지점 | D37: 대리 김수현 | F37: ㈜이수엑사켐 | G37: 42682 | H37: 42725 | I37: =H37-G37 -> 43 | J37: =TRUNC(I37/30,0) -> 1 | K37: 〃 | L37: 7 | Q37: 0.0053533 | S37: =AVERAGE(0.0058,0.0065) -> 0.00615 | Y37: 0.002721 | AD37: 0.0036 | AE37: =IF(Y37="","",Y37) -> 0.002721 | AG37: 0.0036 | AJ37: =IF(AG37="","N","Y") -> Y
A38: =IF(B38="","",IF((YEAR(B38)-YEAR(B37))=0,A37+1,1)) -> 29 | B38: 42690 | C38: 울산영업부 | D38: 차장 김정인 | F38: 석유공사 | G38: 42690 | H38: 42718 | I38: =H38-G38 -> 28 | J38: =TRUNC(I38/30,0) -> 0 | K38: 〃 | L38: 30 | Q38: 0.0055011 | S38: =AVERAGE(0.0055,0.006) -> 0.00575 | Y38: 0.001605 | AD38: 0.0029 | AE38: =IF(Y38="","",Y38) -> 0.001605 | AJ38: =IF(AG38="","N","Y") -> N
A39: =IF(B39="","",IF((YEAR(B39)-YEAR(B38))=0,A38+1,1)) -> 30 | B39: 42695 | C39: 울산영업부 | D39: 차장 김정인 | F39: 석유공사 | G39: 42695 | H39: 42726 | I39: =H39-G39 -> 31 | J39: =TRUNC(I39/30,0) -> 1 | K39: 〃 | L39: 60 | Q39: 0.00566 | S39: =AVERAGE(0.0055,0.006) -> 0.00575 | Y39: 0.003021 | AD39: 0.0039 | AE39: =IF(Y39="","",Y39) -> 0.003021 | AJ39: =IF(AG39="","N","Y") -> N
A40: =IF(B40="","",IF((YEAR(B40)-YEAR(B39))=0,A39+1,1)) -> 31 | B40: 42702 | C40: 울산영업부 | D40: 차장 김정인 | F40: 석유공사 | G40: 42702 | H40: 42718 | I40: =H40-G40 -> 16 | J40: =TRUNC(I40/30,0) -> 0 | K40: 〃 | L40: 30 | Q40: 0.0045822 | S40: =AVERAGE(0.0052,0.0058,0.0051) -> 0.0053666667 | Y40: 0.001598 | AD40: 0.0026 | AE40: =IF(Y40="","",Y40) -> 0.001598 | AJ40: =IF(AG40="","N","Y") -> N
A41: =IF(B41="","",IF((YEAR(B41)-YEAR(B40))=0,A40+1,1)) -> 32 | B41: 42702 | C41: 울산영업부 | D41: 차장 김정인 | F41: 석유공사 | G41: 42702 | H41: 42724 | I41: =H41-G41 -> 22 | J41: =TRUNC(I41/30,0) -> 0 | K41: 〃 | L41: 50 | Q41: 0.0045822 | S41: =AVERAGE(0.0052,0.0058,0.0054) -> 0.0054666667 | Y41: 0.001598 | AD41: 0.003 | AE41: =IF(Y41="","",Y41) -> 0.001598 | AJ41: =IF(AG41="","N","Y") -> N
...

Sheet 예금만기도래
A1: ■ 외화예금 만기도래 현황 (기준일 ~ +10일)
A2: 기준일 | B2: =TODAY() -> 46189 | D2: ←날짜 직접 입력시 해당일 기준 조회 | G2: 총 건수 | H2: =COUNT($Y$6:$Y$85) -> 11 | I2: 합계(백만불) | J2: =SUM($I$6:$I$85) -> 51.24
A3: 조회기간 | B3: =TEXT(B2,"yyyy-mm-dd")&" ~ "&TEXT(B2+10,"yyyy-mm-dd") -> 2026-06-16 ~ 2026-06-26 | G3: 10백만불↑ | H3: =COUNTIF($I$6:$I$85,">=10") -> 2
A5: 구분 | B5: 만기일 | C5: 요일 | D5: 시작일 | E5: 업체명 | F5: 영업점 | G5: 예금종류 | H5: 통화 | I5: 금액(백만불) | J5: 승인금리 | K5: 자금마진 | L5: 비고
A6: =IF($Y6="","",IF(INDEX($N$6:$N$1005,$Y6)=$B$2,"오늘","+"&(INDEX($N$6:$N$1005,$Y6)-$B$2)&"일")) -> 오늘 | B6: =IF($Y6="","",INDEX($N$6:$N$1005,$Y6)) -> 46189 | C6: =IF($Y6="","",CHOOSE(WEEKDAY(INDEX($N$6:$N$1005,$Y6)),"일","월","화","수","목","금","토")) -> 화 | D6: =IF($Y6="","",INDEX($O$6:$O$1005,$Y6)) -> 46097 | E6: =IF($Y6="","",INDEX($P$6:$P$1005,$Y6)) -> ㈜ 동아홀딩스 | F6: =IF($Y6="","",INDEX($Q$6:$Q$1005,$Y6)) -> 달성공단영업부 | G6: =IF($Y6="","",INDEX($R$6:$R$1005,$Y6)) -> 정기예금 | H6: =IF($Y6="","","USD") -> USD | I6: =IF($Y6="","",INDEX($S$6:$S$1005,$Y6)) -> 2.19 | J6: =IF($Y6="","",INDEX($T$6:$T$1005,$Y6)) -> 0.036 | K6: =IF($Y6="","",INDEX($U$6:$U$1005,$Y6)) -> 0.00264 | L6: =IF($Y6="","",IF(INDEX($S$6:$S$1005,$Y6)>=10,"★ 10백만불↑","")) | N6: =IF('(1)예금승인내역'!H632="","",'(1)예금승인내역'!H632) -> 45313 | O6: =IF('(1)예금승인내역'!G632="","",'(1)예금승인내역'!G632) -> 45280 | P6: =IF('(1)예금승인내역'!F632="","",'(1)예금승인내역'!F632) -> 주식회사 한국비앤씨 | Q6: =IF('(1)예금승인내역'!C632="","",'(1)예금승인내역'!C632) -> 성서영업부 | R6: =IF('(1)예금승인내역'!K632="","",'(1)예금승인내역'!K632) -> 정기예금 | S6: =IF('(1)예금승인내역'!L632="","",'(1)예금승인내역'!L632) -> 5 | T6: =IF('(1)예금승인내역'!AG632="","",'(1)예금승인내역'!AG632) -> 0.0525 | U6: =IF('(1)예금승인내역'!X632="","",'(1)예금승인내역'!X632) -> 0.002275 | V6: =IF(ISNUMBER(N6),N6-$B$2,"") -> -876 | W6: =IF(AND(ISNUMBER(N6),N6>=$B$2,N6<=$B$2+10),N6*100000+ROW(),"") | X6: =IFERROR(SMALL($W$6:$W$1005,1),"") -> 4618900541 | Y6: =IF(X6="","",MATCH(X6,$W$6:$W$1005,0)) -> 536
A7: =IF($Y7="","",IF(INDEX($N$6:$N$1005,$Y7)=$B$2,"오늘","+"&(INDEX($N$6:$N$1005,$Y7)-$B$2)&"일")) -> 오늘 | B7: =IF($Y7="","",INDEX($N$6:$N$1005,$Y7)) -> 46189 | C7: =IF($Y7="","",CHOOSE(WEEKDAY(INDEX($N$6:$N$1005,$Y7)),"일","월","화","수","목","금","토")) -> 화 | D7: =IF($Y7="","",INDEX($O$6:$O$1005,$Y7)) -> 46097 | E7: =IF($Y7="","",INDEX($P$6:$P$1005,$Y7)) -> 해내다컨트리클럽 | F7: =IF($Y7="","",INDEX($Q$6:$Q$1005,$Y7)) -> 달성공단영업부 | G7: =IF($Y7="","",INDEX($R$6:$R$1005,$Y7)) -> 정기예금 | H7: =IF($Y7="","","USD") -> USD | I7: =IF($Y7="","",INDEX($S$6:$S$1005,$Y7)) -> 3.65 | J7: =IF($Y7="","",INDEX($T$6:$T$1005,$Y7)) -> 0.036 | K7: =IF($Y7="","",INDEX($U$6:$U$1005,$Y7)) -> 0.00264 | L7: =IF($Y7="","",IF(INDEX($S$6:$S$1005,$Y7)>=10,"★ 10백만불↑","")) | N7: =IF('(1)예금승인내역'!H633="","",'(1)예금승인내역'!H633) -> 45313 | O7: =IF('(1)예금승인내역'!G633="","",'(1)예금승인내역'!G633) -> 45280 | P7: =IF('(1)예금승인내역'!F633="","",'(1)예금승인내역'!F633) -> 주식회사 한국비앤씨 | Q7: =IF('(1)예금승인내역'!C633="","",'(1)예금승인내역'!C633) -> 성서영업부 | R7: =IF('(1)예금승인내역'!K633="","",'(1)예금승인내역'!K633) -> 정기예금 | S7: =IF('(1)예금승인내역'!L633="","",'(1)예금승인내역'!L633) -> 5 | T7: =IF('(1)예금승인내역'!AG633="","",'(1)예금승인내역'!AG633) -> 0.0525 | U7: =IF('(1)예금승인내역'!X633="","",'(1)예금승인내역'!X633) -> 0.002275 | V7: =IF(ISNUMBER(N7),N7-$B$2,"") -> -876 | W7: =IF(AND(ISNUMBER(N7),N7>=$B$2,N7<=$B$2+10),N7*100000+ROW(),"") | X7: =IFERROR(SMALL($W$6:$W$1005,2),"") -> 4618900542 | Y7: =IF(X7="","",MATCH(X7,$W$6:$W$1005,0)) -> 537
A8: =IF($Y8="","",IF(INDEX($N$6:$N$1005,$Y8)=$B$2,"오늘","+"&(INDEX($N$6:$N$1005,$Y8)-$B$2)&"일")) -> 오늘 | B8: =IF($Y8="","",INDEX($N$6:$N$1005,$Y8)) -> 46189 | C8: =IF($Y8="","",CHOOSE(WEEKDAY(INDEX($N$6:$N$1005,$Y8)),"일","월","화","수","목","금","토")) -> 화 | D8: =IF($Y8="","",INDEX($O$6:$O$1005,$Y8)) -> 46097 | E8: =IF($Y8="","",INDEX($P$6:$P$1005,$Y8)) -> 거림테크주식회사 | F8: =IF($Y8="","",INDEX($Q$6:$Q$1005,$Y8)) -> 죽전지점 | G8: =IF($Y8="","",INDEX($R$6:$R$1005,$Y8)) -> 정기예금 | H8: =IF($Y8="","","USD") -> USD | I8: =IF($Y8="","",INDEX($S$6:$S$1005,$Y8)) -> 2 | J8: =IF($Y8="","",INDEX($T$6:$T$1005,$Y8)) -> 0.0365 | K8: =IF($Y8="","",INDEX($U$6:$U$1005,$Y8)) -> 0.00214 | L8: =IF($Y8="","",IF(INDEX($S$6:$S$1005,$Y8)>=10,"★ 10백만불↑","")) | N8: =IF('(1)예금승인내역'!H634="","",'(1)예금승인내역'!H634) -> 45313 | O8: =IF('(1)예금승인내역'!G634="","",'(1)예금승인내역'!G634) -> 45280 | P8: =IF('(1)예금승인내역'!F634="","",'(1)예금승인내역'!F634) -> ㈜대우로지스틱스 | Q8: =IF('(1)예금승인내역'!C634="","",'(1)예금승인내역'!C634) -> 사상공단영업부 | R8: =IF('(1)예금승인내역'!K634="","",'(1)예금승인내역'!K634) -> MMDA | S8: =IF('(1)예금승인내역'!L634="","",'(1)예금승인내역'!L634) -> 1 | T8: =IF('(1)예금승인내역'!AG634="","",'(1)예금승인내역'!AG634) -> 0.0435 | U8: =IF('(1)예금승인내역'!X634="","",'(1)예금승인내역'!X634) -> 0.009148 | V8: =IF(ISNUMBER(N8),N8-$B$2,"") -> -876 | W8: =IF(AND(ISNUMBER(N8),N8>=$B$2,N8<=$B$2+10),N8*100000+ROW(),"") | X8: =IFERROR(SMALL($W$6:$W$1005,3),"") -> 4618900543 | Y8: =IF(X8="","",MATCH(X8,$W$6:$W$1005,0)) -> 538
A9: =IF($Y9="","",IF(INDEX($N$6:$N$1005,$Y9)=$B$2,"오늘","+"&(INDEX($N$6:$N$1005,$Y9)-$B$2)&"일")) -> +1일 | B9: =IF($Y9="","",INDEX($N$6:$N$1005,$Y9)) -> 46190 | C9: =IF($Y9="","",CHOOSE(WEEKDAY(INDEX($N$6:$N$1005,$Y9)),"일","월","화","수","목","금","토")) -> 수 | D9: =IF($Y9="","",INDEX($O$6:$O$1005,$Y9)) -> 46098 | E9: =IF($Y9="","",INDEX($P$6:$P$1005,$Y9)) -> 거림테크주식회사 | F9: =IF($Y9="","",INDEX($Q$6:$Q$1005,$Y9)) -> 죽전지점 | G9: =IF($Y9="","",INDEX($R$6:$R$1005,$Y9)) -> 정기예금 | H9: =IF($Y9="","","USD") -> USD | I9: =IF($Y9="","",INDEX($S$6:$S$1005,$Y9)) -> 2 | J9: =IF($Y9="","",INDEX($T$6:$T$1005,$Y9)) -> 0.0365 | K9: =IF($Y9="","",INDEX($U$6:$U$1005,$Y9)) -> 0.002232 | L9: =IF($Y9="","",IF(INDEX($S$6:$S$1005,$Y9)>=10,"★ 10백만불↑","")) | N9: =IF('(1)예금승인내역'!H635="","",'(1)예금승인내역'!H635) -> 45659 | O9: =IF('(1)예금승인내역'!G635="","",'(1)예금승인내역'!G635) -> 45293 | P9: =IF('(1)예금승인내역'!F635="","",'(1)예금승인내역'!F635) -> 윤만수 | Q9: =IF('(1)예금승인내역'!C635="","",'(1)예금승인내역'!C635) -> 경산공단영업부 | R9: =IF('(1)예금승인내역'!K635="","",'(1)예금승인내역'!K635) -> 정기예금 | S9: =IF('(1)예금승인내역'!L635="","",'(1)예금승인내역'!L635) -> 1 | T9: =IF('(1)예금승인내역'!AG635="","",'(1)예금승인내역'!AG635) -> 0.05 | U9: =IF('(1)예금승인내역'!X635="","",'(1)예금승인내역'!X635) -> 0.004779 | V9: =IF(ISNUMBER(N9),N9-$B$2,"") -> -530 | W9: =IF(AND(ISNUMBER(N9),N9>=$B$2,N9<=$B$2+10),N9*100000+ROW(),"") | X9: =IFERROR(SMALL($W$6:$W$1005,4),"") -> 4619000544 | Y9: =IF(X9="","",MATCH(X9,$W$6:$W$1005,0)) -> 539
A10: =IF($Y10="","",IF(INDEX($N$6:$N$1005,$Y10)=$B$2,"오늘","+"&(INDEX($N$6:$N$1005,$Y10)-$B$2)&"일")) -> +3일 | B10: =IF($Y10="","",INDEX($N$6:$N$1005,$Y10)) -> 46192 | C10: =IF($Y10="","",CHOOSE(WEEKDAY(INDEX($N$6:$N$1005,$Y10)),"일","월","화","수","목","금","토")) -> 금 | D10: =IF($Y10="","",INDEX($O$6:$O$1005,$Y10)) -> 46162 | E10: =IF($Y10="","",INDEX($P$6:$P$1005,$Y10)) -> ㈜일지테크 | F10: =IF($Y10="","",INDEX($Q$6:$Q$1005,$Y10)) -> 경산공단영업부 | G10: =IF($Y10="","",INDEX($R$6:$R$1005,$Y10)) -> MMDA | H10: =IF($Y10="","","USD") -> USD | I10: =IF($Y10="","",INDEX($S$6:$S$1005,$Y10)) -> 11.11 | J10: =IF($Y10="","",INDEX($T$6:$T$1005,$Y10)) -> 0.032 | K10: =IF($Y10="","",INDEX($U$6:$U$1005,$Y10)) -> 0.003398 | L10: =IF($Y10="","",IF(INDEX($S$6:$S$1005,$Y10)>=10,"★ 10백만불↑","")) -> ★ 10백만불↑ | N10: =IF('(1)예금승인내역'!H636="","",'(1)예금승인내역'!H636) -> 45659 | O10: =IF('(1)예금승인내역'!G636="","",'(1)예금승인내역'!G636) -> 45293 | P10: =IF('(1)예금승인내역'!F636="","",'(1)예금승인내역'!F636) -> 윤만수 | Q10: =IF('(1)예금승인내역'!C636="","",'(1)예금승인내역'!C636) -> 경산공단영업부 | R10: =IF('(1)예금승인내역'!K636="","",'(1)예금승인내역'!K636) -> 정기예금 | S10: =IF('(1)예금승인내역'!L636="","",'(1)예금승인내역'!L636) -> 0.5 | T10: =IF('(1)예금승인내역'!AG636="","",'(1)예금승인내역'!AG636) -> 0.05 | U10: =IF('(1)예금승인내역'!X636="","",'(1)예금승인내역'!X636) -> 0.004779 | V10: =IF(ISNUMBER(N10),N10-$B$2,"") -> -530 | W10: =IF(AND(ISNUMBER(N10),N10>=$B$2,N10<=$B$2+10),N10*100000+ROW(),"") | X10: =IFERROR(SMALL($W$6:$W$1005,5),"") -> 4619200590 | Y10: =IF(X10="","",MATCH(X10,$W$6:$W$1005,0)) -> 585
A11: =IF($Y11="","",IF(INDEX($N$6:$N$1005,$Y11)=$B$2,"오늘","+"&(INDEX($N$6:$N$1005,$Y11)-$B$2)&"일")) -> +3일 | B11: =IF($Y11="","",INDEX($N$6:$N$1005,$Y11)) -> 46192 | C11: =IF($Y11="","",CHOOSE(WEEKDAY(INDEX($N$6:$N$1005,$Y11)),"일","월","화","수","목","금","토")) -> 금 | D11: =IF($Y11="","",INDEX($O$6:$O$1005,$Y11)) -> 46162 | E11: =IF($Y11="","",INDEX($P$6:$P$1005,$Y11)) -> ㈜약진통상 | F11: =IF($Y11="","",INDEX($Q$6:$Q$1005,$Y11)) -> 반월공단영업부 | G11: =IF($Y11="","",INDEX($R$6:$R$1005,$Y11)) -> MMDA | H11: =IF($Y11="","","USD") -> USD | I11: =IF($Y11="","",INDEX($S$6:$S$1005,$Y11)) -> 12.39 | J11: =IF($Y11="","",INDEX($T$6:$T$1005,$Y11)) -> 0.032 | K11: =IF($Y11="","",INDEX($U$6:$U$1005,$Y11)) -> 0.003398 | L11: =IF($Y11="","",IF(INDEX($S$6:$S$1005,$Y11)>=10,"★ 10백만불↑","")) -> ★ 10백만불↑ | N11: =IF('(1)예금승인내역'!H637="","",'(1)예금승인내역'!H637) -> 45335 | O11: =IF('(1)예금승인내역'!G637="","",'(1)예금승인내역'!G637) -> 45302 | P11: =IF('(1)예금승인내역'!F637="","",'(1)예금승인내역'!F637) -> 한국비철㈜ | Q11: =IF('(1)예금승인내역'!C637="","",'(1)예금승인내역'!C637) -> 달성공단영업부 | R11: =IF('(1)예금승인내역'!K637="","",'(1)예금승인내역'!K637) -> MMDA | S11: =IF('(1)예금승인내역'!L637="","",'(1)예금승인내역'!L637) -> 8.59 | T11: =IF('(1)예금승인내역'!AG637="","",'(1)예금승인내역'!AG637) -> 0.043 | U11: =IF('(1)예금승인내역'!X637="","",'(1)예금승인내역'!X637) -> 0.009316 | V11: =IF(ISNUMBER(N11),N11-$B$2,"") -> -854 | W11: =IF(AND(ISNUMBER(N11),N11>=$B$2,N11<=$B$2+10),N11*100000+ROW(),"") | X11: =IFERROR(SMALL($W$6:$W$1005,6),"") -> 4619200591 | Y11: =IF(X11="","",MATCH(X11,$W$6:$W$1005,0)) -> 586
A12: =IF($Y12="","",IF(INDEX($N$6:$N$1005,$Y12)=$B$2,"오늘","+"&(INDEX($N$6:$N$1005,$Y12)-$B$2)&"일")) -> +3일 | B12: =IF($Y12="","",INDEX($N$6:$N$1005,$Y12)) -> 46192 | C12: =IF($Y12="","",CHOOSE(WEEKDAY(INDEX($N$6:$N$1005,$Y12)),"일","월","화","수","목","금","토")) -> 금 | D12: =IF($Y12="","",INDEX($O$6:$O$1005,$Y12)) -> 46162 | E12: =IF($Y12="","",INDEX($P$6:$P$1005,$Y12)) -> 대원지에스아이 | F12: =IF($Y12="","",INDEX($Q$6:$Q$1005,$Y12)) -> 유통단지영업부 | G12: =IF($Y12="","",INDEX($R$6:$R$1005,$Y12)) -> 정기예금 | H12: =IF($Y12="","","USD") -> USD | I12: =IF($Y12="","",INDEX($S$6:$S$1005,$Y12)) -> 1.5 | J12: =IF($Y12="","",INDEX($T$6:$T$1005,$Y12)) -> 0.034 | K12: =IF($Y12="","",INDEX($U$6:$U$1005,$Y12)) -> 0.002487 | L12: =IF($Y12="","",IF(INDEX($S$6:$S$1005,$Y12)>=10,"★ 10백만불↑","")) | N12: =IF('(1)예금승인내역'!H638="","",'(1)예금승인내역'!H638) -> 45579 | O12: =IF('(1)예금승인내역'!G638="","",'(1)예금승인내역'!G638) -> 45303 | P12: =IF('(1)예금승인내역'!F638="","",'(1)예금승인내역'!F638) -> 케이와이글로벌셀앤진사모투자합자회사 | Q12: =IF('(1)예금승인내역'!C638="","",'(1)예금승인내역'!C638) -> 평택금융센터 | R12: =IF('(1)예금승인내역'!K638="","",'(1)예금승인내역'!K638) -> 정기예금 | S12: =IF('(1)예금승인내역'!L638="","",'(1)예금승인내역'!L638) -> 2.48 | T12: =IF('(1)예금승인내역'!AG638="","",'(1)예금승인내역'!AG638) -> 0.0515 | U12: =IF('(1)예금승인내역'!X638="","",'(1)예금승인내역'!X638) -> 0.003763 | V12: =IF(ISNUMBER(N12),N12-$B$2,"") -> -610 | W12: =IF(AND(ISNUMBER(N12),N12>=$B$2,N12<=$B$2+10),N12*100000+ROW(),"") | X12: =IFERROR(SMALL($W$6:$W$1005,7),"") -> 4619200592 | Y12: =IF(X12="","",MATCH(X12,$W$6:$W$1005,0)) -> 587
A13: =IF($Y13="","",IF(INDEX($N$6:$N$1005,$Y13)=$B$2,"오늘","+"&(INDEX($N$6:$N$1005,$Y13)-$B$2)&"일")) -> +3일 | B13: =IF($Y13="","",INDEX($N$6:$N$1005,$Y13)) -> 46192 | C13: =IF($Y13="","",CHOOSE(WEEKDAY(INDEX($N$6:$N$1005,$Y13)),"일","월","화","수","목","금","토")) -> 금 | D13: =IF($Y13="","",INDEX($O$6:$O$1005,$Y13)) -> 46162 | E13: =IF($Y13="","",INDEX($P$6:$P$1005,$Y13)) -> ㈜비알팜 | F13: =IF($Y13="","",INDEX($Q$6:$Q$1005,$Y13)) -> 원주금융센터 | G13: =IF($Y13="","",INDEX($R$6:$R$1005,$Y13)) -> MMDA | H13: =IF($Y13="","","USD") -> USD | I13: =IF($Y13="","",INDEX($S$6:$S$1005,$Y13)) -> 5.73 | J13: =IF($Y13="","",INDEX($T$6:$T$1005,$Y13)) -> 0.032 | K13: =IF($Y13="","",INDEX($U$6:$U$1005,$Y13)) -> 0.003398 | L13: =IF($Y13="","",IF(INDEX($S$6:$S$1005,$Y13)>=10,"★ 10백만불↑","")) | N13: =IF('(1)예금승인내역'!H639="","",'(1)예금승인내역'!H639) -> 45314 | O13: =IF('(1)예금승인내역'!G639="","",'(1)예금승인내역'!G639) -> 45307 | P13: =IF('(1)예금승인내역'!F639="","",'(1)예금승인내역'!F639) -> 한국석유공사 | Q13: =IF('(1)예금승인내역'!C639="","",'(1)예금승인내역'!C639) -> 울산영업부 | R13: =IF('(1)예금승인내역'!K639="","",'(1)예금승인내역'!K639) -> 정기예금 | S13: =IF('(1)예금승인내역'!L639="","",'(1)예금승인내역'!L639) -> 20 | T13: =IF('(1)예금승인내역'!AG639="","",'(1)예금승인내역'!AG639) -> 0.0505 | U13: =IF('(1)예금승인내역'!X639="","",'(1)예금승인내역'!X639) -> 0.002227 | V13: =IF(ISNUMBER(N13),N13-$B$2,"") -> -875 | W13: =IF(AND(ISNUMBER(N13),N13>=$B$2,N13<=$B$2+10),N13*100000+ROW(),"") | X13: =IFERROR(SMALL($W$6:$W$1005,8),"") -> 4619200593 | Y13: =IF(X13="","",MATCH(X13,$W$6:$W$1005,0)) -> 588
A14: =IF($Y14="","",IF(INDEX($N$6:$N$1005,$Y14)=$B$2,"오늘","+"&(INDEX($N$6:$N$1005,$Y14)-$B$2)&"일")) -> +6일 | B14: =IF($Y14="","",INDEX($N$6:$N$1005,$Y14)) -> 46195 | C14: =IF($Y14="","",CHOOSE(WEEKDAY(INDEX($N$6:$N$1005,$Y14)),"일","월","화","수","목","금","토")) -> 월 | D14: =IF($Y14="","",INDEX($O$6:$O$1005,$Y14)) -> 46162 | E14: =IF($Y14="","",INDEX($P$6:$P$1005,$Y14)) -> 한국비앤씨㈜ | F14: =IF($Y14="","",INDEX($Q$6:$Q$1005,$Y14)) -> 달성공단영업부 | G14: =IF($Y14="","",INDEX($R$6:$R$1005,$Y14)) -> MMDA | H14: =IF($Y14="","","USD") -> USD | I14: =IF($Y14="","",INDEX($S$6:$S$1005,$Y14)) -> 8.67 | J14: =IF($Y14="","",INDEX($T$6:$T$1005,$Y14)) -> 0.032 | K14: =IF($Y14="","",INDEX($U$6:$U$1005,$Y14)) -> 0.003398 | L14: =IF($Y14="","",IF(INDEX($S$6:$S$1005,$Y14)>=10,"★ 10백만불↑","")) | N14: =IF('(1)예금승인내역'!H640="","",'(1)예금승인내역'!H640) -> 45348 | O14: =IF('(1)예금승인내역'!G640="","",'(1)예금승인내역'!G640) -> 45316 | P14: =IF('(1)예금승인내역'!F640="","",'(1)예금승인내역'!F640) -> ㈜와이투솔루션 | Q14: =IF('(1)예금승인내역'!C640="","",'(1)예금승인내역'!C640) -> 화성금융센터 | R14: =IF('(1)예금승인내역'!K640="","",'(1)예금승인내역'!K640) -> 정기예금 | S14: =IF('(1)예금승인내역'!L640="","",'(1)예금승인내역'!L640) -> 1 | T14: =IF('(1)예금승인내역'!AG640="","",'(1)예금승인내역'!AG640) -> 0.0515 | U14: =IF('(1)예금승인내역'!X640="","",'(1)예금승인내역'!X640) -> 0.003027 | V14: =IF(ISNUMBER(N14),N14-$B$2,"") -> -841 | W14: =IF(AND(ISNUMBER(N14),N14>=$B$2,N14<=$B$2+10),N14*100000+ROW(),"") | X14: =IFERROR(SMALL($W$6:$W$1005,9),"") -> 4619500594 | Y14: =IF(X14="","",MATCH(X14,$W$6:$W$1005,0)) -> 589
A15: =IF($Y15="","",IF(INDEX($N$6:$N$1005,$Y15)=$B$2,"오늘","+"&(INDEX($N$6:$N$1005,$Y15)-$B$2)&"일")) -> +6일 | B15: =IF($Y15="","",INDEX($N$6:$N$1005,$Y15)) -> 46195 | C15: =IF($Y15="","",CHOOSE(WEEKDAY(INDEX($N$6:$N$1005,$Y15)),"일","월","화","수","목","금","토")) -> 월 | D15: =IF($Y15="","",INDEX($O$6:$O$1005,$Y15)) -> 46163 | E15: =IF($Y15="","",INDEX($P$6:$P$1005,$Y15)) -> 더스킨팩토리 | F15: =IF($Y15="","",INDEX($Q$6:$Q$1005,$Y15)) -> 강남영업부 | G15: =IF($Y15="","",INDEX($R$6:$R$1005,$Y15)) -> 정기예금 | H15: =IF($Y15="","","USD") -> USD | I15: =IF($Y15="","",INDEX($S$6:$S$1005,$Y15)) -> 1 | J15: =IF($Y15="","",INDEX($T$6:$T$1005,$Y15)) -> 0.0335 | K15: =IF($Y15="","",INDEX($U$6:$U$1005,$Y15)) -> 0.002944 | L15: =IF($Y15="","",IF(INDEX($S$6:$S$1005,$Y15)>=10,"★ 10백만불↑","")) | N15: =IF('(1)예금승인내역'!H641="","",'(1)예금승인내역'!H641) -> 45348 | O15: =IF('(1)예금승인내역'!G641="","",'(1)예금승인내역'!G641) -> 45316 | P15: =IF('(1)예금승인내역'!F641="","",'(1)예금승인내역'!F641) -> ㈜와이투솔루션 | Q15: =IF('(1)예금승인내역'!C641="","",'(1)예금승인내역'!C641) -> 화성금융센터 | R15: =IF('(1)예금승인내역'!K641="","",'(1)예금승인내역'!K641) -> 정기예금 | S15: =IF('(1)예금승인내역'!L641="","",'(1)예금승인내역'!L641) -> 1 | T15: =IF('(1)예금승인내역'!AG641="","",'(1)예금승인내역'!AG641) -> 0.0515 | U15: =IF('(1)예금승인내역'!X641="","",'(1)예금승인내역'!X641) -> 0.003027 | V15: =IF(ISNUMBER(N15),N15-$B$2,"") -> -841 | W15: =IF(AND(ISNUMBER(N15),N15>=$B$2,N15<=$B$2+10),N15*100000+ROW(),"") | X15: =IFERROR(SMALL($W$6:$W$1005,10),"") -> 4619500595 | Y15: =IF(X15="","",MATCH(X15,$W$6:$W$1005,0)) -> 590
A16: =IF($Y16="","",IF(INDEX($N$6:$N$1005,$Y16)=$B$2,"오늘","+"&(INDEX($N$6:$N$1005,$Y16)-$B$2)&"일")) -> +7일 | B16: =IF($Y16="","",INDEX($N$6:$N$1005,$Y16)) -> 46196 | C16: =IF($Y16="","",CHOOSE(WEEKDAY(INDEX($N$6:$N$1005,$Y16)),"일","월","화","수","목","금","토")) -> 화 | D16: =IF($Y16="","",INDEX($O$6:$O$1005,$Y16)) -> 46104 | E16: =IF($Y16="","",INDEX($P$6:$P$1005,$Y16)) -> ㈜비앤에프 | F16: =IF($Y16="","",INDEX($Q$6:$Q$1005,$Y16)) -> 죽전지점 | G16: =IF($Y16="","",INDEX($R$6:$R$1005,$Y16)) -> 정기예금 | H16: =IF($Y16="","","USD") -> USD | I16: =IF($Y16="","",INDEX($S$6:$S$1005,$Y16)) -> 1 | J16: =IF($Y16="","",INDEX($T$6:$T$1005,$Y16)) -> 0.0365 | K16: =IF($Y16="","",INDEX($U$6:$U$1005,$Y16)) -> 0.002274 | L16: =IF($Y16="","",IF(INDEX($S$6:$S$1005,$Y16)>=10,"★ 10백만불↑","")) | N16: =IF('(1)예금승인내역'!H642="","",'(1)예금승인내역'!H642) -> 45348 | O16: =IF('(1)예금승인내역'!G642="","",'(1)예금승인내역'!G642) -> 45316 | P16: =IF('(1)예금승인내역'!F642="","",'(1)예금승인내역'!F642) -> ㈜와이투솔루션 | Q16: =IF('(1)예금승인내역'!C642="","",'(1)예금승인내역'!C642) -> 화성금융센터 | R16: =IF('(1)예금승인내역'!K642="","",'(1)예금승인내역'!K642) -> 정기예금 | S16: =IF('(1)예금승인내역'!L642="","",'(1)예금승인내역'!L642) -> 1 | T16: =IF('(1)예금승인내역'!AG642="","",'(1)예금승인내역'!AG642) -> 0.0515 | U16: =IF('(1)예금승인내역'!X642="","",'(1)예금승인내역'!X642) -> 0.003027 | V16: =IF(ISNUMBER(N16),N16-$B$2,"") -> -841 | W16: =IF(AND(ISNUMBER(N16),N16>=$B$2,N16<=$B$2+10),N16*100000+ROW(),"") | X16: =IFERROR(SMALL($W$6:$W$1005,11),"") -> 4619600551 | Y16: =IF(X16="","",MATCH(X16,$W$6:$W$1005,0)) -> 546
A17: =IF($Y17="","",IF(INDEX($N$6:$N$1005,$Y17)=$B$2,"오늘","+"&(INDEX($N$6:$N$1005,$Y17)-$B$2)&"일")) | B17: =IF($Y17="","",INDEX($N$6:$N$1005,$Y17)) | C17: =IF($Y17="","",CHOOSE(WEEKDAY(INDEX($N$6:$N$1005,$Y17)),"일","월","화","수","목","금","토")) | D17: =IF($Y17="","",INDEX($O$6:$O$1005,$Y17)) | E17: =IF($Y17="","",INDEX($P$6:$P$1005,$Y17)) | F17: =IF($Y17="","",INDEX($Q$6:$Q$1005,$Y17)) | G17: =IF($Y17="","",INDEX($R$6:$R$1005,$Y17)) | H17: =IF($Y17="","","USD") | I17: =IF($Y17="","",INDEX($S$6:$S$1005,$Y17)) | J17: =IF($Y17="","",INDEX($T$6:$T$1005,$Y17)) | K17: =IF($Y17="","",INDEX($U$6:$U$1005,$Y17)) | L17: =IF($Y17="","",IF(INDEX($S$6:$S$1005,$Y17)>=10,"★ 10백만불↑","")) | N17: =IF('(1)예금승인내역'!H643="","",'(1)예금승인내역'!H643) -> 45348 | O17: =IF('(1)예금승인내역'!G643="","",'(1)예금승인내역'!G643) -> 45316 | P17: =IF('(1)예금승인내역'!F643="","",'(1)예금승인내역'!F643) -> ㈜와이투솔루션 | Q17: =IF('(1)예금승인내역'!C643="","",'(1)예금승인내역'!C643) -> 화성금융센터 | R17: =IF('(1)예금승인내역'!K643="","",'(1)예금승인내역'!K643) -> 정기예금 | S17: =IF('(1)예금승인내역'!L643="","",'(1)예금승인내역'!L643) -> 1 | T17: =IF('(1)예금승인내역'!AG643="","",'(1)예금승인내역'!AG643) -> 0.0515 | U17: =IF('(1)예금승인내역'!X643="","",'(1)예금승인내역'!X643) -> 0.003027 | V17: =IF(ISNUMBER(N17),N17-$B$2,"") -> -841 | W17: =IF(AND(ISNUMBER(N17),N17>=$B$2,N17<=$B$2+10),N17*100000+ROW(),"") | X17: =IFERROR(SMALL($W$6:$W$1005,12),"") | Y17: =IF(X17="","",MATCH(X17,$W$6:$W$1005,0))
A18: =IF($Y18="","",IF(INDEX($N$6:$N$1005,$Y18)=$B$2,"오늘","+"&(INDEX($N$6:$N$1005,$Y18)-$B$2)&"일")) | B18: =IF($Y18="","",INDEX($N$6:$N$1005,$Y18)) | C18: =IF($Y18="","",CHOOSE(WEEKDAY(INDEX($N$6:$N$1005,$Y18)),"일","월","화","수","목","금","토")) | D18: =IF($Y18="","",INDEX($O$6:$O$1005,$Y18)) | E18: =IF($Y18="","",INDEX($P$6:$P$1005,$Y18)) | F18: =IF($Y18="","",INDEX($Q$6:$Q$1005,$Y18)) | G18: =IF($Y18="","",INDEX($R$6:$R$1005,$Y18)) | H18: =IF($Y18="","","USD") | I18: =IF($Y18="","",INDEX($S$6:$S$1005,$Y18)) | J18: =IF($Y18="","",INDEX($T$6:$T$1005,$Y18)) | K18: =IF($Y18="","",INDEX($U$6:$U$1005,$Y18)) | L18: =IF($Y18="","",IF(INDEX($S$6:$S$1005,$Y18)>=10,"★ 10백만불↑","")) | N18: =IF('(1)예금승인내역'!H644="","",'(1)예금승인내역'!H644) -> 45357 | O18: =IF('(1)예금승인내역'!G644="","",'(1)예금승인내역'!G644) -> 45328 | P18: =IF('(1)예금승인내역'!F644="","",'(1)예금승인내역'!F644) -> 한국비철㈜ | Q18: =IF('(1)예금승인내역'!C644="","",'(1)예금승인내역'!C644) -> 달성공단영업부 | R18: =IF('(1)예금승인내역'!K644="","",'(1)예금승인내역'!K644) -> MMDA | S18: =IF('(1)예금승인내역'!L644="","",'(1)예금승인내역'!L644) -> 9.7 | T18: =IF('(1)예금승인내역'!AG644="","",'(1)예금승인내역'!AG644) -> 0.0435 | U18: =IF('(1)예금승인내역'!X644="","",'(1)예금승인내역'!X644) -> 0.009959 | V18: =IF(ISNUMBER(N18),N18-$B$2,"") -> -832 | W18: =IF(AND(ISNUMBER(N18),N18>=$B$2,N18<=$B$2+10),N18*100000+ROW(),"") | X18: =IFERROR(SMALL($W$6:$W$1005,13),"") | Y18: =IF(X18="","",MATCH(X18,$W$6:$W$1005,0))
A19: =IF($Y19="","",IF(INDEX($N$6:$N$1005,$Y19)=$B$2,"오늘","+"&(INDEX($N$6:$N$1005,$Y19)-$B$2)&"일")) | B19: =IF($Y19="","",INDEX($N$6:$N$1005,$Y19)) | C19: =IF($Y19="","",CHOOSE(WEEKDAY(INDEX($N$6:$N$1005,$Y19)),"일","월","화","수","목","금","토")) | D19: =IF($Y19="","",INDEX($O$6:$O$1005,$Y19)) | E19: =IF($Y19="","",INDEX($P$6:$P$1005,$Y19)) | F19: =IF($Y19="","",INDEX($Q$6:$Q$1005,$Y19)) | G19: =IF($Y19="","",INDEX($R$6:$R$1005,$Y19)) | H19: =IF($Y19="","","USD") | I19: =IF($Y19="","",INDEX($S$6:$S$1005,$Y19)) | J19: =IF($Y19="","",INDEX($T$6:$T$1005,$Y19)) | K19: =IF($Y19="","",INDEX($U$6:$U$1005,$Y19)) | L19: =IF($Y19="","",IF(INDEX($S$6:$S$1005,$Y19)>=10,"★ 10백만불↑","")) | N19: =IF('(1)예금승인내역'!H645="","",'(1)예금승인내역'!H645) -> 45425 | O19: =IF('(1)예금승인내역'!G645="","",'(1)예금승인내역'!G645) -> 45335 | P19: =IF('(1)예금승인내역'!F645="","",'(1)예금승인내역'!F645) -> 대성산업㈜ | Q19: =IF('(1)예금승인내역'!C645="","",'(1)예금승인내역'!C645) -> 강남영업부 | R19: =IF('(1)예금승인내역'!K645="","",'(1)예금승인내역'!K645) -> 정기예금 | S19: =IF('(1)예금승인내역'!L645="","",'(1)예금승인내역'!L645) -> 3.5 | T19: =IF('(1)예금승인내역'!AG645="","",'(1)예금승인내역'!AG645) -> 0.0492 | U19: =IF('(1)예금승인내역'!X645="","",'(1)예금승인내역'!X645) -> 0.006521 | V19: =IF(ISNUMBER(N19),N19-$B$2,"") -> -764 | W19: =IF(AND(ISNUMBER(N19),N19>=$B$2,N19<=$B$2+10),N19*100000+ROW(),"") | X19: =IFERROR(SMALL($W$6:$W$1005,14),"") | Y19: =IF(X19="","",MATCH(X19,$W$6:$W$1005,0))
A20: =IF($Y20="","",IF(INDEX($N$6:$N$1005,$Y20)=$B$2,"오늘","+"&(INDEX($N$6:$N$1005,$Y20)-$B$2)&"일")) | B20: =IF($Y20="","",INDEX($N$6:$N$1005,$Y20)) | C20: =IF($Y20="","",CHOOSE(WEEKDAY(INDEX($N$6:$N$1005,$Y20)),"일","월","화","수","목","금","토")) | D20: =IF($Y20="","",INDEX($O$6:$O$1005,$Y20)) | E20: =IF($Y20="","",INDEX($P$6:$P$1005,$Y20)) | F20: =IF($Y20="","",INDEX($Q$6:$Q$1005,$Y20)) | G20: =IF($Y20="","",INDEX($R$6:$R$1005,$Y20)) | H20: =IF($Y20="","","USD") | I20: =IF($Y20="","",INDEX($S$6:$S$1005,$Y20)) | J20: =IF($Y20="","",INDEX($T$6:$T$1005,$Y20)) | K20: =IF($Y20="","",INDEX($U$6:$U$1005,$Y20)) | L20: =IF($Y20="","",IF(INDEX($S$6:$S$1005,$Y20)>=10,"★ 10백만불↑","")) | N20: =IF('(1)예금승인내역'!H646="","",'(1)예금승인내역'!H646) -> 45366 | O20: =IF('(1)예금승인내역'!G646="","",'(1)예금승인내역'!G646) -> 45338 | P20: =IF('(1)예금승인내역'!F646="","",'(1)예금승인내역'!F646) -> 오스템임플란트㈜ | Q20: =IF('(1)예금승인내역'!C646="","",'(1)예금승인내역'!C646) -> 성남금융센터 | R20: =IF('(1)예금승인내역'!K646="","",'(1)예금승인내역'!K646) -> MMDA | S20: =IF('(1)예금승인내역'!L646="","",'(1)예금승인내역'!L646) -> 2 | T20: =IF('(1)예금승인내역'!AG646="","",'(1)예금승인내역'!AG646) -> 0.0435 | U20: =IF('(1)예금승인내역'!X646="","",'(1)예금승인내역'!X646) -> 0.010115 | V20: =IF(ISNUMBER(N20),N20-$B$2,"") -> -823 | W20: =IF(AND(ISNUMBER(N20),N20>=$B$2,N20<=$B$2+10),N20*100000+ROW(),"") | X20: =IFERROR(SMALL($W$6:$W$1005,15),"") | Y20: =IF(X20="","",MATCH(X20,$W$6:$W$1005,0))
A21: =IF($Y21="","",IF(INDEX($N$6:$N$1005,$Y21)=$B$2,"오늘","+"&(INDEX($N$6:$N$1005,$Y21)-$B$2)&"일")) | B21: =IF($Y21="","",INDEX($N$6:$N$1005,$Y21)) | C21: =IF($Y21="","",CHOOSE(WEEKDAY(INDEX($N$6:$N$1005,$Y21)),"일","월","화","수","목","금","토")) | D21: =IF($Y21="","",INDEX($O$6:$O$1005,$Y21)) | E21: =IF($Y21="","",INDEX($P$6:$P$1005,$Y21)) | F21: =IF($Y21="","",INDEX($Q$6:$Q$1005,$Y21)) | G21: =IF($Y21="","",INDEX($R$6:$R$1005,$Y21)) | H21: =IF($Y21="","","USD") | I21: =IF($Y21="","",INDEX($S$6:$S$1005,$Y21)) | J21: =IF($Y21="","",INDEX($T$6:$T$1005,$Y21)) | K21: =IF($Y21="","",INDEX($U$6:$U$1005,$Y21)) | L21: =IF($Y21="","",IF(INDEX($S$6:$S$1005,$Y21)>=10,"★ 10백만불↑","")) | N21: =IF('(1)예금승인내역'!H647="","",'(1)예금승인내역'!H647) -> 45404 | O21: =IF('(1)예금승인내역'!G647="","",'(1)예금승인내역'!G647) -> 45344 | P21: =IF('(1)예금승인내역'!F647="","",'(1)예금승인내역'!F647) -> 에스엠상선㈜ | Q21: =IF('(1)예금승인내역'!C647="","",'(1)예금승인내역'!C647) -> 강남영업부 | R21: =IF('(1)예금승인내역'!K647="","",'(1)예금승인내역'!K647) -> 정기예금 | S21: =IF('(1)예금승인내역'!L647="","",'(1)예금승인내역'!L647) -> 10 | T21: =IF('(1)예금승인내역'!AG647="","",'(1)예금승인내역'!AG647) -> 0.0525 | U21: =IF('(1)예금승인내역'!X647="","",'(1)예금승인내역'!X647) -> 0.00258 | V21: =IF(ISNUMBER(N21),N21-$B$2,"") -> -785 | W21: =IF(AND(ISNUMBER(N21),N21>=$B$2,N21<=$B$2+10),N21*100000+ROW(),"") | X21: =IFERROR(SMALL($W$6:$W$1005,16),"") | Y21: =IF(X21="","",MATCH(X21,$W$6:$W$1005,0))
A22: =IF($Y22="","",IF(INDEX($N$6:$N$1005,$Y22)=$B$2,"오늘","+"&(INDEX($N$6:$N$1005,$Y22)-$B$2)&"일")) | B22: =IF($Y22="","",INDEX($N$6:$N$1005,$Y22)) | C22: =IF($Y22="","",CHOOSE(WEEKDAY(INDEX($N$6:$N$1005,$Y22)),"일","월","화","수","목","금","토")) | D22: =IF($Y22="","",INDEX($O$6:$O$1005,$Y22)) | E22: =IF($Y22="","",INDEX($P$6:$P$1005,$Y22)) | F22: =IF($Y22="","",INDEX($Q$6:$Q$1005,$Y22)) | G22: =IF($Y22="","",INDEX($R$6:$R$1005,$Y22)) | H22: =IF($Y22="","","USD") | I22: =IF($Y22="","",INDEX($S$6:$S$1005,$Y22)) | J22: =IF($Y22="","",INDEX($T$6:$T$1005,$Y22)) | K22: =IF($Y22="","",INDEX($U$6:$U$1005,$Y22)) | L22: =IF($Y22="","",IF(INDEX($S$6:$S$1005,$Y22)>=10,"★ 10백만불↑","")) | N22: =IF('(1)예금승인내역'!H648="","",'(1)예금승인내역'!H648) -> 45439 | O22: =IF('(1)예금승인내역'!G648="","",'(1)예금승인내역'!G648) -> 45348 | P22: =IF('(1)예금승인내역'!F648="","",'(1)예금승인내역'!F648) -> 에스엠상선㈜ | Q22: =IF('(1)예금승인내역'!C648="","",'(1)예금승인내역'!C648) -> 강남영업부 | R22: =IF('(1)예금승인내역'!K648="","",'(1)예금승인내역'!K648) -> 정기예금 | S22: =IF('(1)예금승인내역'!L648="","",'(1)예금승인내역'!L648) -> 10 | T22: =IF('(1)예금승인내역'!AG648="","",'(1)예금승인내역'!AG648) -> 0.053 | U22: =IF('(1)예금승인내역'!X648="","",'(1)예금승인내역'!X648) -> 0.002813 | V22: =IF(ISNUMBER(N22),N22-$B$2,"") -> -750 | W22: =IF(AND(ISNUMBER(N22),N22>=$B$2,N22<=$B$2+10),N22*100000+ROW(),"") | X22: =IFERROR(SMALL($W$6:$W$1005,17),"") | Y22: =IF(X22="","",MATCH(X22,$W$6:$W$1005,0))
A23: =IF($Y23="","",IF(INDEX($N$6:$N$1005,$Y23)=$B$2,"오늘","+"&(INDEX($N$6:$N$1005,$Y23)-$B$2)&"일")) | B23: =IF($Y23="","",INDEX($N$6:$N$1005,$Y23)) | C23: =IF($Y23="","",CHOOSE(WEEKDAY(INDEX($N$6:$N$1005,$Y23)),"일","월","화","수","목","금","토")) | D23: =IF($Y23="","",INDEX($O$6:$O$1005,$Y23)) | E23: =IF($Y23="","",INDEX($P$6:$P$1005,$Y23)) | F23: =IF($Y23="","",INDEX($Q$6:$Q$1005,$Y23)) | G23: =IF($Y23="","",INDEX($R$6:$R$1005,$Y23)) | H23: =IF($Y23="","","USD") | I23: =IF($Y23="","",INDEX($S$6:$S$1005,$Y23)) | J23: =IF($Y23="","",INDEX($T$6:$T$1005,$Y23)) | K23: =IF($Y23="","",INDEX($U$6:$U$1005,$Y23)) | L23: =IF($Y23="","",IF(INDEX($S$6:$S$1005,$Y23)>=10,"★ 10백만불↑","")) | N23: =IF('(1)예금승인내역'!H649="","",'(1)예금승인내역'!H649) -> 45377 | O23: =IF('(1)예금승인내역'!G649="","",'(1)예금승인내역'!G649) -> 45348 | P23: =IF('(1)예금승인내역'!F649="","",'(1)예금승인내역'!F649) -> ㈜와이투솔루션 | Q23: =IF('(1)예금승인내역'!C649="","",'(1)예금승인내역'!C649) -> 화성금융센터 | R23: =IF('(1)예금승인내역'!K649="","",'(1)예금승인내역'!K649) -> 정기예금 | S23: =IF('(1)예금승인내역'!L649="","",'(1)예금승인내역'!L649) -> 1 | T23: =IF('(1)예금승인내역'!AG649="","",'(1)예금승인내역'!AG649) -> 0.052 | U23: =IF('(1)예금승인내역'!X649="","",'(1)예금승인내역'!X649) -> 0.00224 | V23: =IF(ISNUMBER(N23),N23-$B$2,"") -> -812 | W23: =IF(AND(ISNUMBER(N23),N23>=$B$2,N23<=$B$2+10),N23*100000+ROW(),"") | X23: =IFERROR(SMALL($W$6:$W$1005,18),"") | Y23: =IF(X23="","",MATCH(X23,$W$6:$W$1005,0))
A24: =IF($Y24="","",IF(INDEX($N$6:$N$1005,$Y24)=$B$2,"오늘","+"&(INDEX($N$6:$N$1005,$Y24)-$B$2)&"일")) | B24: =IF($Y24="","",INDEX($N$6:$N$1005,$Y24)) | C24: =IF($Y24="","",CHOOSE(WEEKDAY(INDEX($N$6:$N$1005,$Y24)),"일","월","화","수","목","금","토")) | D24: =IF($Y24="","",INDEX($O$6:$O$1005,$Y24)) | E24: =IF($Y24="","",INDEX($P$6:$P$1005,$Y24)) | F24: =IF($Y24="","",INDEX($Q$6:$Q$1005,$Y24)) | G24: =IF($Y24="","",INDEX($R$6:$R$1005,$Y24)) | H24: =IF($Y24="","","USD") | I24: =IF($Y24="","",INDEX($S$6:$S$1005,$Y24)) | J24: =IF($Y24="","",INDEX($T$6:$T$1005,$Y24)) | K24: =IF($Y24="","",INDEX($U$6:$U$1005,$Y24)) | L24: =IF($Y24="","",IF(INDEX($S$6:$S$1005,$Y24)>=10,"★ 10백만불↑","")) | N24: =IF('(1)예금승인내역'!H650="","",'(1)예금승인내역'!H650) -> 45377 | O24: =IF('(1)예금승인내역'!G650="","",'(1)예금승인내역'!G650) -> 45348 | P24: =IF('(1)예금승인내역'!F650="","",'(1)예금승인내역'!F650) -> ㈜와이투솔루션 | Q24: =IF('(1)예금승인내역'!C650="","",'(1)예금승인내역'!C650) -> 화성금융센터 | R24: =IF('(1)예금승인내역'!K650="","",'(1)예금승인내역'!K650) -> 정기예금 | S24: =IF('(1)예금승인내역'!L650="","",'(1)예금승인내역'!L650) -> 1 | T24: =IF('(1)예금승인내역'!AG650="","",'(1)예금승인내역'!AG650) -> 0.052 | U24: =IF('(1)예금승인내역'!X650="","",'(1)예금승인내역'!X650) -> 0.00224 | V24: =IF(ISNUMBER(N24),N24-$B$2,"") -> -812 | W24: =IF(AND(ISNUMBER(N24),N24>=$B$2,N24<=$B$2+10),N24*100000+ROW(),"") | X24: =IFERROR(SMALL($W$6:$W$1005,19),"") | Y24: =IF(X24="","",MATCH(X24,$W$6:$W$1005,0))
A25: =IF($Y25="","",IF(INDEX($N$6:$N$1005,$Y25)=$B$2,"오늘","+"&(INDEX($N$6:$N$1005,$Y25)-$B$2)&"일")) | B25: =IF($Y25="","",INDEX($N$6:$N$1005,$Y25)) | C25: =IF($Y25="","",CHOOSE(WEEKDAY(INDEX($N$6:$N$1005,$Y25)),"일","월","화","수","목","금","토")) | D25: =IF($Y25="","",INDEX($O$6:$O$1005,$Y25)) | E25: =IF($Y25="","",INDEX($P$6:$P$1005,$Y25)) | F25: =IF($Y25="","",INDEX($Q$6:$Q$1005,$Y25)) | G25: =IF($Y25="","",INDEX($R$6:$R$1005,$Y25)) | H25: =IF($Y25="","","USD") | I25: =IF($Y25="","",INDEX($S$6:$S$1005,$Y25)) | J25: =IF($Y25="","",INDEX($T$6:$T$1005,$Y25)) | K25: =IF($Y25="","",INDEX($U$6:$U$1005,$Y25)) | L25: =IF($Y25="","",IF(INDEX($S$6:$S$1005,$Y25)>=10,"★ 10백만불↑","")) | N25: =IF('(1)예금승인내역'!H651="","",'(1)예금승인내역'!H651) -> 45377 | O25: =IF('(1)예금승인내역'!G651="","",'(1)예금승인내역'!G651) -> 45348 | P25: =IF('(1)예금승인내역'!F651="","",'(1)예금승인내역'!F651) -> ㈜와이투솔루션 | Q25: =IF('(1)예금승인내역'!C651="","",'(1)예금승인내역'!C651) -> 화성금융센터 | R25: =IF('(1)예금승인내역'!K651="","",'(1)예금승인내역'!K651) -> 정기예금 | S25: =IF('(1)예금승인내역'!L651="","",'(1)예금승인내역'!L651) -> 1 | T25: =IF('(1)예금승인내역'!AG651="","",'(1)예금승인내역'!AG651) -> 0.052 | U25: =IF('(1)예금승인내역'!X651="","",'(1)예금승인내역'!X651) -> 0.00224 | V25: =IF(ISNUMBER(N25),N25-$B$2,"") -> -812 | W25: =IF(AND(ISNUMBER(N25),N25>=$B$2,N25<=$B$2+10),N25*100000+ROW(),"") | X25: =IFERROR(SMALL($W$6:$W$1005,20),"") | Y25: =IF(X25="","",MATCH(X25,$W$6:$W$1005,0))
A26: =IF($Y26="","",IF(INDEX($N$6:$N$1005,$Y26)=$B$2,"오늘","+"&(INDEX($N$6:$N$1005,$Y26)-$B$2)&"일")) | B26: =IF($Y26="","",INDEX($N$6:$N$1005,$Y26)) | C26: =IF($Y26="","",CHOOSE(WEEKDAY(INDEX($N$6:$N$1005,$Y26)),"일","월","화","수","목","금","토")) | D26: =IF($Y26="","",INDEX($O$6:$O$1005,$Y26)) | E26: =IF($Y26="","",INDEX($P$6:$P$1005,$Y26)) | F26: =IF($Y26="","",INDEX($Q$6:$Q$1005,$Y26)) | G26: =IF($Y26="","",INDEX($R$6:$R$1005,$Y26)) | H26: =IF($Y26="","","USD") | I26: =IF($Y26="","",INDEX($S$6:$S$1005,$Y26)) | J26: =IF($Y26="","",INDEX($T$6:$T$1005,$Y26)) | K26: =IF($Y26="","",INDEX($U$6:$U$1005,$Y26)) | L26: =IF($Y26="","",IF(INDEX($S$6:$S$1005,$Y26)>=10,"★ 10백만불↑","")) | N26: =IF('(1)예금승인내역'!H652="","",'(1)예금승인내역'!H652) -> 45377 | O26: =IF('(1)예금승인내역'!G652="","",'(1)예금승인내역'!G652) -> 45348 | P26: =IF('(1)예금승인내역'!F652="","",'(1)예금승인내역'!F652) -> ㈜와이투솔루션 | Q26: =IF('(1)예금승인내역'!C652="","",'(1)예금승인내역'!C652) -> 화성금융센터 | R26: =IF('(1)예금승인내역'!K652="","",'(1)예금승인내역'!K652) -> 정기예금 | S26: =IF('(1)예금승인내역'!L652="","",'(1)예금승인내역'!L652) -> 1 | T26: =IF('(1)예금승인내역'!AG652="","",'(1)예금승인내역'!AG652) -> 0.052 | U26: =IF('(1)예금승인내역'!X652="","",'(1)예금승인내역'!X652) -> 0.00224 | V26: =IF(ISNUMBER(N26),N26-$B$2,"") -> -812 | W26: =IF(AND(ISNUMBER(N26),N26>=$B$2,N26<=$B$2+10),N26*100000+ROW(),"") | X26: =IFERROR(SMALL($W$6:$W$1005,21),"") | Y26: =IF(X26="","",MATCH(X26,$W$6:$W$1005,0))
A27: =IF($Y27="","",IF(INDEX($N$6:$N$1005,$Y27)=$B$2,"오늘","+"&(INDEX($N$6:$N$1005,$Y27)-$B$2)&"일")) | B27: =IF($Y27="","",INDEX($N$6:$N$1005,$Y27)) | C27: =IF($Y27="","",CHOOSE(WEEKDAY(INDEX($N$6:$N$1005,$Y27)),"일","월","화","수","목","금","토")) | D27: =IF($Y27="","",INDEX($O$6:$O$1005,$Y27)) | E27: =IF($Y27="","",INDEX($P$6:$P$1005,$Y27)) | F27: =IF($Y27="","",INDEX($Q$6:$Q$1005,$Y27)) | G27: =IF($Y27="","",INDEX($R$6:$R$1005,$Y27)) | H27: =IF($Y27="","","USD") | I27: =IF($Y27="","",INDEX($S$6:$S$1005,$Y27)) | J27: =IF($Y27="","",INDEX($T$6:$T$1005,$Y27)) | K27: =IF($Y27="","",INDEX($U$6:$U$1005,$Y27)) | L27: =IF($Y27="","",IF(INDEX($S$6:$S$1005,$Y27)>=10,"★ 10백만불↑","")) | N27: =IF('(1)예금승인내역'!H653="","",'(1)예금승인내역'!H653) -> 45377 | O27: =IF('(1)예금승인내역'!G653="","",'(1)예금승인내역'!G653) -> 45348 | P27: =IF('(1)예금승인내역'!F653="","",'(1)예금승인내역'!F653) -> ㈜와이투솔루션 | Q27: =IF('(1)예금승인내역'!C653="","",'(1)예금승인내역'!C653) -> 화성금융센터 | R27: =IF('(1)예금승인내역'!K653="","",'(1)예금승인내역'!K653) -> 정기예금 | S27: =IF('(1)예금승인내역'!L653="","",'(1)예금승인내역'!L653) -> 1 | T27: =IF('(1)예금승인내역'!AG653="","",'(1)예금승인내역'!AG653) -> 0.052 | U27: =IF('(1)예금승인내역'!X653="","",'(1)예금승인내역'!X653) -> 0.00224 | V27: =IF(ISNUMBER(N27),N27-$B$2,"") -> -812 | W27: =IF(AND(ISNUMBER(N27),N27>=$B$2,N27<=$B$2+10),N27*100000+ROW(),"") | X27: =IFERROR(SMALL($W$6:$W$1005,22),"") | Y27: =IF(X27="","",MATCH(X27,$W$6:$W$1005,0))
A28: =IF($Y28="","",IF(INDEX($N$6:$N$1005,$Y28)=$B$2,"오늘","+"&(INDEX($N$6:$N$1005,$Y28)-$B$2)&"일")) | B28: =IF($Y28="","",INDEX($N$6:$N$1005,$Y28)) | C28: =IF($Y28="","",CHOOSE(WEEKDAY(INDEX($N$6:$N$1005,$Y28)),"일","월","화","수","목","금","토")) | D28: =IF($Y28="","",INDEX($O$6:$O$1005,$Y28)) | E28: =IF($Y28="","",INDEX($P$6:$P$1005,$Y28)) | F28: =IF($Y28="","",INDEX($Q$6:$Q$1005,$Y28)) | G28: =IF($Y28="","",INDEX($R$6:$R$1005,$Y28)) | H28: =IF($Y28="","","USD") | I28: =IF($Y28="","",INDEX($S$6:$S$1005,$Y28)) | J28: =IF($Y28="","",INDEX($T$6:$T$1005,$Y28)) | K28: =IF($Y28="","",INDEX($U$6:$U$1005,$Y28)) | L28: =IF($Y28="","",IF(INDEX($S$6:$S$1005,$Y28)>=10,"★ 10백만불↑","")) | N28: =IF('(1)예금승인내역'!H654="","",'(1)예금승인내역'!H654) -> 45387 | O28: =IF('(1)예금승인내역'!G654="","",'(1)예금승인내역'!G654) -> 45356 | P28: =IF('(1)예금승인내역'!F654="","",'(1)예금승인내역'!F654) -> 한국비철㈜ | Q28: =IF('(1)예금승인내역'!C654="","",'(1)예금승인내역'!C654) -> 달성공단영업부 | R28: =IF('(1)예금승인내역'!K654="","",'(1)예금승인내역'!K654) -> 정기예금 | S28: =IF('(1)예금승인내역'!L654="","",'(1)예금승인내역'!L654) -> 7 | T28: =IF('(1)예금승인내역'!AG654="","",'(1)예금승인내역'!AG654) -> 0.052 | U28: =IF('(1)예금승인내역'!X654="","",'(1)예금승인내역'!X654) -> 0.002376 | V28: =IF(ISNUMBER(N28),N28-$B$2,"") -> -802 | W28: =IF(AND(ISNUMBER(N28),N28>=$B$2,N28<=$B$2+10),N28*100000+ROW(),"") | X28: =IFERROR(SMALL($W$6:$W$1005,23),"") | Y28: =IF(X28="","",MATCH(X28,$W$6:$W$1005,0))
A29: =IF($Y29="","",IF(INDEX($N$6:$N$1005,$Y29)=$B$2,"오늘","+"&(INDEX($N$6:$N$1005,$Y29)-$B$2)&"일")) | B29: =IF($Y29="","",INDEX($N$6:$N$1005,$Y29)) | C29: =IF($Y29="","",CHOOSE(WEEKDAY(INDEX($N$6:$N$1005,$Y29)),"일","월","화","수","목","금","토")) | D29: =IF($Y29="","",INDEX($O$6:$O$1005,$Y29)) | E29: =IF($Y29="","",INDEX($P$6:$P$1005,$Y29)) | F29: =IF($Y29="","",INDEX($Q$6:$Q$1005,$Y29)) | G29: =IF($Y29="","",INDEX($R$6:$R$1005,$Y29)) | H29: =IF($Y29="","","USD") | I29: =IF($Y29="","",INDEX($S$6:$S$1005,$Y29)) | J29: =IF($Y29="","",INDEX($T$6:$T$1005,$Y29)) | K29: =IF($Y29="","",INDEX($U$6:$U$1005,$Y29)) | L29: =IF($Y29="","",IF(INDEX($S$6:$S$1005,$Y29)>=10,"★ 10백만불↑","")) | N29: =IF('(1)예금승인내역'!H655="","",'(1)예금승인내역'!H655) -> 45387 | O29: =IF('(1)예금승인내역'!G655="","",'(1)예금승인내역'!G655) -> 45356 | P29: =IF('(1)예금승인내역'!F655="","",'(1)예금승인내역'!F655) -> 한국비철㈜ | Q29: =IF('(1)예금승인내역'!C655="","",'(1)예금승인내역'!C655) -> 달성공단영업부 | R29: =IF('(1)예금승인내역'!K655="","",'(1)예금승인내역'!K655) -> 정기예금 | S29: =IF('(1)예금승인내역'!L655="","",'(1)예금승인내역'!L655) -> 1 | T29: =IF('(1)예금승인내역'!AG655="","",'(1)예금승인내역'!AG655) -> 0.052 | U29: =IF('(1)예금승인내역'!X655="","",'(1)예금승인내역'!X655) -> 0.002376 | V29: =IF(ISNUMBER(N29),N29-$B$2,"") -> -802 | W29: =IF(AND(ISNUMBER(N29),N29>=$B$2,N29<=$B$2+10),N29*100000+ROW(),"") | X29: =IFERROR(SMALL($W$6:$W$1005,24),"") | Y29: =IF(X29="","",MATCH(X29,$W$6:$W$1005,0))
A30: =IF($Y30="","",IF(INDEX($N$6:$N$1005,$Y30)=$B$2,"오늘","+"&(INDEX($N$6:$N$1005,$Y30)-$B$2)&"일")) | B30: =IF($Y30="","",INDEX($N$6:$N$1005,$Y30)) | C30: =IF($Y30="","",CHOOSE(WEEKDAY(INDEX($N$6:$N$1005,$Y30)),"일","월","화","수","목","금","토")) | D30: =IF($Y30="","",INDEX($O$6:$O$1005,$Y30)) | E30: =IF($Y30="","",INDEX($P$6:$P$1005,$Y30)) | F30: =IF($Y30="","",INDEX($Q$6:$Q$1005,$Y30)) | G30: =IF($Y30="","",INDEX($R$6:$R$1005,$Y30)) | H30: =IF($Y30="","","USD") | I30: =IF($Y30="","",INDEX($S$6:$S$1005,$Y30)) | J30: =IF($Y30="","",INDEX($T$6:$T$1005,$Y30)) | K30: =IF($Y30="","",INDEX($U$6:$U$1005,$Y30)) | L30: =IF($Y30="","",IF(INDEX($S$6:$S$1005,$Y30)>=10,"★ 10백만불↑","")) | N30: =IF('(1)예금승인내역'!H656="","",'(1)예금승인내역'!H656) -> 45390 | O30: =IF('(1)예금승인내역'!G656="","",'(1)예금승인내역'!G656) -> 45358 | P30: =IF('(1)예금승인내역'!F656="","",'(1)예금승인내역'!F656) -> ㈜성우하이텍 | Q30: =IF('(1)예금승인내역'!C656="","",'(1)예금승인내역'!C656) -> 서울영업부 | R30: =IF('(1)예금승인내역'!K656="","",'(1)예금승인내역'!K656) -> MMDA | S30: =IF('(1)예금승인내역'!L656="","",'(1)예금승인내역'!L656) -> 6.44 | T30: =IF('(1)예금승인내역'!AG656="","",'(1)예금승인내역'!AG656) -> 0.0435 | U30: =IF('(1)예금승인내역'!X656="","",'(1)예금승인내역'!X656) -> 0.008721 | V30: =IF(ISNUMBER(N30),N30-$B$2,"") -> -799 | W30: =IF(AND(ISNUMBER(N30),N30>=$B$2,N30<=$B$2+10),N30*100000+ROW(),"") | X30: =IFERROR(SMALL($W$6:$W$1005,25),"") | Y30: =IF(X30="","",MATCH(X30,$W$6:$W$1005,0))
A31: =IF($Y31="","",IF(INDEX($N$6:$N$1005,$Y31)=$B$2,"오늘","+"&(INDEX($N$6:$N$1005,$Y31)-$B$2)&"일")) | B31: =IF($Y31="","",INDEX($N$6:$N$1005,$Y31)) | C31: =IF($Y31="","",CHOOSE(WEEKDAY(INDEX($N$6:$N$1005,$Y31)),"일","월","화","수","목","금","토")) | D31: =IF($Y31="","",INDEX($O$6:$O$1005,$Y31)) | E31: =IF($Y31="","",INDEX($P$6:$P$1005,$Y31)) | F31: =IF($Y31="","",INDEX($Q$6:$Q$1005,$Y31)) | G31: =IF($Y31="","",INDEX($R$6:$R$1005,$Y31)) | H31: =IF($Y31="","","USD") | I31: =IF($Y31="","",INDEX($S$6:$S$1005,$Y31)) | J31: =IF($Y31="","",INDEX($T$6:$T$1005,$Y31)) | K31: =IF($Y31="","",INDEX($U$6:$U$1005,$Y31)) | L31: =IF($Y31="","",IF(INDEX($S$6:$S$1005,$Y31)>=10,"★ 10백만불↑","")) | N31: =IF('(1)예금승인내역'!H657="","",'(1)예금승인내역'!H657) -> 45456 | O31: =IF('(1)예금승인내역'!G657="","",'(1)예금승인내역'!G657) -> 45364 | P31: =IF('(1)예금승인내역'!F657="","",'(1)예금승인내역'!F657) -> ㈜노바인터내쇼널 | Q31: =IF('(1)예금승인내역'!C657="","",'(1)예금승인내역'!C657) -> 사상공단영업부 | R31: =IF('(1)예금승인내역'!K657="","",'(1)예금승인내역'!K657) -> 정기예금 | S31: =IF('(1)예금승인내역'!L657="","",'(1)예금승인내역'!L657) -> 1.01 | T31: =IF('(1)예금승인내역'!AG657="","",'(1)예금승인내역'!AG657) -> 0.053 | U31: =IF('(1)예금승인내역'!X657="","",'(1)예금승인내역'!X657) -> 0.002752 | V31: =IF(ISNUMBER(N31),N31-$B$2,"") -> -733 | W31: =IF(AND(ISNUMBER(N31),N31>=$B$2,N31<=$B$2+10),N31*100000+ROW(),"") | X31: =IFERROR(SMALL($W$6:$W$1005,26),"") | Y31: =IF(X31="","",MATCH(X31,$W$6:$W$1005,0))
A32: =IF($Y32="","",IF(INDEX($N$6:$N$1005,$Y32)=$B$2,"오늘","+"&(INDEX($N$6:$N$1005,$Y32)-$B$2)&"일")) | B32: =IF($Y32="","",INDEX($N$6:$N$1005,$Y32)) | C32: =IF($Y32="","",CHOOSE(WEEKDAY(INDEX($N$6:$N$1005,$Y32)),"일","월","화","수","목","금","토")) | D32: =IF($Y32="","",INDEX($O$6:$O$1005,$Y32)) | E32: =IF($Y32="","",INDEX($P$6:$P$1005,$Y32)) | F32: =IF($Y32="","",INDEX($Q$6:$Q$1005,$Y32)) | G32: =IF($Y32="","",INDEX($R$6:$R$1005,$Y32)) | H32: =IF($Y32="","","USD") | I32: =IF($Y32="","",INDEX($S$6:$S$1005,$Y32)) | J32: =IF($Y32="","",INDEX($T$6:$T$1005,$Y32)) | K32: =IF($Y32="","",INDEX($U$6:$U$1005,$Y32)) | L32: =IF($Y32="","",IF(INDEX($S$6:$S$1005,$Y32)>=10,"★ 10백만불↑","")) | N32: =IF('(1)예금승인내역'!H658="","",'(1)예금승인내역'!H658) -> 45397 | O32: =IF('(1)예금승인내역'!G658="","",'(1)예금승인내역'!G658) -> 45365 | P32: =IF('(1)예금승인내역'!F658="","",'(1)예금승인내역'!F658) -> 두손산업㈜ | Q32: =IF('(1)예금승인내역'!C658="","",'(1)예금승인내역'!C658) -> 화성금융센터 | R32: =IF('(1)예금승인내역'!K658="","",'(1)예금승인내역'!K658) -> MMDA | S32: =IF('(1)예금승인내역'!L658="","",'(1)예금승인내역'!L658) -> 1 | T32: =IF('(1)예금승인내역'!AG658="","",'(1)예금승인내역'!AG658) -> 0.0433 | U32: =IF('(1)예금승인내역'!X658="","",'(1)예금승인내역'!X658) -> 0.008959 | V32: =IF(ISNUMBER(N32),N32-$B$2,"") -> -792 | W32: =IF(AND(ISNUMBER(N32),N32>=$B$2,N32<=$B$2+10),N32*100000+ROW(),"") | X32: =IFERROR(SMALL($W$6:$W$1005,27),"") | Y32: =IF(X32="","",MATCH(X32,$W$6:$W$1005,0))
A33: =IF($Y33="","",IF(INDEX($N$6:$N$1005,$Y33)=$B$2,"오늘","+"&(INDEX($N$6:$N$1005,$Y33)-$B$2)&"일")) | B33: =IF($Y33="","",INDEX($N$6:$N$1005,$Y33)) | C33: =IF($Y33="","",CHOOSE(WEEKDAY(INDEX($N$6:$N$1005,$Y33)),"일","월","화","수","목","금","토")) | D33: =IF($Y33="","",INDEX($O$6:$O$1005,$Y33)) | E33: =IF($Y33="","",INDEX($P$6:$P$1005,$Y33)) | F33: =IF($Y33="","",INDEX($Q$6:$Q$1005,$Y33)) | G33: =IF($Y33="","",INDEX($R$6:$R$1005,$Y33)) | H33: =IF($Y33="","","USD") | I33: =IF($Y33="","",INDEX($S$6:$S$1005,$Y33)) | J33: =IF($Y33="","",INDEX($T$6:$T$1005,$Y33)) | K33: =IF($Y33="","",INDEX($U$6:$U$1005,$Y33)) | L33: =IF($Y33="","",IF(INDEX($S$6:$S$1005,$Y33)>=10,"★ 10백만불↑","")) | N33: =IF('(1)예금승인내역'!H659="","",'(1)예금승인내역'!H659) -> 45397 | O33: =IF('(1)예금승인내역'!G659="","",'(1)예금승인내역'!G659) -> 45366 | P33: =IF('(1)예금승인내역'!F659="","",'(1)예금승인내역'!F659) -> 오스템임플란트㈜ | Q33: =IF('(1)예금승인내역'!C659="","",'(1)예금승인내역'!C659) -> 성남금융센터 | R33: =IF('(1)예금승인내역'!K659="","",'(1)예금승인내역'!K659) -> MMDA | S33: =IF('(1)예금승인내역'!L659="","",'(1)예금승인내역'!L659) -> 2 | T33: =IF('(1)예금승인내역'!AG659="","",'(1)예금승인내역'!AG659) -> 0.0435 | U33: =IF('(1)예금승인내역'!X659="","",'(1)예금승인내역'!X659) -> 0.008755 | V33: =IF(ISNUMBER(N33),N33-$B$2,"") -> -792 | W33: =IF(AND(ISNUMBER(N33),N33>=$B$2,N33<=$B$2+10),N33*100000+ROW(),"") | X33: =IFERROR(SMALL($W$6:$W$1005,28),"") | Y33: =IF(X33="","",MATCH(X33,$W$6:$W$1005,0))
A34: =IF($Y34="","",IF(INDEX($N$6:$N$1005,$Y34)=$B$2,"오늘","+"&(INDEX($N$6:$N$1005,$Y34)-$B$2)&"일")) | B34: =IF($Y34="","",INDEX($N$6:$N$1005,$Y34)) | C34: =IF($Y34="","",CHOOSE(WEEKDAY(INDEX($N$6:$N$1005,$Y34)),"일","월","화","수","목","금","토")) | D34: =IF($Y34="","",INDEX($O$6:$O$1005,$Y34)) | E34: =IF($Y34="","",INDEX($P$6:$P$1005,$Y34)) | F34: =IF($Y34="","",INDEX($Q$6:$Q$1005,$Y34)) | G34: =IF($Y34="","",INDEX($R$6:$R$1005,$Y34)) | H34: =IF($Y34="","","USD") | I34: =IF($Y34="","",INDEX($S$6:$S$1005,$Y34)) | J34: =IF($Y34="","",INDEX($T$6:$T$1005,$Y34)) | K34: =IF($Y34="","",INDEX($U$6:$U$1005,$Y34)) | L34: =IF($Y34="","",IF(INDEX($S$6:$S$1005,$Y34)>=10,"★ 10백만불↑","")) | N34: =IF('(1)예금승인내역'!H660="","",'(1)예금승인내역'!H660) -> 45384 | O34: =IF('(1)예금승인내역'!G660="","",'(1)예금승인내역'!G660) -> 45370 | P34: =IF('(1)예금승인내역'!F660="","",'(1)예금승인내역'!F660) -> 한국석유공사 | Q34: =IF('(1)예금승인내역'!C660="","",'(1)예금승인내역'!C660) -> 울산영업부 | R34: =IF('(1)예금승인내역'!K660="","",'(1)예금승인내역'!K660) -> 정기예금 | S34: =IF('(1)예금승인내역'!L660="","",'(1)예금승인내역'!L660) -> 10 | T34: =IF('(1)예금승인내역'!AG660="","",'(1)예금승인내역'!AG660) -> 0.0523 | U34: =IF('(1)예금승인내역'!X660="","",'(1)예금승인내역'!X660) -> 0.00091 | V34: =IF(ISNUMBER(N34),N34-$B$2,"") -> -805 | W34: =IF(AND(ISNUMBER(N34),N34>=$B$2,N34<=$B$2+10),N34*100000+ROW(),"") | X34: =IFERROR(SMALL($W$6:$W$1005,29),"") | Y34: =IF(X34="","",MATCH(X34,$W$6:$W$1005,0))
A35: =IF($Y35="","",IF(INDEX($N$6:$N$1005,$Y35)=$B$2,"오늘","+"&(INDEX($N$6:$N$1005,$Y35)-$B$2)&"일")) | B35: =IF($Y35="","",INDEX($N$6:$N$1005,$Y35)) | C35: =IF($Y35="","",CHOOSE(WEEKDAY(INDEX($N$6:$N$1005,$Y35)),"일","월","화","수","목","금","토")) | D35: =IF($Y35="","",INDEX($O$6:$O$1005,$Y35)) | E35: =IF($Y35="","",INDEX($P$6:$P$1005,$Y35)) | F35: =IF($Y35="","",INDEX($Q$6:$Q$1005,$Y35)) | G35: =IF($Y35="","",INDEX($R$6:$R$1005,$Y35)) | H35: =IF($Y35="","","USD") | I35: =IF($Y35="","",INDEX($S$6:$S$1005,$Y35)) | J35: =IF($Y35="","",INDEX($T$6:$T$1005,$Y35)) | K35: =IF($Y35="","",INDEX($U$6:$U$1005,$Y35)) | L35: =IF($Y35="","",IF(INDEX($S$6:$S$1005,$Y35)>=10,"★ 10백만불↑","")) | N35: =IF('(1)예금승인내역'!H661="","",'(1)예금승인내역'!H661) -> 45408 | O35: =IF('(1)예금승인내역'!G661="","",'(1)예금승인내역'!G661) -> 45377 | P35: =IF('(1)예금승인내역'!F661="","",'(1)예금승인내역'!F661) -> ㈜와이투솔루션 | Q35: =IF('(1)예금승인내역'!C661="","",'(1)예금승인내역'!C661) -> 화성금융센터 | R35: =IF('(1)예금승인내역'!K661="","",'(1)예금승인내역'!K661) -> 정기예금 | S35: =IF('(1)예금승인내역'!L661="","",'(1)예금승인내역'!L661) -> 8 | T35: =IF('(1)예금승인내역'!AG661="","",'(1)예금승인내역'!AG661) -> 0.0523 | U35: =IF('(1)예금승인내역'!X661="","",'(1)예금승인내역'!X661) -> 0.002134 | V35: =IF(ISNUMBER(N35),N35-$B$2,"") -> -781 | W35: =IF(AND(ISNUMBER(N35),N35>=$B$2,N35<=$B$2+10),N35*100000+ROW(),"") | X35: =IFERROR(SMALL($W$6:$W$1005,30),"") | Y35: =IF(X35="","",MATCH(X35,$W$6:$W$1005,0))
A36: =IF($Y36="","",IF(INDEX($N$6:$N$1005,$Y36)=$B$2,"오늘","+"&(INDEX($N$6:$N$1005,$Y36)-$B$2)&"일")) | B36: =IF($Y36="","",INDEX($N$6:$N$1005,$Y36)) | C36: =IF($Y36="","",CHOOSE(WEEKDAY(INDEX($N$6:$N$1005,$Y36)),"일","월","화","수","목","금","토")) | D36: =IF($Y36="","",INDEX($O$6:$O$1005,$Y36)) | E36: =IF($Y36="","",INDEX($P$6:$P$1005,$Y36)) | F36: =IF($Y36="","",INDEX($Q$6:$Q$1005,$Y36)) | G36: =IF($Y36="","",INDEX($R$6:$R$1005,$Y36)) | H36: =IF($Y36="","","USD") | I36: =IF($Y36="","",INDEX($S$6:$S$1005,$Y36)) | J36: =IF($Y36="","",INDEX($T$6:$T$1005,$Y36)) | K36: =IF($Y36="","",INDEX($U$6:$U$1005,$Y36)) | L36: =IF($Y36="","",IF(INDEX($S$6:$S$1005,$Y36)>=10,"★ 10백만불↑","")) | N36: =IF('(1)예금승인내역'!H662="","",'(1)예금승인내역'!H662) -> 45408 | O36: =IF('(1)예금승인내역'!G662="","",'(1)예금승인내역'!G662) -> 45377 | P36: =IF('(1)예금승인내역'!F662="","",'(1)예금승인내역'!F662) -> ㈜와이투솔루션 | Q36: =IF('(1)예금승인내역'!C662="","",'(1)예금승인내역'!C662) -> 화성금융센터 | R36: =IF('(1)예금승인내역'!K662="","",'(1)예금승인내역'!K662) -> 정기예금 | S36: =IF('(1)예금승인내역'!L662="","",'(1)예금승인내역'!L662) -> 1 | T36: =IF('(1)예금승인내역'!AG662="","",'(1)예금승인내역'!AG662) -> 0.0523 | U36: =IF('(1)예금승인내역'!X662="","",'(1)예금승인내역'!X662) -> 0.002134 | V36: =IF(ISNUMBER(N36),N36-$B$2,"") -> -781 | W36: =IF(AND(ISNUMBER(N36),N36>=$B$2,N36<=$B$2+10),N36*100000+ROW(),"") | X36: =IFERROR(SMALL($W$6:$W$1005,31),"") | Y36: =IF(X36="","",MATCH(X36,$W$6:$W$1005,0))
A37: =IF($Y37="","",IF(INDEX($N$6:$N$1005,$Y37)=$B$2,"오늘","+"&(INDEX($N$6:$N$1005,$Y37)-$B$2)&"일")) | B37: =IF($Y37="","",INDEX($N$6:$N$1005,$Y37)) | C37: =IF($Y37="","",CHOOSE(WEEKDAY(INDEX($N$6:$N$1005,$Y37)),"일","월","화","수","목","금","토")) | D37: =IF($Y37="","",INDEX($O$6:$O$1005,$Y37)) | E37: =IF($Y37="","",INDEX($P$6:$P$1005,$Y37)) | F37: =IF($Y37="","",INDEX($Q$6:$Q$1005,$Y37)) | G37: =IF($Y37="","",INDEX($R$6:$R$1005,$Y37)) | H37: =IF($Y37="","","USD") | I37: =IF($Y37="","",INDEX($S$6:$S$1005,$Y37)) | J37: =IF($Y37="","",INDEX($T$6:$T$1005,$Y37)) | K37: =IF($Y37="","",INDEX($U$6:$U$1005,$Y37)) | L37: =IF($Y37="","",IF(INDEX($S$6:$S$1005,$Y37)>=10,"★ 10백만불↑","")) | N37: =IF('(1)예금승인내역'!H663="","",'(1)예금승인내역'!H663) -> 45408 | O37: =IF('(1)예금승인내역'!G663="","",'(1)예금승인내역'!G663) -> 45377 | P37: =IF('(1)예금승인내역'!F663="","",'(1)예금승인내역'!F663) -> ㈜와이투솔루션 | Q37: =IF('(1)예금승인내역'!C663="","",'(1)예금승인내역'!C663) -> 화성금융센터 | R37: =IF('(1)예금승인내역'!K663="","",'(1)예금승인내역'!K663) -> 정기예금 | S37: =IF('(1)예금승인내역'!L663="","",'(1)예금승인내역'!L663) -> 1 | T37: =IF('(1)예금승인내역'!AG663="","",'(1)예금승인내역'!AG663) -> 0.0523 | U37: =IF('(1)예금승인내역'!X663="","",'(1)예금승인내역'!X663) -> 0.002134 | V37: =IF(ISNUMBER(N37),N37-$B$2,"") -> -781 | W37: =IF(AND(ISNUMBER(N37),N37>=$B$2,N37<=$B$2+10),N37*100000+ROW(),"") | X37: =IFERROR(SMALL($W$6:$W$1005,32),"") | Y37: =IF(X37="","",MATCH(X37,$W$6:$W$1005,0))
