Workbook
Name Database1: #REF!
Name Database1: #REF!
Name 금융: #REF!
Name 금융: 상해지점!$AN$149:$AN$150
Name 금융: '(1)예금승인내역'!$AM$149:$AM$150

Sheet 외화예금일일가이드라인

Sheet 승인절차
N3: 1. 신청세부내용 확인. (고시금리, 가산금리, 최종금리, 상품, 기간 등)
N4: 2. 결재자 배정에 1차 결재자 체크, 부장님 체크 -> 후결 체크
N5: 3. 심사의견에 승인조건 및 심사의견 작성 후 심사의견 저장
N6: 4. 오른쪽 상단에 결재 누르고 <승인> 누르면 끝! (승인완료가 아닌 승인)
N7: 반려하는 경우 결재 <불승인> 클릭하면 됨!

Sheet (1)규정
A1: 내규 - 국제금융/외국환 - 외국환업무지침 - 제8장 외화예금
A2: 3. 우대금리 적용
B3: 기본이율보다 우대하고자 할 경우에는 다음 각 호의 주무부서장 승인을 득하여 적용한다. 다만, 외화종합통장에 의한 우대이율 적용의 경우와 중복될 때에는 높은 이율 하나만을 적용한다.
B4: 가. 원금이 미화 1백만불 상당액 미만인 경우 : 외환사업부장
B5: 나. 원금이 미화 1백만불 상당액 이상인 경우 : 자금부장
A7: ※ 기본이율 : 넥스피아(7452:금리주요정보조회)
A10: 나. 지급준비율
A11: (1) 만기 1개월 이상 외화정기예금, 만기 30일 이상 외화양도성예금증서 및 만기 6개월 이상 외화정기적금 : 2%
A12: (2) 기타예금 : 7%
A16: 내규 - 전반관리 - 종합수익관리지침
A18: 제1장 총 칙
A19: 1. 목 적
B20: 종합수익관리 업무란 전행의 재무적 지표인 손익을 관리회계에서 정의한 손익체계에 따라 조직.상품.고객별 등의 구분으로 상세하게 산출하는것으로
B21: 여.수신 금리 결정 및 조직별 성과평가, 고객별 수익성 분석 등을 통한 전략적 의사결정을 지원하는 것을 목적으로 한다.
A23: 2. 종합수익관리 기본원칙
B25: 종합수익관리의 기본원칙은 다음 각 호와 같다.
B26: 가. 자금원가 관리
B27: (1) 내부금리 결정방식은 만기대응내부(또는 시장)금리에 의한다.
B28: (2) 계산방법은 조달자금과 운용자금을 각각 계산하는 총액법으로 한다.
B29: (3) 자금원가관리 적용대상은 은행계정(신탁계정제외) 대차대조표를 보유한 모든 회계단위로 한다. 단, 조직단위 수익성 측정에 불필요하다고 판단되는 계정과목에 대해서는 제외할 수 있다.(2009.3.5 개정)
B30: 나. 업무원가 관리
B31: (1) 모든 투입자원을 활동으로 배분하여 원가를 계산한다.
B32: (2) 집계된 원가를 각 활동과 고객·상품과의 인과관계를 기준으로 배분한다.
B33: 다. 수익성 관리
B34: (1) 수익성관리 기간은 원칙적으로 회계연도와 같이 하되, 관리목적에 따라 월별, 분기별, 반기별 또는 임의기간으로 할 수 있다.
B35: (2) 관리회계 재무제표의 작성단위는 전행, 사업본부별, 영업점별, 회계단위부서별(총계정 원장 설치부서 또는 기타 필요부서)로 한다.
B36: (3) 계정과목은 원칙적으로 재무회계 계정과목을 준용하되, 내부관리목적상 별도의 계정과목을 신설할 수 있고, 재무제표의 계정체계 및 서식 등은 재무회계와 구분하여 주무부서장이 별도로 정하는 바에 따른다.
B37: (4) 수익성분석은 모든 상품을 대상으로 계좌별로 관리함을 원칙으로 한다. 단, 계좌가 구분되지 않는 항목은 조직별 이익관리실적표에 과목기준으로 계상한다.
A39: 3. 용어의 정의
B41: 이 지침에서 사용하는 용어의 정의는 다음 각 호와 같다.
B42: 가. 자금원가관리
B43: (1) 「내부금리」라 함은 본부(원화는 자금증권부, 외화는 국제금융부)와 각 회계단위간 조달 또는 운용한 자금에 대한 자금원가를 산출하기 위하여 적용되는 내부이전가격을 말한다(2009.3.5 개정)
B44: (2) 「내부이자」라 함은 내부금리에 의거 계산되는 보상 및 부담금액을 말한다.
B45: (3) 「내부이자 결산」이라 함은 은행 내부거래 자금의 보상 및 부담에 따른 내부이자 계산을 말한다.
B46: (4) 「만기대응내부금리」라 함은 여수신 상품의 만기에 대응하는 시장대표상품의 동일한 기간 시장수익률(시장기회비용)을 내부이전가격으로 하는 내부금리 결정방식을 말한다.
B47: (5) 「개별 만기대응내부금리」라 함은 신규시점의 일별 내부금리가 만기대응 되어 만기 또는 금리개정 전일까지 적용되는 내부금리를 말한다.
B48: (6) 「가중평균 만기대응내부금리」라 함은 만기 이전에 현금흐름이 있는 우대금리(P-rate)연동 여신상품에 적용하는데 원금이 현금흐름(회수) 시점별로 각각의 개별 만기대응내부금리를 구하고, 현금흐름의 금액과 기간 비중에 따라 금리를 가중평균 하는 내부금리를 말한다.
B49: (7) 「개별 만기대응시장금리」라 함은 신규시점의 일별 시장금리가 만기대응 되어 만기 또는 금리개정 전일까지 적용되는 시장금리를 말한다.
B50: (8) 「가중평균 만기대응시장금리」라 함은 만기 이전에 현금흐름이 있는 투자유가 증권에 적용하는데 원금이 현금흐름(회수) 시점별로 각각의 개별 만기대응시장금리를 구하고, 현금흐름의 금액과 기간 비중에 따라 금리를 가중평균 하는 시장금리를 말한다.
B51: (9) 「Core율에 의한 만기대응내부금리」라 함은 계좌가 있으나 만기가 없는 상품에 적용하는 것으로 Core율(월별실적 추세를 반영하여 일정부분 변동 없이 유지예상 되는 핵심)부분은 장기 내부금리를 비Core부분은 단기 내부금리를 적용하는 것을 말한다.
...

Sheet (1)예금승인내역
B1: ※ 금리협의시 기준
B2: 1. 외화MMDA | F2: 2. 외화정기예금
B3: (1) ~1주 또는 통지예금 금리 참조하여 협의 | F3: (1) 3개월 이하 : 금리부운용(콜론) vs 비금리부운용(스왑) 비교 (단, 외화제규제비율 및 NIM감안)
F4: (2) 3개월 초과 : 되도록 금리부운용(대여금)으로 매칭
X5: 0.001776
G6: 상세내역 | M6: 외부 참조금리 | V6: 내부 참조금리 | AE6: 승인정보 | AL6: 메모란
I7: 기간 | M7: 타행외화예금금리 | O7: 은행간 운용금리 | V7: 종합수익관리시스템 | Z7: 비용 | AB7: BEP금리
A8: 순번 | B8: 상담일자 | C8: 영업점 | D8: 지점장 | E8: 담당자 | F8: 고객 | G8: 시작일자 | H8: 만기일자 | I8: 일수 | J8: 월수 | K8: 예금종류 | L8: 통화/금액 | M8: 평균 | N8: 최대(은행) | O8: Tenor | P8: SOFR | Q8: LIBOR | R8: 이자(MM) | T8: 비이자(FXSWAP) | V8: 내부금리 | W8: 지준비용 | X8: 자금마진 | Y8: 고시금리 | Z8: 자금원가 | AA8: NIS | AB8: 이자운용 | AC8: 비이자운용 | AD8: 협의금리 | AE8: 고시금리 | AF8: 우대금리 | AG8: 승인금리 | AH8: 승인일자 | AI8: 신청번호 | AJ8: 여부 | AK8: 매칭 운용거래 (비이자 / 이자)
A10: 1 | B10: 42583 | C10: 여의도지점 | D10: 계장 조수현 | F10: 키움자산운용 | G10: 42583 | H10: 42674 | I10: =H10-G10 -> 91 | J10: =TRUNC(I10/30,0) -> 3 | L10: 4 | Q10: 0.007591 | S10: 0.0084 | Y10: 0.005314 | AD10: 0.0065 | AE10: =IF(Y10="","",Y10) -> 0.005314 | AG10: =IF(AF10="","",AE10+AF10) | AJ10: =IF(AG10="","N","Y") -> N
A11: =IF(B11="","",IF((YEAR(B11)-YEAR(B10))=0,A10+1,1)) -> 2 | B11: 42586 | C11: 포항공단점 | D11: 계장 배인영 | F11: 개인 | G11: 42586 | H11: 42678 | I11: =H11-G11 -> 92 | J11: =TRUNC(I11/30,0) -> 3 | K11: 정기예금 | L11: 2.5 | Q11: 0.007776 | S11: 0.0084 | Y11: 0.005495 | AD11: 0.0065 | AE11: =IF(Y11="","",Y11) -> 0.005495 | AF11: 0.001505 | AG11: =IF(AF11="","",AE11+AF11) -> 0.007 | AJ11: =IF(AG11="","N","Y") -> Y
A12: =IF(B12="","",IF((YEAR(B12)-YEAR(B11))=0,A11+1,1)) -> 3 | B12: 42587 | C12: 강남영업부 | D12: 과장 이진아 | F12: 한전 | G12: 42587 | H12: 42618 | I12: =H12-G12 -> 31 | J12: =TRUNC(I12/30,0) -> 1 | K12: MMDA | L12: 50 | Q12: 0.005039 | S12: 0.0055 | Y12: 0.002359 | AD12: 0.0043 | AE12: =IF(Y12="","",Y12) -> 0.002359 | AG12: =IF(AF12="","",AE12+AF12) | AJ12: =IF(AG12="","N","Y") -> N
A13: =IF(B13="","",IF((YEAR(B13)-YEAR(B12))=0,A12+1,1)) -> 4 | B13: 42590 | C13: 울산영업부 | D13: 차장 김정인 | F13: 석유공사 | G13: 42590 | H13: 42654 | I13: =H13-G13 -> 64 | J13: =TRUNC(I13/30,0) -> 2 | K13: 정기예금 | L13: 55 | Q13: 0.006148 | S13: =AVERAGE(0.0064,0.009,0.007) -> 0.0074666667 | Y13: 0.003475 | AD13: 0.0038 | AE13: =IF(Y13="","",Y13) -> 0.003475 | AG13: =IF(AF13="","",AE13+AF13) | AJ13: =IF(AG13="","N","Y") -> N
A14: =IF(B14="","",IF((YEAR(B14)-YEAR(B13))=0,A13+1,1)) -> 5 | B14: 42593 | C14: 울산영업부 | D14: 차장 김정인 | F14: 석유공사 | G14: 42593 | H14: 42641 | I14: =H14-G14 -> 48 | J14: =TRUNC(I14/30,0) -> 1 | K14: 정기예금 | L14: 28 | Q14: 0.0051765 | S14: =AVERAGE(0.0064,0.0085,0.0058) -> 0.0069 | Y14: 0.002547 | AD14: 0.0035 | AE14: =IF(Y14="","",Y14) -> 0.002547 | AG14: =IF(AF14="","",AE14+AF14) | AJ14: =IF(AG14="","N","Y") -> N
A15: =IF(B15="","",IF((YEAR(B15)-YEAR(B14))=0,A14+1,1)) -> 6 | B15: 42606 | C15: 울산영업부 | D15: 차장 김정인 | F15: 석유공사 | G15: 42606 | H15: 42639 | I15: =H15-G15 -> 33 | J15: =TRUNC(I15/30,0) -> 1 | K15: 정기예금 | L15: 60 | Q15: 0.0052439 | S15: =AVERAGE(0.0076,0.008,0.0058) -> 0.0071333333 | Y15: 0.002614 | AD15: 0.004 | AE15: =IF(Y15="","",Y15) -> 0.002614 | AF15: 0.001386 | AG15: =IF(AF15="","",AE15+AF15) -> 0.004 | AJ15: =IF(AG15="","N","Y") -> Y
A16: =IF(B16="","",IF((YEAR(B16)-YEAR(B15))=0,A15+1,1)) -> 7 | B16: 42612 | C16: 강남영업부 | D16: 과장 이진아 | F16: 한전 | G16: 42612 | H16: 42643 | I16: =H16-G16 -> 31 | J16: =TRUNC(I16/30,0) -> 1 | K16: MMDA | L16: 50 | Q16: 0.0052439 | S16: =AVERAGE(0.007,0.0051,0.0058) -> 0.0059666667 | Y16: 0.000852 | AD16: 0.0045 | AE16: =IF(Y16="","",Y16) -> 0.000852 | AG16: =IF(AF16="","",AE16+AF16) | AJ16: =IF(AG16="","N","Y") -> N
A17: =IF(B17="","",IF((YEAR(B17)-YEAR(B16))=0,A16+1,1)) -> 8 | B17: 42612 | C17: 울산영업부 | D17: 차장 김정인 | F17: 석유공사 | G17: 42612 | H17: 42661 | I17: =H17-G17 -> 49 | J17: =TRUNC(I17/30,0) -> 1 | K17: 정기예금 | L17: 40 | Q17: 0.0052439 | S17: =AVERAGE(0.007,0.0051,0.0058) -> 0.0059666667 | Y17: 0.002614 | AD17: 0.0036 | AE17: =IF(Y17="","",Y17) -> 0.002614 | AG17: =IF(AF17="","",AE17+AF17) | AJ17: =IF(AG17="","N","Y") -> N
A18: =IF(B18="","",IF((YEAR(B18)-YEAR(B17))=0,A17+1,1)) -> 9 | B18: 42618 | C18: 서울영업부 | D18: 차장 이순정 | F18: 현대중공업 | G18: 42618 | H18: 42648 | I18: =H18-G18 -> 30 | J18: =TRUNC(I18/30,0) -> 1 | K18: MMDA | L18: 50 | Q18: 0.0052572 | S18: 0.0046 | Y18: 0.000857 | AD18: 0.004 | AE18: =IF(Y18="","",Y18) -> 0.000857 | AG18: =IF(AF18="","",AE18+AF18) | AJ18: =IF(AG18="","N","Y") -> N
A19: =IF(B19="","",IF((YEAR(B19)-YEAR(B18))=0,A18+1,1)) -> 10 | B19: 42620 | C19: 울산영업부 | D19: 계장 고재희 | F19: 석유공사 | G19: 42620 | H19: 42670 | I19: =H19-G19 -> 50 | J19: =TRUNC(I19/30,0) -> 1 | K19: 정기예금 | L19: 90 | Q19: 0.0051656 | S19: 0.005 | Y19: 0.002573 | AD19: 0.0035 | AE19: =IF(Y19="","",Y19) -> 0.002573 | AG19: =IF(AF19="","",AE19+AF19) | AJ19: =IF(AG19="","N","Y") -> N
A20: =IF(B20="","",IF((YEAR(B20)-YEAR(B19))=0,A19+1,1)) -> 11 | B20: 42620 | C20: 성서지점 | D20: 차장 이민 | F20: 법인고객 | G20: 42620 | H20: 42985 | I20: =H20-G20 -> 365 | J20: =TRUNC(I20/30,0) -> 12 | K20: 정기예금 | L20: 2 | Q20: 0.009825 | S20: =AVERAGE(0.0145,0.015,0.013) -> 0.014166667 | Y20: 0.009825 | AD20: 0.0115 | AE20: =IF(Y20="","",Y20) -> 0.009825 | AG20: =IF(AF20="","",AE20+AF20) | AJ20: =IF(AG20="","N","Y") -> N
A21: =IF(B21="","",IF((YEAR(B21)-YEAR(B20))=0,A20+1,1)) -> 12 | B21: 42622 | C21: 울산영업부 | D21: 차장 김정인 | F21: 석유공사 | G21: 42622 | H21: 42652 | I21: =H21-G21 -> 30 | J21: =TRUNC(I21/30,0) -> 1 | K21: MMDA | L21: 0 | Q21: 0.0042211 | S21: =AVERAGE(0.0045,0.0046,0.0047) -> 0.0046 | Y21: 0.000878 | AD21: 0.0025 | AE21: =IF(Y21="","",Y21) -> 0.000878 | AG21: =IF(AF21="","",AE21+AF21) | AJ21: =IF(AG21="","N","Y") -> N
A22: =IF(B22="","",IF((YEAR(B22)-YEAR(B21))=0,A21+1,1)) -> 13 | B22: 42622 | C22: 〃 | D22: 〃 | F22: 〃 | G22: 42622 | H22: 42652 | I22: =H22-G22 -> 30 | J22: =TRUNC(I22/30,0) -> 1 | K22: 정기예금 | L22: 0 | Q22: 0.0051822 | S22: =AVERAGE(0.007,0.0075) -> 0.00725 | Y22: 0.002553 | AD22: 0.0035 | AE22: =IF(Y22="","",Y22) -> 0.002553 | AG22: =IF(AF22="","",AE22+AF22) | AJ22: =IF(AG22="","N","Y") -> N
A23: =IF(B23="","",IF((YEAR(B23)-YEAR(B22))=0,A22+1,1)) -> 14 | B23: 42622 | C23: 〃 | D23: 〃 | F23: 〃 | G23: 42622 | H23: 42683 | I23: =H23-G23 -> 61 | J23: =TRUNC(I23/30,0) -> 2 | K23: 정기예금 | L23: 0 | Q23: 0.0066467 | S23: =AVERAGE(0.0077,0.0082) -> 0.00795 | Y23: 0.003988 | AD23: 0.0045 | AE23: =IF(Y23="","",Y23) -> 0.003988 | AG23: =IF(AF23="","",AE23+AF23) | AJ23: =IF(AG23="","N","Y") -> N
A24: =IF(B24="","",IF((YEAR(B24)-YEAR(B23))=0,A23+1,1)) -> 15 | B24: 42622 | C24: 〃 | D24: 〃 | F24: 〃 | G24: 42622 | H24: 42713 | I24: =H24-G24 -> 91 | J24: =TRUNC(I24/30,0) -> 3 | K24: 정기예금 | L24: 0 | Q24: 0.0084544 | S24: =AVERAGE(0.0115,0.0088,0.012) -> 0.010766667 | Y24: 0.00616 | AD24: 0.0067 | AE24: =IF(Y24="","",Y24) -> 0.00616 | AG24: =IF(AF24="","",AE24+AF24) | AJ24: =IF(AG24="","N","Y") -> N
A25: =IF(B25="","",IF((YEAR(B25)-YEAR(B24))=0,A24+1,1)) -> 16 | B25: 42622 | C25: 〃 | D25: 〃 | F25: 〃 | G25: 42622 | H25: 42803 | I25: =H25-G25 -> 181 | J25: =TRUNC(I25/30,0) -> 6 | K25: 정기예금 | L25: 0 | Q25: 0.0123472 | S25: =AVERAGE(0.0129,0.0116,0.0112) -> 0.0119 | Y25: 0.009675 | AD25: 0.01 | AE25: =IF(Y25="","",Y25) -> 0.009675 | AG25: =IF(AF25="","",AE25+AF25) | AJ25: =IF(AG25="","N","Y") -> N
A26: =IF(B26="","",IF((YEAR(B26)-YEAR(B25))=0,A25+1,1)) -> 17 | B26: 42634 | C26: 울산영업부 | D26: 차장 김정인 | F26: 석유공사 | G26: 42634 | H26: 42670 | I26: =H26-G26 -> 36 | J26: =TRUNC(I26/30,0) -> 1 | K26: 정기예금 | L26: 80 | Q26: 0.0054306 | S26: =AVERAGE(0.0065,0.0057,0.004) -> 0.0054 | Y26: 0.002796 | AD26: 0.0035 | AE26: =IF(Y26="","",Y26) -> 0.002796 | AG26: =IF(AF26="","",AE26+AF26) | AJ26: =IF(AG26="","N","Y") -> N
A27: =IF(B27="","",IF((YEAR(B27)-YEAR(B26))=0,A26+1,1)) -> 18 | B27: 42636 | C27: 강남영업부 | D27: 과장 이진아 | F27: 한전 | G27: 42636 | H27: 42666 | I27: =H27-G27 -> 30 | J27: =TRUNC(I27/30,0) -> 1 | K27: MMDA | L27: 50 | Q27: 0.0042322 | S27: =AVERAGE(0.0065,0.0057,0.004) -> 0.0054 | Y27: 0.000977 | AD27: 0.0047 | AE27: =IF(Y27="","",Y27) -> 0.000977 | AG27: =IF(AF27="","",AE27+AF27) | AJ27: =IF(AG27="","N","Y") -> N
A28: =IF(B28="","",IF((YEAR(B28)-YEAR(B27))=0,A27+1,1)) -> 19 | B28: 42649 | C28: 강남영업부 | D28: 차장 황수덕 | F28: SK하이닉스 | G28: 42649 | H28: 42680 | I28: =H28-G28 -> 31 | J28: =TRUNC(I28/30,0) -> 1 | K28: MMDA | L28: 50 | Q28: 0.0042822 | Y28: 0.000977 | AE28: =IF(Y28="","",Y28) -> 0.000977 | AG28: =IF(AF28="","",AE28+AF28) | AJ28: =IF(AG28="","N","Y") -> N
A29: =IF(B29="","",IF((YEAR(B29)-YEAR(B28))=0,A28+1,1)) -> 20 | B29: 42649 | C29: 성서지점 | D29: 대리 홍지현 | F29: 법인고객 | G29: 42649 | H29: 43014 | I29: =H29-G29 -> 365 | J29: =TRUNC(I29/30,0) -> 12 | K29: 정기예금 | L29: 2 | Q29: 0.0157267 | S29: =AVERAGE(0.015,0.014,0.0135) -> 0.014166667 | Y29: 0.011434 | AD29: 0.0125 | AE29: =IF(Y29="","",Y29) -> 0.011434 | AG29: =IF(AF29="","",AE29+AF29) | AJ29: =IF(AG29="","N","Y") -> N
A30: =IF(B30="","",IF((YEAR(B30)-YEAR(B29))=0,A29+1,1)) -> 21 | B30: 42650 | C30: 성서지점 | D30: 행원 이현경 | F30: ㈜나인플러스 | G30: 42650 | H30: 42742 | I30: =H30-G30 -> 92 | J30: =TRUNC(I30/30,0) -> 3 | K30: 정기예금 | L30: 1 | Q30: 0.0087156 | S30: =AVERAGE(0.0115,0.011,0.0089) -> 0.010466667 | Y30: 0.0064 | AD30: 0.007 | AE30: =IF(Y30="","",Y30) -> 0.0064 | AG30: 0.0071 | AJ30: =IF(AG30="","N","Y") -> Y
A31: =IF(B31="","",IF((YEAR(B31)-YEAR(B30))=0,A30+1,1)) -> 22 | B31: 42661 | C31: 울산영업부 | D31: 차장 김정인 | F31: 석유공사 | G31: 42661 | H31: 42695 | I31: =H31-G31 -> 34 | J31: =TRUNC(I31/30,0) -> 1 | K31: 정기예금 | L31: 70 | Q31: 0.0052789 | S31: =AVERAGE(0.0077,0.008) -> 0.00785 | Y31: 0.002647 | AD31: 0.0036 | AE31: =IF(Y31="","",Y31) -> 0.002647 | AJ31: =IF(AG31="","N","Y") -> N
A32: =IF(B32="","",IF((YEAR(B32)-YEAR(B31))=0,A31+1,1)) -> 23 | B32: 42668 | C32: 울산영업부 | D32: 차장 김정인 | F32: 석유공사 | G32: 42668 | H32: 42684 | I32: =H32-G32 -> 16 | J32: =TRUNC(I32/30,0) -> 0 | K32: 정기예금 | L32: 45 | Q32: 0.0045589 | S32: =AVERAGE(0.006,0.005) -> 0.0055 | Y32: 0.001577 | AD32: 0.002 | AE32: =IF(Y32="","",Y32) -> 0.001577 | AJ32: =IF(AG32="","N","Y") -> N
A33: =IF(B33="","",IF((YEAR(B33)-YEAR(B32))=0,A32+1,1)) -> 24 | B33: 42668 | C33: 〃 | D33: 〃 | F33: 〃 | G33: 42668 | H33: 42690 | I33: =H33-G33 -> 22 | J33: =TRUNC(I33/30,0) -> 0 | K33: 〃 | L33: 35 | Q33: 0.0045589 | S33: =AVERAGE(0.006,0.005) -> 0.0055 | Y33: 0.001577 | AD33: 0.002 | AE33: =IF(Y33="","",Y33) -> 0.001577 | AJ33: =IF(AG33="","N","Y") -> N
A34: =IF(B34="","",IF((YEAR(B34)-YEAR(B33))=0,A33+1,1)) -> 25 | B34: 42668 | C34: 〃 | D34: 〃 | F34: 〃 | G34: 42668 | H34: 42704 | I34: =H34-G34 -> 36 | J34: =TRUNC(I34/30,0) -> 1 | K34: 〃 | L34: 70 | Q34: 0.00534 | S34: =AVERAGE(0.0058,0.0065) -> 0.00615 | Y34: 0.002708 | AD34: 0.004 | AE34: =IF(Y34="","",Y34) -> 0.002708 | AG34: 0.004 | AJ34: =IF(AG34="","N","Y") -> Y
A35: =IF(B35="","",IF((YEAR(B35)-YEAR(B34))=0,A34+1,1)) -> 26 | B35: 42678 | C35: 〃 | D35: 〃 | F35: 〃 | G35: 42678 | H35: 42711 | I35: =H35-G35 -> 33 | J35: =TRUNC(I35/30,0) -> 1 | K35: 〃 | L35: 20 | Q35: 0.0053256 | AD35: 0.0036 | AE35: =IF(Y35="","",Y35) | AG35: 0 | AJ35: =IF(AG35="","N","Y") -> Y
A36: =IF(B36="","",IF((YEAR(B36)-YEAR(B35))=0,A35+1,1)) -> 27 | B36: 42678 | C36: 〃 | D36: 〃 | F36: 〃 | G36: 42678 | H36: 42711 | I36: =H36-G36 -> 33 | J36: =TRUNC(I36/30,0) -> 1 | K36: 〃 | L36: 30 | Q36: 0.0053256 | AD36: 0.0036 | AE36: =IF(Y36="","",Y36) | AJ36: =IF(AG36="","N","Y") -> N
A37: =IF(B37="","",IF((YEAR(B37)-YEAR(B36))=0,A36+1,1)) -> 28 | B37: 42682 | C37: 반월공단지점 | D37: 대리 김수현 | F37: ㈜이수엑사켐 | G37: 42682 | H37: 42725 | I37: =H37-G37 -> 43 | J37: =TRUNC(I37/30,0) -> 1 | K37: 〃 | L37: 7 | Q37: 0.0053533 | S37: =AVERAGE(0.0058,0.0065) -> 0.00615 | Y37: 0.002721 | AD37: 0.0036 | AE37: =IF(Y37="","",Y37) -> 0.002721 | AG37: 0.0036 | AJ37: =IF(AG37="","N","Y") -> Y
A38: =IF(B38="","",IF((YEAR(B38)-YEAR(B37))=0,A37+1,1)) -> 29 | B38: 42690 | C38: 울산영업부 | D38: 차장 김정인 | F38: 석유공사 | G38: 42690 | H38: 42718 | I38: =H38-G38 -> 28 | J38: =TRUNC(I38/30,0) -> 0 | K38: 〃 | L38: 30 | Q38: 0.0055011 | S38: =AVERAGE(0.0055,0.006) -> 0.00575 | Y38: 0.001605 | AD38: 0.0029 | AE38: =IF(Y38="","",Y38) -> 0.001605 | AJ38: =IF(AG38="","N","Y") -> N
A39: =IF(B39="","",IF((YEAR(B39)-YEAR(B38))=0,A38+1,1)) -> 30 | B39: 42695 | C39: 울산영업부 | D39: 차장 김정인 | F39: 석유공사 | G39: 42695 | H39: 42726 | I39: =H39-G39 -> 31 | J39: =TRUNC(I39/30,0) -> 1 | K39: 〃 | L39: 60 | Q39: 0.00566 | S39: =AVERAGE(0.0055,0.006) -> 0.00575 | Y39: 0.003021 | AD39: 0.0039 | AE39: =IF(Y39="","",Y39) -> 0.003021 | AJ39: =IF(AG39="","N","Y") -> N
A40: =IF(B40="","",IF((YEAR(B40)-YEAR(B39))=0,A39+1,1)) -> 31 | B40: 42702 | C40: 울산영업부 | D40: 차장 김정인 | F40: 석유공사 | G40: 42702 | H40: 42718 | I40: =H40-G40 -> 16 | J40: =TRUNC(I40/30,0) -> 0 | K40: 〃 | L40: 30 | Q40: 0.0045822 | S40: =AVERAGE(0.0052,0.0058,0.0051) -> 0.0053666667 | Y40: 0.001598 | AD40: 0.0026 | AE40: =IF(Y40="","",Y40) -> 0.001598 | AJ40: =IF(AG40="","N","Y") -> N
A41: =IF(B41="","",IF((YEAR(B41)-YEAR(B40))=0,A40+1,1)) -> 32 | B41: 42702 | C41: 울산영업부 | D41: 차장 김정인 | F41: 석유공사 | G41: 42702 | H41: 42724 | I41: =H41-G41 -> 22 | J41: =TRUNC(I41/30,0) -> 0 | K41: 〃 | L41: 50 | Q41: 0.0045822 | S41: =AVERAGE(0.0052,0.0058,0.0054) -> 0.0054666667 | Y41: 0.001598 | AD41: 0.003 | AE41: =IF(Y41="","",Y41) -> 0.001598 | AJ41: =IF(AG41="","N","Y") -> N
...

Sheet 예금만기도래
A1: TODAY | B1: =TEXT(A2,"aaaa") -> 월요일 | D1: +1일 | E1: =TEXT(D2,"aaaa") -> 화요일 | G1: +2일 | H1: =TEXT(G2,"aaaa") -> 수요일 | J1: +3일 | K1: =TEXT(J2,"aaaa") -> 목요일 | M1: +4일 | N1: =TEXT(M2,"aaaa") -> 금요일 | P1: +5일 | Q1: =TEXT(P2,"aaaa") -> 토요일 | S1: +6일 | T1: =TEXT(S2,"aaaa") -> 일요일 | V1: +7일 | W1: =TEXT(V2,"aaaa") -> 월요일 | Y1: +8일 | Z1: =TEXT(Y2,"aaaa") -> 화요일 | AB1: +9일 | AC1: =TEXT(AB2,"aaaa") -> 수요일 | AF1: 만기일 | AG1: 시작일 | AH1: 업체명 | AI1: 금액 | AJ1: 금리 | AK1: 예금종류
A2: =TODAY() -> 46188 | B2: 예금종류 | C2: $ | D2: =$A$2+_xlfn.NUMBERVALUE(MID(D1,3,1)) -> 46189 | E2: 예금종류 | F2: $ | G2: =$A$2+_xlfn.NUMBERVALUE(MID(G1,3,1)) -> 46190 | H2: 예금종류 | I2: $ | J2: =$A$2+_xlfn.NUMBERVALUE(MID(J1,3,1)) -> 46191 | K2: 예금종류 | L2: $ | M2: =$A$2+_xlfn.NUMBERVALUE(MID(M1,3,1)) -> 46192 | N2: 예금종류 | O2: $ | P2: =$A$2+_xlfn.NUMBERVALUE(MID(P1,3,1)) -> 46193 | Q2: 예금종류 | R2: $ | S2: =$A$2+_xlfn.NUMBERVALUE(MID(S1,3,1)) -> 46194 | T2: 예금종류 | U2: $ | V2: =$A$2+_xlfn.NUMBERVALUE(MID(V1,3,1)) -> 46195 | W2: 예금종류 | X2: $ | Y2: =$A$2+_xlfn.NUMBERVALUE(MID(Y1,3,1)) -> 46196 | Z2: 예금종류 | AA2: $ | AB2: =$A$2+_xlfn.NUMBERVALUE(MID(AB1,3,1)) -> 46197 | AC2: 예금종류 | AD2: $ | AE2: ='(1)예금승인내역'!H632 -> 45313 | AF2: =VALUE(AE2) -> 45313 | AG2: ='(1)예금승인내역'!G632 -> 45280 | AH2: ='(1)예금승인내역'!F632 -> 주식회사 한국비앤씨 | AI2: ='(1)예금승인내역'!L632 -> 5 | AJ2: ='(1)예금승인내역'!AG632 -> 0.0525 | AK2: ='(1)예금승인내역'!K632 -> 정기예금
A3: {=IFERROR( INDEX($AH$2:$AH$9999,SMALL(IF($AF$2:$AF$9999=$A$2, ROW($AH$2:$AH$9999)-ROW($AH$2)+1),ROWS(A$3:$A3))),"")} -> ㈜이수스페셜티케미컬 | B3: {=IFERROR( INDEX($AK$2:$AK$9999,SMALL(IF($AF$2:$AF$9999=$A$2, ROW($AK$2:$AK$9999)-ROW($AK$2)+1),ROWS($A$3:B3))),"")} -> MMDA | C3: {=IFERROR( INDEX($AI$2:$AI$9999,SMALL(IF($AF$2:$AF$9999=$A$2, ROW($AI$2:$AI$9999)-ROW($AI$2)+1),ROWS($A$3:C3))),"")} -> 7.97 | D3: {=IFERROR( INDEX($AH$2:$AH$9999,SMALL(IF($AF$2:$AF$9999=$D$2, ROW($AH$2:$AH$9999)-ROW($AH$2)+1),ROWS($D$3:D3))),"")} -> ㈜ 동아홀딩스 | E3: {=IFERROR( INDEX($AK$2:$AK$9999,SMALL(IF($AF$2:$AF$9999=$D$2, ROW($AK$2:$AK$9999)-ROW($AK$2)+1),ROWS($D$3:E3))),"")} -> 정기예금 | F3: {=IFERROR( INDEX($AI$2:$AI$9999,SMALL(IF($AF$2:$AF$9999=$D$2, ROW($AI$2:$AI$9999)-ROW($AI$2)+1),ROWS($F$3:F3))),"")} -> 2.19 | G3: {=IFERROR( INDEX($AH$2:$AH$9999,SMALL(IF($AF$2:$AF$9999=$G$2, ROW($AH$2:$AH$9999)-ROW($AH$2)+1),ROWS($G$3:G3))),"")} -> 거림테크주식회사 | H3: {=IFERROR( INDEX($AK$2:$AK$9999,SMALL(IF($AF$2:$AF$9999=$G$2, ROW($AK$2:$AK$9999)-ROW($AK$2)+1),ROWS($G$3:H3))),"")} -> 정기예금 | I3: {=IFERROR( INDEX($AI$2:$AI$9999,SMALL(IF($AF$2:$AF$9999=$G$2, ROW($AI$2:$AI$9999)-ROW($AI$2)+1),ROWS($I$3:I3))),"")} -> 2 | J3: {=IFERROR( INDEX($AH$2:$AH$9999,SMALL(IF($AF$2:$AF$9999=$J$2, ROW($AH$2:$AH$9999)-ROW($AH$2)+1),ROWS($J$3:J3))),"")} | K3: {=IFERROR( INDEX($AK$2:$AK$9999,SMALL(IF($AF$2:$AF$9999=$J$2, ROW($AK$2:$AK$9999)-ROW($AK$2)+1),ROWS($J$3:K3))),"")} | L3: {=IFERROR( INDEX($AI$2:$AI$9999,SMALL(IF($AF$2:$AF$9999=$J$2, ROW($AI$2:$AI$9999)-ROW($AI$2)+1),ROWS($L$3:L3))),"")} | M3: {=IFERROR( INDEX($AH$2:$AH$9999,SMALL(IF($AF$2:$AF$9999=$M$2, ROW($AH$2:$AH$9999)-ROW($AH$2)+1),ROWS($M$3:M3))),"")} -> ㈜일지테크 | N3: {=IFERROR( INDEX($AK$2:$AK$9999,SMALL(IF($AF$2:$AF$9999=$M$2, ROW($AK$2:$AK$9999)-ROW($AK$2)+1),ROWS($M$3:N3))),"")} -> MMDA | O3: {=IFERROR( INDEX($AI$2:$AI$9999,SMALL(IF($AF$2:$AF$9999=$M$2, ROW($AI$2:$AI$9999)-ROW($AI$2)+1),ROWS($O$3:O3))),"")} -> 11.11 | P3: {=IFERROR( INDEX($AH$2:$AH$9999,SMALL(IF($AF$2:$AF$9999=$P$2, ROW($AH$2:$AH$9999)-ROW($AH$2)+1),ROWS($P$3:P3))),"")} | Q3: {=IFERROR( INDEX($AK$2:$AK$9999,SMALL(IF($AF$2:$AF$9999=$P$2, ROW($AK$2:$AK$9999)-ROW($AK$2)+1),ROWS($P$3:Q3))),"")} | R3: {=IFERROR( INDEX($AI$2:$AI$9999,SMALL(IF($AF$2:$AF$9999=$P$2, ROW($AI$2:$AI$9999)-ROW($AI$2)+1),ROWS($R$3:R3))),"")} | S3: {=IFERROR( INDEX($AH$2:$AH$9999,SMALL(IF($AF$2:$AF$9999=$S$2, ROW($AH$2:$AH$9999)-ROW($AH$2)+1),ROWS($S$3:S3))),"")} | T3: {=IFERROR( INDEX($AK$2:$AK$9999,SMALL(IF($AF$2:$AF$9999=$S$2, ROW($AK$2:$AK$9999)-ROW($AK$2)+1),ROWS($S$3:T3))),"")} | U3: {=IFERROR( INDEX($AI$2:$AI$9999,SMALL(IF($AF$2:$AF$9999=$S$2, ROW($AI$2:$AI$9999)-ROW($AI$2)+1),ROWS($U$3:U3))),"")} | V3: {=IFERROR( INDEX($AH$2:$AH$9999,SMALL(IF($AF$2:$AF$9999=$V$2, ROW($AH$2:$AH$9999)-ROW($AH$2)+1),ROWS($V$3:V3))),"")} -> 한국비앤씨㈜ | W3: {=IFERROR( INDEX($AK$2:$AK$9999,SMALL(IF($AF$2:$AF$9999=$V$2, ROW($AK$2:$AK$9999)-ROW($AK$2)+1),ROWS($V$3:W3))),"")} -> MMDA | X3: {=IFERROR( INDEX($AI$2:$AI$9999,SMALL(IF($AF$2:$AF$9999=$V$2, ROW($AI$2:$AI$9999)-ROW($AI$2)+1),ROWS($X$3:X3))),"")} -> 8.67 | Y3: {=IFERROR( INDEX($AH$2:$AH$9999,SMALL(IF($AF$2:$AF$9999=$Y$2, ROW($AH$2:$AH$9999)-ROW($AH$2)+1),ROWS($Y$3:Y3))),"")} -> ㈜비앤에프 | Z3: {=IFERROR( INDEX($AK$2:$AK$9999,SMALL(IF($AF$2:$AF$9999=$Y$2, ROW($AK$2:$AK$9999)-ROW($AK$2)+1),ROWS($Y$3:Z3))),"")} -> 정기예금 | AA3: {=IFERROR( INDEX($AI$2:$AI$9999,SMALL(IF($AF$2:$AF$9999=$Y$2, ROW($AI$2:$AI$9999)-ROW($AI$2)+1),ROWS($AA$3:AA3))),"")} -> 1 | AB3: {=IFERROR( INDEX($AH$2:$AH$9999,SMALL(IF($AF$2:$AF$9999=$AB$2, ROW($AH$2:$AH$9999)-ROW($AH$2)+1),ROWS($AB$3:AB3))),"")} | AC3: {=IFERROR( INDEX($AK$2:$AK$9999,SMALL(IF($AF$2:$AF$9999=$AB$2, ROW($AK$2:$AK$9999)-ROW($AK$2)+1),ROWS($AB$3:AC3))),"")} | AD3: {=IFERROR( INDEX($AI$2:$AI$9999,SMALL(IF($AF$2:$AF$9999=$AB$2, ROW($AI$2:$AI$9999)-ROW($AI$2)+1),ROWS($AD$3:AD3))),"")} | AE3: ='(1)예금승인내역'!H633 -> 45313 | AF3: =VALUE(AE3) -> 45313 | AG3: ='(1)예금승인내역'!G633 -> 45280 | AH3: ='(1)예금승인내역'!F633 -> 주식회사 한국비앤씨 | AI3: ='(1)예금승인내역'!L633 -> 5 | AJ3: ='(1)예금승인내역'!AG633 -> 0.0525 | AK3: ='(1)예금승인내역'!K633 -> 정기예금
A4: {=IFERROR( INDEX($AH$2:$AH$9999,SMALL(IF($AF$2:$AF$9999=$A$2, ROW($AH$2:$AH$9999)-ROW($AH$2)+1),ROWS(A$3:$A4))),"")} -> ㈜현대그린푸드 | B4: {=IFERROR( INDEX($AK$2:$AK$9999,SMALL(IF($AF$2:$AF$9999=$A$2, ROW($AK$2:$AK$9999)-ROW($AK$2)+1),ROWS($A$3:B4))),"")} -> MMDA | C4: {=IFERROR( INDEX($AI$2:$AI$9999,SMALL(IF($AF$2:$AF$9999=$A$2, ROW($AI$2:$AI$9999)-ROW($AI$2)+1),ROWS($A$3:C4))),"")} -> 1.43 | D4: {=IFERROR( INDEX($AH$2:$AH$9999,SMALL(IF($AF$2:$AF$9999=$D$2, ROW($AH$2:$AH$9999)-ROW($AH$2)+1),ROWS($D$3:D4))),"")} -> 해내다컨트리클럽 | E4: {=IFERROR( INDEX($AK$2:$AK$9999,SMALL(IF($AF$2:$AF$9999=$D$2, ROW($AK$2:$AK$9999)-ROW($AK$2)+1),ROWS($D$3:E4))),"")} -> 정기예금 | F4: {=IFERROR( INDEX($AI$2:$AI$9999,SMALL(IF($AF$2:$AF$9999=$D$2, ROW($AI$2:$AI$9999)-ROW($AI$2)+1),ROWS($F$3:F4))),"")} -> 3.65 | G4: {=IFERROR( INDEX($AH$2:$AH$9999,SMALL(IF($AF$2:$AF$9999=$G$2, ROW($AH$2:$AH$9999)-ROW($AH$2)+1),ROWS($G$3:G4))),"")} | H4: {=IFERROR( INDEX($AK$2:$AK$9999,SMALL(IF($AF$2:$AF$9999=$G$2, ROW($AK$2:$AK$9999)-ROW($AK$2)+1),ROWS($G$3:H4))),"")} | I4: {=IFERROR( INDEX($AI$2:$AI$9999,SMALL(IF($AF$2:$AF$9999=$G$2, ROW($AI$2:$AI$9999)-ROW($AI$2)+1),ROWS($I$3:I4))),"")} | J4: {=IFERROR( INDEX($AH$2:$AH$9999,SMALL(IF($AF$2:$AF$9999=$J$2, ROW($AH$2:$AH$9999)-ROW($AH$2)+1),ROWS($J$3:J4))),"")} | K4: {=IFERROR( INDEX($AK$2:$AK$9999,SMALL(IF($AF$2:$AF$9999=$J$2, ROW($AK$2:$AK$9999)-ROW($AK$2)+1),ROWS($J$3:K4))),"")} | L4: {=IFERROR( INDEX($AI$2:$AI$9999,SMALL(IF($AF$2:$AF$9999=$J$2, ROW($AI$2:$AI$9999)-ROW($AI$2)+1),ROWS($L$3:L4))),"")} | M4: {=IFERROR( INDEX($AH$2:$AH$9999,SMALL(IF($AF$2:$AF$9999=$M$2, ROW($AH$2:$AH$9999)-ROW($AH$2)+1),ROWS($M$3:M4))),"")} -> ㈜약진통상 | N4: {=IFERROR( INDEX($AK$2:$AK$9999,SMALL(IF($AF$2:$AF$9999=$M$2, ROW($AK$2:$AK$9999)-ROW($AK$2)+1),ROWS($M$3:N4))),"")} -> MMDA | O4: {=IFERROR( INDEX($AI$2:$AI$9999,SMALL(IF($AF$2:$AF$9999=$M$2, ROW($AI$2:$AI$9999)-ROW($AI$2)+1),ROWS($O$3:O4))),"")} -> 12.39 | P4: {=IFERROR( INDEX($AH$2:$AH$9999,SMALL(IF($AF$2:$AF$9999=$P$2, ROW($AH$2:$AH$9999)-ROW($AH$2)+1),ROWS($P$3:P4))),"")} | Q4: {=IFERROR( INDEX($AK$2:$AK$9999,SMALL(IF($AF$2:$AF$9999=$P$2, ROW($AK$2:$AK$9999)-ROW($AK$2)+1),ROWS($P$3:Q4))),"")} | R4: {=IFERROR( INDEX($AI$2:$AI$9999,SMALL(IF($AF$2:$AF$9999=$P$2, ROW($AI$2:$AI$9999)-ROW($AI$2)+1),ROWS($R$3:R4))),"")} | S4: {=IFERROR( INDEX($AH$2:$AH$9999,SMALL(IF($AF$2:$AF$9999=$S$2, ROW($AH$2:$AH$9999)-ROW($AH$2)+1),ROWS($S$3:S4))),"")} | T4: {=IFERROR( INDEX($AK$2:$AK$9999,SMALL(IF($AF$2:$AF$9999=$S$2, ROW($AK$2:$AK$9999)-ROW($AK$2)+1),ROWS($S$3:T4))),"")} | U4: {=IFERROR( INDEX($AI$2:$AI$9999,SMALL(IF($AF$2:$AF$9999=$S$2, ROW($AI$2:$AI$9999)-ROW($AI$2)+1),ROWS($U$3:U4))),"")} | V4: {=IFERROR( INDEX($AH$2:$AH$9999,SMALL(IF($AF$2:$AF$9999=$V$2, ROW($AH$2:$AH$9999)-ROW($AH$2)+1),ROWS($V$3:V4))),"")} -> 더스킨팩토리 | W4: {=IFERROR( INDEX($AK$2:$AK$9999,SMALL(IF($AF$2:$AF$9999=$V$2, ROW($AK$2:$AK$9999)-ROW($AK$2)+1),ROWS($V$3:W4))),"")} -> 정기예금 | X4: {=IFERROR( INDEX($AI$2:$AI$9999,SMALL(IF($AF$2:$AF$9999=$V$2, ROW($AI$2:$AI$9999)-ROW($AI$2)+1),ROWS($X$3:X4))),"")} -> 1 | Y4: {=IFERROR( INDEX($AH$2:$AH$9999,SMALL(IF($AF$2:$AF$9999=$Y$2, ROW($AH$2:$AH$9999)-ROW($AH$2)+1),ROWS($Y$3:Y4))),"")} -> ㈜비앤에프 | Z4: {=IFERROR( INDEX($AK$2:$AK$9999,SMALL(IF($AF$2:$AF$9999=$Y$2, ROW($AK$2:$AK$9999)-ROW($AK$2)+1),ROWS($Y$3:Z4))),"")} -> 정기예금 | AA4: {=IFERROR( INDEX($AI$2:$AI$9999,SMALL(IF($AF$2:$AF$9999=$Y$2, ROW($AI$2:$AI$9999)-ROW($AI$2)+1),ROWS($AA$3:AA4))),"")} -> 1 | AB4: {=IFERROR( INDEX($AH$2:$AH$9999,SMALL(IF($AF$2:$AF$9999=$AB$2, ROW($AH$2:$AH$9999)-ROW($AH$2)+1),ROWS($AB$3:AB4))),"")} | AC4: {=IFERROR( INDEX($AK$2:$AK$9999,SMALL(IF($AF$2:$AF$9999=$AB$2, ROW($AK$2:$AK$9999)-ROW($AK$2)+1),ROWS($AB$3:AC4))),"")} | AD4: {=IFERROR( INDEX($AI$2:$AI$9999,SMALL(IF($AF$2:$AF$9999=$AB$2, ROW($AI$2:$AI$9999)-ROW($AI$2)+1),ROWS($AD$3:AD4))),"")} | AE4: ='(1)예금승인내역'!H634 -> 45313 | AF4: =VALUE(AE4) -> 45313 | AG4: ='(1)예금승인내역'!G634 -> 45280 | AH4: ='(1)예금승인내역'!F634 -> ㈜대우로지스틱스 | AI4: ='(1)예금승인내역'!L634 -> 1 | AJ4: ='(1)예금승인내역'!AG634 -> 0.0435 | AK4: ='(1)예금승인내역'!K634 -> MMDA
A5: {=IFERROR( INDEX($AH$2:$AH$9999,SMALL(IF($AF$2:$AF$9999=$A$2, ROW($AH$2:$AH$9999)-ROW($AH$2)+1),ROWS(A$3:$A5))),"")} -> 와이엠에스에이 | B5: {=IFERROR( INDEX($AK$2:$AK$9999,SMALL(IF($AF$2:$AF$9999=$A$2, ROW($AK$2:$AK$9999)-ROW($AK$2)+1),ROWS($A$3:B5))),"")} -> MMDA | C5: {=IFERROR( INDEX($AI$2:$AI$9999,SMALL(IF($AF$2:$AF$9999=$A$2, ROW($AI$2:$AI$9999)-ROW($AI$2)+1),ROWS($A$3:C5))),"")} -> 4.3 | D5: {=IFERROR( INDEX($AH$2:$AH$9999,SMALL(IF($AF$2:$AF$9999=$D$2, ROW($AH$2:$AH$9999)-ROW($AH$2)+1),ROWS($D$3:D5))),"")} -> 거림테크주식회사 | E5: {=IFERROR( INDEX($AK$2:$AK$9999,SMALL(IF($AF$2:$AF$9999=$D$2, ROW($AK$2:$AK$9999)-ROW($AK$2)+1),ROWS($D$3:E5))),"")} -> 정기예금 | F5: {=IFERROR( INDEX($AI$2:$AI$9999,SMALL(IF($AF$2:$AF$9999=$D$2, ROW($AI$2:$AI$9999)-ROW($AI$2)+1),ROWS($F$3:F5))),"")} -> 2 | G5: {=IFERROR( INDEX($AH$2:$AH$9999,SMALL(IF($AF$2:$AF$9999=$G$2, ROW($AH$2:$AH$9999)-ROW($AH$2)+1),ROWS($G$3:G5))),"")} | H5: {=IFERROR( INDEX($AK$2:$AK$9999,SMALL(IF($AF$2:$AF$9999=$G$2, ROW($AK$2:$AK$9999)-ROW($AK$2)+1),ROWS($G$3:H5))),"")} | I5: {=IFERROR( INDEX($AI$2:$AI$9999,SMALL(IF($AF$2:$AF$9999=$G$2, ROW($AI$2:$AI$9999)-ROW($AI$2)+1),ROWS($I$3:I5))),"")} | J5: {=IFERROR( INDEX($AH$2:$AH$9999,SMALL(IF($AF$2:$AF$9999=$J$2, ROW($AH$2:$AH$9999)-ROW($AH$2)+1),ROWS($J$3:J5))),"")} | K5: {=IFERROR( INDEX($AK$2:$AK$9999,SMALL(IF($AF$2:$AF$9999=$J$2, ROW($AK$2:$AK$9999)-ROW($AK$2)+1),ROWS($J$3:K5))),"")} | L5: {=IFERROR( INDEX($AI$2:$AI$9999,SMALL(IF($AF$2:$AF$9999=$J$2, ROW($AI$2:$AI$9999)-ROW($AI$2)+1),ROWS($L$3:L5))),"")} | M5: {=IFERROR( INDEX($AH$2:$AH$9999,SMALL(IF($AF$2:$AF$9999=$M$2, ROW($AH$2:$AH$9999)-ROW($AH$2)+1),ROWS($M$3:M5))),"")} -> ㈜약진통상 | N5: {=IFERROR( INDEX($AK$2:$AK$9999,SMALL(IF($AF$2:$AF$9999=$M$2, ROW($AK$2:$AK$9999)-ROW($AK$2)+1),ROWS($M$3:N5))),"")} -> MMDA | O5: {=IFERROR( INDEX($AI$2:$AI$9999,SMALL(IF($AF$2:$AF$9999=$M$2, ROW($AI$2:$AI$9999)-ROW($AI$2)+1),ROWS($O$3:O5))),"")} -> 12.39 | P5: {=IFERROR( INDEX($AH$2:$AH$9999,SMALL(IF($AF$2:$AF$9999=$P$2, ROW($AH$2:$AH$9999)-ROW($AH$2)+1),ROWS($P$3:P5))),"")} | Q5: {=IFERROR( INDEX($AK$2:$AK$9999,SMALL(IF($AF$2:$AF$9999=$P$2, ROW($AK$2:$AK$9999)-ROW($AK$2)+1),ROWS($P$3:Q5))),"")} | R5: {=IFERROR( INDEX($AI$2:$AI$9999,SMALL(IF($AF$2:$AF$9999=$P$2, ROW($AI$2:$AI$9999)-ROW($AI$2)+1),ROWS($R$3:R5))),"")} | S5: {=IFERROR( INDEX($AH$2:$AH$9999,SMALL(IF($AF$2:$AF$9999=$S$2, ROW($AH$2:$AH$9999)-ROW($AH$2)+1),ROWS($S$3:S5))),"")} | T5: {=IFERROR( INDEX($AK$2:$AK$9999,SMALL(IF($AF$2:$AF$9999=$S$2, ROW($AK$2:$AK$9999)-ROW($AK$2)+1),ROWS($S$3:T5))),"")} | U5: {=IFERROR( INDEX($AI$2:$AI$9999,SMALL(IF($AF$2:$AF$9999=$S$2, ROW($AI$2:$AI$9999)-ROW($AI$2)+1),ROWS($U$3:U5))),"")} | V5: {=IFERROR( INDEX($AH$2:$AH$9999,SMALL(IF($AF$2:$AF$9999=$V$2, ROW($AH$2:$AH$9999)-ROW($AH$2)+1),ROWS($V$3:V5))),"")} | W5: {=IFERROR( INDEX($AK$2:$AK$9999,SMALL(IF($AF$2:$AF$9999=$V$2, ROW($AK$2:$AK$9999)-ROW($AK$2)+1),ROWS($V$3:W5))),"")} | X5: {=IFERROR( INDEX($AI$2:$AI$9999,SMALL(IF($AF$2:$AF$9999=$V$2, ROW($AI$2:$AI$9999)-ROW($AI$2)+1),ROWS($X$3:X5))),"")} | Y5: {=IFERROR( INDEX($AH$2:$AH$9999,SMALL(IF($AF$2:$AF$9999=$Y$2, ROW($AH$2:$AH$9999)-ROW($AH$2)+1),ROWS($Y$3:Y5))),"")} | Z5: {=IFERROR( INDEX($AK$2:$AK$9999,SMALL(IF($AF$2:$AF$9999=$Y$2, ROW($AK$2:$AK$9999)-ROW($AK$2)+1),ROWS($Y$3:Z5))),"")} | AA5: {=IFERROR( INDEX($AI$2:$AI$9999,SMALL(IF($AF$2:$AF$9999=$Y$2, ROW($AI$2:$AI$9999)-ROW($AI$2)+1),ROWS($AA$3:AA5))),"")} | AB5: {=IFERROR( INDEX($AH$2:$AH$9999,SMALL(IF($AF$2:$AF$9999=$AB$2, ROW($AH$2:$AH$9999)-ROW($AH$2)+1),ROWS($AB$3:AB5))),"")} | AC5: {=IFERROR( INDEX($AK$2:$AK$9999,SMALL(IF($AF$2:$AF$9999=$AB$2, ROW($AK$2:$AK$9999)-ROW($AK$2)+1),ROWS($AB$3:AC5))),"")} | AD5: {=IFERROR( INDEX($AI$2:$AI$9999,SMALL(IF($AF$2:$AF$9999=$AB$2, ROW($AI$2:$AI$9999)-ROW($AI$2)+1),ROWS($AD$3:AD5))),"")} | AE5: ='(1)예금승인내역'!H635 -> 45659 | AF5: =VALUE(AE5) -> 45659 | AG5: ='(1)예금승인내역'!G635 -> 45293 | AH5: ='(1)예금승인내역'!F635 -> 윤만수 | AI5: ='(1)예금승인내역'!L635 -> 1 | AJ5: ='(1)예금승인내역'!AG635 -> 0.05 | AK5: ='(1)예금승인내역'!K635 -> 정기예금
A6: {=IFERROR( INDEX($AH$2:$AH$9999,SMALL(IF($AF$2:$AF$9999=$A$2, ROW($AH$2:$AH$9999)-ROW($AH$2)+1),ROWS(A$3:$A6))),"")} -> 엘티메탈 | B6: {=IFERROR( INDEX($AK$2:$AK$9999,SMALL(IF($AF$2:$AF$9999=$A$2, ROW($AK$2:$AK$9999)-ROW($AK$2)+1),ROWS($A$3:B6))),"")} -> MMDA | C6: {=IFERROR( INDEX($AI$2:$AI$9999,SMALL(IF($AF$2:$AF$9999=$A$2, ROW($AI$2:$AI$9999)-ROW($AI$2)+1),ROWS($A$3:C6))),"")} -> 7 | D6: {=IFERROR( INDEX($AH$2:$AH$9999,SMALL(IF($AF$2:$AF$9999=$D$2, ROW($AH$2:$AH$9999)-ROW($AH$2)+1),ROWS($D$3:D6))),"")} | E6: {=IFERROR( INDEX($AK$2:$AK$9999,SMALL(IF($AF$2:$AF$9999=$D$2, ROW($AK$2:$AK$9999)-ROW($AK$2)+1),ROWS($D$3:E6))),"")} | F6: {=IFERROR( INDEX($AI$2:$AI$9999,SMALL(IF($AF$2:$AF$9999=$D$2, ROW($AI$2:$AI$9999)-ROW($AI$2)+1),ROWS($F$3:F6))),"")} | G6: {=IFERROR( INDEX($AH$2:$AH$9999,SMALL(IF($AF$2:$AF$9999=$G$2, ROW($AH$2:$AH$9999)-ROW($AH$2)+1),ROWS($G$3:G6))),"")} | H6: {=IFERROR( INDEX($AK$2:$AK$9999,SMALL(IF($AF$2:$AF$9999=$G$2, ROW($AK$2:$AK$9999)-ROW($AK$2)+1),ROWS($G$3:H6))),"")} | I6: {=IFERROR( INDEX($AI$2:$AI$9999,SMALL(IF($AF$2:$AF$9999=$G$2, ROW($AI$2:$AI$9999)-ROW($AI$2)+1),ROWS($I$3:I6))),"")} | J6: {=IFERROR( INDEX($AH$2:$AH$9999,SMALL(IF($AF$2:$AF$9999=$J$2, ROW($AH$2:$AH$9999)-ROW($AH$2)+1),ROWS($J$3:J6))),"")} | K6: {=IFERROR( INDEX($AK$2:$AK$9999,SMALL(IF($AF$2:$AF$9999=$J$2, ROW($AK$2:$AK$9999)-ROW($AK$2)+1),ROWS($J$3:K6))),"")} | L6: {=IFERROR( INDEX($AI$2:$AI$9999,SMALL(IF($AF$2:$AF$9999=$J$2, ROW($AI$2:$AI$9999)-ROW($AI$2)+1),ROWS($L$3:L6))),"")} | M6: {=IFERROR( INDEX($AH$2:$AH$9999,SMALL(IF($AF$2:$AF$9999=$M$2, ROW($AH$2:$AH$9999)-ROW($AH$2)+1),ROWS($M$3:M6))),"")} -> 대원지에스아이 | N6: {=IFERROR( INDEX($AK$2:$AK$9999,SMALL(IF($AF$2:$AF$9999=$M$2, ROW($AK$2:$AK$9999)-ROW($AK$2)+1),ROWS($M$3:N6))),"")} -> 정기예금 | O6: {=IFERROR( INDEX($AI$2:$AI$9999,SMALL(IF($AF$2:$AF$9999=$M$2, ROW($AI$2:$AI$9999)-ROW($AI$2)+1),ROWS($O$3:O6))),"")} -> 1.5 | P6: {=IFERROR( INDEX($AH$2:$AH$9999,SMALL(IF($AF$2:$AF$9999=$P$2, ROW($AH$2:$AH$9999)-ROW($AH$2)+1),ROWS($P$3:P6))),"")} | Q6: {=IFERROR( INDEX($AK$2:$AK$9999,SMALL(IF($AF$2:$AF$9999=$P$2, ROW($AK$2:$AK$9999)-ROW($AK$2)+1),ROWS($P$3:Q6))),"")} | R6: {=IFERROR( INDEX($AI$2:$AI$9999,SMALL(IF($AF$2:$AF$9999=$P$2, ROW($AI$2:$AI$9999)-ROW($AI$2)+1),ROWS($R$3:R6))),"")} | S6: {=IFERROR( INDEX($AH$2:$AH$9999,SMALL(IF($AF$2:$AF$9999=$S$2, ROW($AH$2:$AH$9999)-ROW($AH$2)+1),ROWS($S$3:S6))),"")} | T6: {=IFERROR( INDEX($AK$2:$AK$9999,SMALL(IF($AF$2:$AF$9999=$S$2, ROW($AK$2:$AK$9999)-ROW($AK$2)+1),ROWS($S$3:T6))),"")} | U6: {=IFERROR( INDEX($AI$2:$AI$9999,SMALL(IF($AF$2:$AF$9999=$S$2, ROW($AI$2:$AI$9999)-ROW($AI$2)+1),ROWS($U$3:U6))),"")} | V6: {=IFERROR( INDEX($AH$2:$AH$9999,SMALL(IF($AF$2:$AF$9999=$V$2, ROW($AH$2:$AH$9999)-ROW($AH$2)+1),ROWS($V$3:V6))),"")} | W6: {=IFERROR( INDEX($AK$2:$AK$9999,SMALL(IF($AF$2:$AF$9999=$V$2, ROW($AK$2:$AK$9999)-ROW($AK$2)+1),ROWS($V$3:W6))),"")} | X6: {=IFERROR( INDEX($AI$2:$AI$9999,SMALL(IF($AF$2:$AF$9999=$V$2, ROW($AI$2:$AI$9999)-ROW($AI$2)+1),ROWS($X$3:X6))),"")} | Y6: {=IFERROR( INDEX($AH$2:$AH$9999,SMALL(IF($AF$2:$AF$9999=$Y$2, ROW($AH$2:$AH$9999)-ROW($AH$2)+1),ROWS($Y$3:Y6))),"")} | Z6: {=IFERROR( INDEX($AK$2:$AK$9999,SMALL(IF($AF$2:$AF$9999=$Y$2, ROW($AK$2:$AK$9999)-ROW($AK$2)+1),ROWS($Y$3:Z6))),"")} | AA6: {=IFERROR( INDEX($AI$2:$AI$9999,SMALL(IF($AF$2:$AF$9999=$Y$2, ROW($AI$2:$AI$9999)-ROW($AI$2)+1),ROWS($AA$3:AA6))),"")} | AB6: {=IFERROR( INDEX($AH$2:$AH$9999,SMALL(IF($AF$2:$AF$9999=$AB$2, ROW($AH$2:$AH$9999)-ROW($AH$2)+1),ROWS($AB$3:AB6))),"")} | AC6: {=IFERROR( INDEX($AK$2:$AK$9999,SMALL(IF($AF$2:$AF$9999=$AB$2, ROW($AK$2:$AK$9999)-ROW($AK$2)+1),ROWS($AB$3:AC6))),"")} | AD6: {=IFERROR( INDEX($AI$2:$AI$9999,SMALL(IF($AF$2:$AF$9999=$AB$2, ROW($AI$2:$AI$9999)-ROW($AI$2)+1),ROWS($AD$3:AD6))),"")} | AE6: ='(1)예금승인내역'!H636 -> 45659 | AF6: =VALUE(AE6) -> 45659 | AG6: ='(1)예금승인내역'!G636 -> 45293 | AH6: ='(1)예금승인내역'!F636 -> 윤만수 | AI6: ='(1)예금승인내역'!L636 -> 0.5 | AJ6: ='(1)예금승인내역'!AG636 -> 0.05 | AK6: ='(1)예금승인내역'!K636 -> 정기예금
A7: {=IFERROR( INDEX($AH$2:$AH$9999,SMALL(IF($AF$2:$AF$9999=$A$2, ROW($AH$2:$AH$9999)-ROW($AH$2)+1),ROWS(A$3:$A7))),"")} | B7: {=IFERROR( INDEX($AK$2:$AK$9999,SMALL(IF($AF$2:$AF$9999=$A$2, ROW($AK$2:$AK$9999)-ROW($AK$2)+1),ROWS($A$3:B7))),"")} | C7: {=IFERROR( INDEX($AI$2:$AI$9999,SMALL(IF($AF$2:$AF$9999=$A$2, ROW($AI$2:$AI$9999)-ROW($AI$2)+1),ROWS($A$3:C7))),"")} | D7: {=IFERROR( INDEX($AH$2:$AH$9999,SMALL(IF($AF$2:$AF$9999=$D$2, ROW($AH$2:$AH$9999)-ROW($AH$2)+1),ROWS($D$3:D7))),"")} | E7: {=IFERROR( INDEX($AK$2:$AK$9999,SMALL(IF($AF$2:$AF$9999=$D$2, ROW($AK$2:$AK$9999)-ROW($AK$2)+1),ROWS($D$3:E7))),"")} | F7: {=IFERROR( INDEX($AI$2:$AI$9999,SMALL(IF($AF$2:$AF$9999=$D$2, ROW($AI$2:$AI$9999)-ROW($AI$2)+1),ROWS($F$3:F7))),"")} | G7: {=IFERROR( INDEX($AH$2:$AH$9999,SMALL(IF($AF$2:$AF$9999=$G$2, ROW($AH$2:$AH$9999)-ROW($AH$2)+1),ROWS($G$3:G7))),"")} | H7: {=IFERROR( INDEX($AK$2:$AK$9999,SMALL(IF($AF$2:$AF$9999=$G$2, ROW($AK$2:$AK$9999)-ROW($AK$2)+1),ROWS($G$3:H7))),"")} | I7: {=IFERROR( INDEX($AI$2:$AI$9999,SMALL(IF($AF$2:$AF$9999=$G$2, ROW($AI$2:$AI$9999)-ROW($AI$2)+1),ROWS($I$3:I7))),"")} | J7: {=IFERROR( INDEX($AH$2:$AH$9999,SMALL(IF($AF$2:$AF$9999=$J$2, ROW($AH$2:$AH$9999)-ROW($AH$2)+1),ROWS($J$3:J7))),"")} | K7: {=IFERROR( INDEX($AK$2:$AK$9999,SMALL(IF($AF$2:$AF$9999=$J$2, ROW($AK$2:$AK$9999)-ROW($AK$2)+1),ROWS($J$3:K7))),"")} | L7: {=IFERROR( INDEX($AI$2:$AI$9999,SMALL(IF($AF$2:$AF$9999=$J$2, ROW($AI$2:$AI$9999)-ROW($AI$2)+1),ROWS($L$3:L7))),"")} | M7: {=IFERROR( INDEX($AH$2:$AH$9999,SMALL(IF($AF$2:$AF$9999=$M$2, ROW($AH$2:$AH$9999)-ROW($AH$2)+1),ROWS($M$3:M7))),"")} -> ㈜비알팜 | N7: {=IFERROR( INDEX($AK$2:$AK$9999,SMALL(IF($AF$2:$AF$9999=$M$2, ROW($AK$2:$AK$9999)-ROW($AK$2)+1),ROWS($M$3:N7))),"")} -> MMDA | O7: {=IFERROR( INDEX($AI$2:$AI$9999,SMALL(IF($AF$2:$AF$9999=$M$2, ROW($AI$2:$AI$9999)-ROW($AI$2)+1),ROWS($O$3:O7))),"")} -> 5.73 | P7: {=IFERROR( INDEX($AH$2:$AH$9999,SMALL(IF($AF$2:$AF$9999=$P$2, ROW($AH$2:$AH$9999)-ROW($AH$2)+1),ROWS($P$3:P7))),"")} | Q7: {=IFERROR( INDEX($AK$2:$AK$9999,SMALL(IF($AF$2:$AF$9999=$P$2, ROW($AK$2:$AK$9999)-ROW($AK$2)+1),ROWS($P$3:Q7))),"")} | R7: {=IFERROR( INDEX($AI$2:$AI$9999,SMALL(IF($AF$2:$AF$9999=$P$2, ROW($AI$2:$AI$9999)-ROW($AI$2)+1),ROWS($R$3:R7))),"")} | S7: {=IFERROR( INDEX($AH$2:$AH$9999,SMALL(IF($AF$2:$AF$9999=$S$2, ROW($AH$2:$AH$9999)-ROW($AH$2)+1),ROWS($S$3:S7))),"")} | T7: {=IFERROR( INDEX($AK$2:$AK$9999,SMALL(IF($AF$2:$AF$9999=$S$2, ROW($AK$2:$AK$9999)-ROW($AK$2)+1),ROWS($S$3:T7))),"")} | U7: {=IFERROR( INDEX($AI$2:$AI$9999,SMALL(IF($AF$2:$AF$9999=$S$2, ROW($AI$2:$AI$9999)-ROW($AI$2)+1),ROWS($U$3:U7))),"")} | V7: {=IFERROR( INDEX($AH$2:$AH$9999,SMALL(IF($AF$2:$AF$9999=$V$2, ROW($AH$2:$AH$9999)-ROW($AH$2)+1),ROWS($V$3:V7))),"")} | W7: {=IFERROR( INDEX($AK$2:$AK$9999,SMALL(IF($AF$2:$AF$9999=$V$2, ROW($AK$2:$AK$9999)-ROW($AK$2)+1),ROWS($V$3:W7))),"")} | X7: {=IFERROR( INDEX($AI$2:$AI$9999,SMALL(IF($AF$2:$AF$9999=$V$2, ROW($AI$2:$AI$9999)-ROW($AI$2)+1),ROWS($X$3:X7))),"")} | Y7: {=IFERROR( INDEX($AH$2:$AH$9999,SMALL(IF($AF$2:$AF$9999=$Y$2, ROW($AH$2:$AH$9999)-ROW($AH$2)+1),ROWS($Y$3:Y7))),"")} | Z7: {=IFERROR( INDEX($AK$2:$AK$9999,SMALL(IF($AF$2:$AF$9999=$Y$2, ROW($AK$2:$AK$9999)-ROW($AK$2)+1),ROWS($Y$3:Z7))),"")} | AA7: {=IFERROR( INDEX($AI$2:$AI$9999,SMALL(IF($AF$2:$AF$9999=$Y$2, ROW($AI$2:$AI$9999)-ROW($AI$2)+1),ROWS($AA$3:AA7))),"")} | AB7: {=IFERROR( INDEX($AH$2:$AH$9999,SMALL(IF($AF$2:$AF$9999=$AB$2, ROW($AH$2:$AH$9999)-ROW($AH$2)+1),ROWS($AB$3:AB7))),"")} | AC7: {=IFERROR( INDEX($AK$2:$AK$9999,SMALL(IF($AF$2:$AF$9999=$AB$2, ROW($AK$2:$AK$9999)-ROW($AK$2)+1),ROWS($AB$3:AC7))),"")} | AD7: {=IFERROR( INDEX($AI$2:$AI$9999,SMALL(IF($AF$2:$AF$9999=$AB$2, ROW($AI$2:$AI$9999)-ROW($AI$2)+1),ROWS($AD$3:AD7))),"")} | AE7: ='(1)예금승인내역'!H637 -> 45335 | AF7: =VALUE(AE7) -> 45335 | AG7: ='(1)예금승인내역'!G637 -> 45302 | AH7: ='(1)예금승인내역'!F637 -> 한국비철㈜ | AI7: ='(1)예금승인내역'!L637 -> 8.59 | AJ7: ='(1)예금승인내역'!AG637 -> 0.043 | AK7: ='(1)예금승인내역'!K637 -> MMDA
A8: {=IFERROR( INDEX($AH$2:$AH$9999,SMALL(IF($AF$2:$AF$9999=$A$2, ROW($AH$2:$AH$9999)-ROW($AH$2)+1),ROWS(A$3:$A8))),"")} | B8: {=IFERROR( INDEX($AK$2:$AK$9999,SMALL(IF($AF$2:$AF$9999=$A$2, ROW($AK$2:$AK$9999)-ROW($AK$2)+1),ROWS($A$3:B8))),"")} | C8: {=IFERROR( INDEX($AI$2:$AI$9999,SMALL(IF($AF$2:$AF$9999=$A$2, ROW($AI$2:$AI$9999)-ROW($AI$2)+1),ROWS($A$3:C8))),"")} | D8: {=IFERROR( INDEX($AH$2:$AH$9999,SMALL(IF($AF$2:$AF$9999=$D$2, ROW($AH$2:$AH$9999)-ROW($AH$2)+1),ROWS($D$3:D8))),"")} | E8: {=IFERROR( INDEX($AK$2:$AK$9999,SMALL(IF($AF$2:$AF$9999=$D$2, ROW($AK$2:$AK$9999)-ROW($AK$2)+1),ROWS($D$3:E8))),"")} | F8: {=IFERROR( INDEX($AI$2:$AI$9999,SMALL(IF($AF$2:$AF$9999=$D$2, ROW($AI$2:$AI$9999)-ROW($AI$2)+1),ROWS($F$3:F8))),"")} | G8: {=IFERROR( INDEX($AH$2:$AH$9999,SMALL(IF($AF$2:$AF$9999=$G$2, ROW($AH$2:$AH$9999)-ROW($AH$2)+1),ROWS($G$3:G8))),"")} | H8: {=IFERROR( INDEX($AK$2:$AK$9999,SMALL(IF($AF$2:$AF$9999=$G$2, ROW($AK$2:$AK$9999)-ROW($AK$2)+1),ROWS($G$3:H8))),"")} | I8: {=IFERROR( INDEX($AI$2:$AI$9999,SMALL(IF($AF$2:$AF$9999=$G$2, ROW($AI$2:$AI$9999)-ROW($AI$2)+1),ROWS($I$3:I8))),"")} | J8: {=IFERROR( INDEX($AH$2:$AH$9999,SMALL(IF($AF$2:$AF$9999=$J$2, ROW($AH$2:$AH$9999)-ROW($AH$2)+1),ROWS($J$3:J8))),"")} | K8: {=IFERROR( INDEX($AK$2:$AK$9999,SMALL(IF($AF$2:$AF$9999=$J$2, ROW($AK$2:$AK$9999)-ROW($AK$2)+1),ROWS($J$3:K8))),"")} | L8: {=IFERROR( INDEX($AI$2:$AI$9999,SMALL(IF($AF$2:$AF$9999=$J$2, ROW($AI$2:$AI$9999)-ROW($AI$2)+1),ROWS($L$3:L8))),"")} | M8: {=IFERROR( INDEX($AH$2:$AH$9999,SMALL(IF($AF$2:$AF$9999=$M$2, ROW($AH$2:$AH$9999)-ROW($AH$2)+1),ROWS($M$3:M8))),"")} | N8: {=IFERROR( INDEX($AK$2:$AK$9999,SMALL(IF($AF$2:$AF$9999=$M$2, ROW($AK$2:$AK$9999)-ROW($AK$2)+1),ROWS($M$3:N8))),"")} | O8: {=IFERROR( INDEX($AI$2:$AI$9999,SMALL(IF($AF$2:$AF$9999=$M$2, ROW($AI$2:$AI$9999)-ROW($AI$2)+1),ROWS($O$3:O8))),"")} | P8: {=IFERROR( INDEX($AH$2:$AH$9999,SMALL(IF($AF$2:$AF$9999=$P$2, ROW($AH$2:$AH$9999)-ROW($AH$2)+1),ROWS($P$3:P8))),"")} | Q8: {=IFERROR( INDEX($AK$2:$AK$9999,SMALL(IF($AF$2:$AF$9999=$P$2, ROW($AK$2:$AK$9999)-ROW($AK$2)+1),ROWS($P$3:Q8))),"")} | R8: {=IFERROR( INDEX($AI$2:$AI$9999,SMALL(IF($AF$2:$AF$9999=$P$2, ROW($AI$2:$AI$9999)-ROW($AI$2)+1),ROWS($R$3:R8))),"")} | S8: {=IFERROR( INDEX($AH$2:$AH$9999,SMALL(IF($AF$2:$AF$9999=$S$2, ROW($AH$2:$AH$9999)-ROW($AH$2)+1),ROWS($S$3:S8))),"")} | T8: {=IFERROR( INDEX($AK$2:$AK$9999,SMALL(IF($AF$2:$AF$9999=$S$2, ROW($AK$2:$AK$9999)-ROW($AK$2)+1),ROWS($S$3:T8))),"")} | U8: {=IFERROR( INDEX($AI$2:$AI$9999,SMALL(IF($AF$2:$AF$9999=$S$2, ROW($AI$2:$AI$9999)-ROW($AI$2)+1),ROWS($U$3:U8))),"")} | V8: {=IFERROR( INDEX($AH$2:$AH$9999,SMALL(IF($AF$2:$AF$9999=$V$2, ROW($AH$2:$AH$9999)-ROW($AH$2)+1),ROWS($V$3:V8))),"")} | W8: {=IFERROR( INDEX($AK$2:$AK$9999,SMALL(IF($AF$2:$AF$9999=$V$2, ROW($AK$2:$AK$9999)-ROW($AK$2)+1),ROWS($V$3:W8))),"")} | X8: {=IFERROR( INDEX($AI$2:$AI$9999,SMALL(IF($AF$2:$AF$9999=$V$2, ROW($AI$2:$AI$9999)-ROW($AI$2)+1),ROWS($X$3:X8))),"")} | Y8: {=IFERROR( INDEX($AH$2:$AH$9999,SMALL(IF($AF$2:$AF$9999=$Y$2, ROW($AH$2:$AH$9999)-ROW($AH$2)+1),ROWS($Y$3:Y8))),"")} | Z8: {=IFERROR( INDEX($AK$2:$AK$9999,SMALL(IF($AF$2:$AF$9999=$Y$2, ROW($AK$2:$AK$9999)-ROW($AK$2)+1),ROWS($Y$3:Z8))),"")} | AA8: {=IFERROR( INDEX($AI$2:$AI$9999,SMALL(IF($AF$2:$AF$9999=$Y$2, ROW($AI$2:$AI$9999)-ROW($AI$2)+1),ROWS($AA$3:AA8))),"")} | AB8: {=IFERROR( INDEX($AH$2:$AH$9999,SMALL(IF($AF$2:$AF$9999=$AB$2, ROW($AH$2:$AH$9999)-ROW($AH$2)+1),ROWS($AB$3:AB8))),"")} | AC8: {=IFERROR( INDEX($AK$2:$AK$9999,SMALL(IF($AF$2:$AF$9999=$AB$2, ROW($AK$2:$AK$9999)-ROW($AK$2)+1),ROWS($AB$3:AC8))),"")} | AD8: {=IFERROR( INDEX($AI$2:$AI$9999,SMALL(IF($AF$2:$AF$9999=$AB$2, ROW($AI$2:$AI$9999)-ROW($AI$2)+1),ROWS($AD$3:AD8))),"")} | AE8: ='(1)예금승인내역'!H638 -> 45579 | AF8: =VALUE(AE8) -> 45579 | AG8: ='(1)예금승인내역'!G638 -> 45303 | AH8: ='(1)예금승인내역'!F638 -> 케이와이글로벌셀앤진사모투자합자회사 | AI8: ='(1)예금승인내역'!L638 -> 2.48 | AJ8: ='(1)예금승인내역'!AG638 -> 0.0515 | AK8: ='(1)예금승인내역'!K638 -> 정기예금
A9: {=IFERROR( INDEX($AH$2:$AH$9999,SMALL(IF($AF$2:$AF$9999=$A$2, ROW($AH$2:$AH$9999)-ROW($AH$2)+1),ROWS(A$3:$A9))),"")} | B9: {=IFERROR( INDEX($AK$2:$AK$9999,SMALL(IF($AF$2:$AF$9999=$A$2, ROW($AK$2:$AK$9999)-ROW($AK$2)+1),ROWS($A$3:B9))),"")} | C9: {=IFERROR( INDEX($AI$2:$AI$9999,SMALL(IF($AF$2:$AF$9999=$A$2, ROW($AI$2:$AI$9999)-ROW($AI$2)+1),ROWS($A$3:C9))),"")} | D9: {=IFERROR( INDEX($AH$2:$AH$9999,SMALL(IF($AF$2:$AF$9999=$D$2, ROW($AH$2:$AH$9999)-ROW($AH$2)+1),ROWS($D$3:D9))),"")} | E9: {=IFERROR( INDEX($AK$2:$AK$9999,SMALL(IF($AF$2:$AF$9999=$D$2, ROW($AK$2:$AK$9999)-ROW($AK$2)+1),ROWS($D$3:E9))),"")} | F9: {=IFERROR( INDEX($AI$2:$AI$9999,SMALL(IF($AF$2:$AF$9999=$D$2, ROW($AI$2:$AI$9999)-ROW($AI$2)+1),ROWS($F$3:F9))),"")} | G9: {=IFERROR( INDEX($AH$2:$AH$9999,SMALL(IF($AF$2:$AF$9999=$G$2, ROW($AH$2:$AH$9999)-ROW($AH$2)+1),ROWS($G$3:G9))),"")} | H9: {=IFERROR( INDEX($AK$2:$AK$9999,SMALL(IF($AF$2:$AF$9999=$G$2, ROW($AK$2:$AK$9999)-ROW($AK$2)+1),ROWS($G$3:H9))),"")} | I9: {=IFERROR( INDEX($AI$2:$AI$9999,SMALL(IF($AF$2:$AF$9999=$G$2, ROW($AI$2:$AI$9999)-ROW($AI$2)+1),ROWS($I$3:I9))),"")} | J9: {=IFERROR( INDEX($AH$2:$AH$9999,SMALL(IF($AF$2:$AF$9999=$J$2, ROW($AH$2:$AH$9999)-ROW($AH$2)+1),ROWS($J$3:J9))),"")} | K9: {=IFERROR( INDEX($AK$2:$AK$9999,SMALL(IF($AF$2:$AF$9999=$J$2, ROW($AK$2:$AK$9999)-ROW($AK$2)+1),ROWS($J$3:K9))),"")} | L9: {=IFERROR( INDEX($AI$2:$AI$9999,SMALL(IF($AF$2:$AF$9999=$J$2, ROW($AI$2:$AI$9999)-ROW($AI$2)+1),ROWS($L$3:L9))),"")} | M9: {=IFERROR( INDEX($AH$2:$AH$9999,SMALL(IF($AF$2:$AF$9999=$M$2, ROW($AH$2:$AH$9999)-ROW($AH$2)+1),ROWS($M$3:M9))),"")} | N9: {=IFERROR( INDEX($AK$2:$AK$9999,SMALL(IF($AF$2:$AF$9999=$M$2, ROW($AK$2:$AK$9999)-ROW($AK$2)+1),ROWS($M$3:N9))),"")} | O9: {=IFERROR( INDEX($AI$2:$AI$9999,SMALL(IF($AF$2:$AF$9999=$M$2, ROW($AI$2:$AI$9999)-ROW($AI$2)+1),ROWS($O$3:O9))),"")} | P9: {=IFERROR( INDEX($AH$2:$AH$9999,SMALL(IF($AF$2:$AF$9999=$P$2, ROW($AH$2:$AH$9999)-ROW($AH$2)+1),ROWS($P$3:P9))),"")} | Q9: {=IFERROR( INDEX($AK$2:$AK$9999,SMALL(IF($AF$2:$AF$9999=$P$2, ROW($AK$2:$AK$9999)-ROW($AK$2)+1),ROWS($P$3:Q9))),"")} | R9: {=IFERROR( INDEX($AI$2:$AI$9999,SMALL(IF($AF$2:$AF$9999=$P$2, ROW($AI$2:$AI$9999)-ROW($AI$2)+1),ROWS($R$3:R9))),"")} | S9: {=IFERROR( INDEX($AH$2:$AH$9999,SMALL(IF($AF$2:$AF$9999=$S$2, ROW($AH$2:$AH$9999)-ROW($AH$2)+1),ROWS($S$3:S9))),"")} | T9: {=IFERROR( INDEX($AK$2:$AK$9999,SMALL(IF($AF$2:$AF$9999=$S$2, ROW($AK$2:$AK$9999)-ROW($AK$2)+1),ROWS($S$3:T9))),"")} | U9: {=IFERROR( INDEX($AI$2:$AI$9999,SMALL(IF($AF$2:$AF$9999=$S$2, ROW($AI$2:$AI$9999)-ROW($AI$2)+1),ROWS($U$3:U9))),"")} | V9: {=IFERROR( INDEX($AH$2:$AH$9999,SMALL(IF($AF$2:$AF$9999=$V$2, ROW($AH$2:$AH$9999)-ROW($AH$2)+1),ROWS($V$3:V9))),"")} | W9: {=IFERROR( INDEX($AK$2:$AK$9999,SMALL(IF($AF$2:$AF$9999=$V$2, ROW($AK$2:$AK$9999)-ROW($AK$2)+1),ROWS($V$3:W9))),"")} | X9: {=IFERROR( INDEX($AI$2:$AI$9999,SMALL(IF($AF$2:$AF$9999=$V$2, ROW($AI$2:$AI$9999)-ROW($AI$2)+1),ROWS($X$3:X9))),"")} | Y9: {=IFERROR( INDEX($AH$2:$AH$9999,SMALL(IF($AF$2:$AF$9999=$Y$2, ROW($AH$2:$AH$9999)-ROW($AH$2)+1),ROWS($Y$3:Y9))),"")} | Z9: {=IFERROR( INDEX($AK$2:$AK$9999,SMALL(IF($AF$2:$AF$9999=$Y$2, ROW($AK$2:$AK$9999)-ROW($AK$2)+1),ROWS($Y$3:Z9))),"")} | AA9: {=IFERROR( INDEX($AI$2:$AI$9999,SMALL(IF($AF$2:$AF$9999=$Y$2, ROW($AI$2:$AI$9999)-ROW($AI$2)+1),ROWS($AA$3:AA9))),"")} | AB9: {=IFERROR( INDEX($AH$2:$AH$9999,SMALL(IF($AF$2:$AF$9999=$AB$2, ROW($AH$2:$AH$9999)-ROW($AH$2)+1),ROWS($AB$3:AB9))),"")} | AC9: {=IFERROR( INDEX($AK$2:$AK$9999,SMALL(IF($AF$2:$AF$9999=$AB$2, ROW($AK$2:$AK$9999)-ROW($AK$2)+1),ROWS($AB$3:AC9))),"")} | AD9: {=IFERROR( INDEX($AI$2:$AI$9999,SMALL(IF($AF$2:$AF$9999=$AB$2, ROW($AI$2:$AI$9999)-ROW($AI$2)+1),ROWS($AD$3:AD9))),"")} | AE9: ='(1)예금승인내역'!H639 -> 45314 | AF9: =VALUE(AE9) -> 45314 | AG9: ='(1)예금승인내역'!G639 -> 45307 | AH9: ='(1)예금승인내역'!F639 -> 한국석유공사 | AI9: ='(1)예금승인내역'!L639 -> 20 | AJ9: ='(1)예금승인내역'!AG639 -> 0.0505 | AK9: ='(1)예금승인내역'!K639 -> 정기예금
A10: {=IFERROR( INDEX($AH$2:$AH$9999,SMALL(IF($AF$2:$AF$9999=$A$2, ROW($AH$2:$AH$9999)-ROW($AH$2)+1),ROWS(A$3:$A10))),"")} | B10: {=IFERROR( INDEX($AK$2:$AK$9999,SMALL(IF($AF$2:$AF$9999=$A$2, ROW($AK$2:$AK$9999)-ROW($AK$2)+1),ROWS($A$3:B10))),"")} | C10: {=IFERROR( INDEX($AI$2:$AI$9999,SMALL(IF($AF$2:$AF$9999=$A$2, ROW($AI$2:$AI$9999)-ROW($AI$2)+1),ROWS($A$3:C10))),"")} | D10: {=IFERROR( INDEX($AH$2:$AH$9999,SMALL(IF($AF$2:$AF$9999=$D$2, ROW($AH$2:$AH$9999)-ROW($AH$2)+1),ROWS($D$3:D10))),"")} | E10: {=IFERROR( INDEX($AK$2:$AK$9999,SMALL(IF($AF$2:$AF$9999=$D$2, ROW($AK$2:$AK$9999)-ROW($AK$2)+1),ROWS($D$3:E10))),"")} | F10: {=IFERROR( INDEX($AI$2:$AI$9999,SMALL(IF($AF$2:$AF$9999=$D$2, ROW($AI$2:$AI$9999)-ROW($AI$2)+1),ROWS($F$3:F10))),"")} | G10: {=IFERROR( INDEX($AH$2:$AH$9999,SMALL(IF($AF$2:$AF$9999=$G$2, ROW($AH$2:$AH$9999)-ROW($AH$2)+1),ROWS($G$3:G10))),"")} | H10: {=IFERROR( INDEX($AK$2:$AK$9999,SMALL(IF($AF$2:$AF$9999=$G$2, ROW($AK$2:$AK$9999)-ROW($AK$2)+1),ROWS($G$3:H10))),"")} | I10: {=IFERROR( INDEX($AI$2:$AI$9999,SMALL(IF($AF$2:$AF$9999=$G$2, ROW($AI$2:$AI$9999)-ROW($AI$2)+1),ROWS($I$3:I10))),"")} | J10: {=IFERROR( INDEX($AH$2:$AH$9999,SMALL(IF($AF$2:$AF$9999=$J$2, ROW($AH$2:$AH$9999)-ROW($AH$2)+1),ROWS($J$3:J10))),"")} | K10: {=IFERROR( INDEX($AK$2:$AK$9999,SMALL(IF($AF$2:$AF$9999=$J$2, ROW($AK$2:$AK$9999)-ROW($AK$2)+1),ROWS($J$3:K10))),"")} | L10: {=IFERROR( INDEX($AI$2:$AI$9999,SMALL(IF($AF$2:$AF$9999=$J$2, ROW($AI$2:$AI$9999)-ROW($AI$2)+1),ROWS($L$3:L10))),"")} | M10: {=IFERROR( INDEX($AH$2:$AH$9999,SMALL(IF($AF$2:$AF$9999=$M$2, ROW($AH$2:$AH$9999)-ROW($AH$2)+1),ROWS($M$3:M10))),"")} | N10: {=IFERROR( INDEX($AK$2:$AK$9999,SMALL(IF($AF$2:$AF$9999=$M$2, ROW($AK$2:$AK$9999)-ROW($AK$2)+1),ROWS($M$3:N10))),"")} | O10: {=IFERROR( INDEX($AI$2:$AI$9999,SMALL(IF($AF$2:$AF$9999=$M$2, ROW($AI$2:$AI$9999)-ROW($AI$2)+1),ROWS($O$3:O10))),"")} | P10: {=IFERROR( INDEX($AH$2:$AH$9999,SMALL(IF($AF$2:$AF$9999=$P$2, ROW($AH$2:$AH$9999)-ROW($AH$2)+1),ROWS($P$3:P10))),"")} | Q10: {=IFERROR( INDEX($AK$2:$AK$9999,SMALL(IF($AF$2:$AF$9999=$P$2, ROW($AK$2:$AK$9999)-ROW($AK$2)+1),ROWS($P$3:Q10))),"")} | R10: {=IFERROR( INDEX($AI$2:$AI$9999,SMALL(IF($AF$2:$AF$9999=$P$2, ROW($AI$2:$AI$9999)-ROW($AI$2)+1),ROWS($R$3:R10))),"")} | S10: {=IFERROR( INDEX($AH$2:$AH$9999,SMALL(IF($AF$2:$AF$9999=$S$2, ROW($AH$2:$AH$9999)-ROW($AH$2)+1),ROWS($S$3:S10))),"")} | T10: {=IFERROR( INDEX($AK$2:$AK$9999,SMALL(IF($AF$2:$AF$9999=$S$2, ROW($AK$2:$AK$9999)-ROW($AK$2)+1),ROWS($S$3:T10))),"")} | U10: {=IFERROR( INDEX($AI$2:$AI$9999,SMALL(IF($AF$2:$AF$9999=$S$2, ROW($AI$2:$AI$9999)-ROW($AI$2)+1),ROWS($U$3:U10))),"")} | V10: {=IFERROR( INDEX($AH$2:$AH$9999,SMALL(IF($AF$2:$AF$9999=$V$2, ROW($AH$2:$AH$9999)-ROW($AH$2)+1),ROWS($V$3:V10))),"")} | W10: {=IFERROR( INDEX($AK$2:$AK$9999,SMALL(IF($AF$2:$AF$9999=$V$2, ROW($AK$2:$AK$9999)-ROW($AK$2)+1),ROWS($V$3:W10))),"")} | X10: {=IFERROR( INDEX($AI$2:$AI$9999,SMALL(IF($AF$2:$AF$9999=$V$2, ROW($AI$2:$AI$9999)-ROW($AI$2)+1),ROWS($X$3:X10))),"")} | Y10: {=IFERROR( INDEX($AH$2:$AH$9999,SMALL(IF($AF$2:$AF$9999=$Y$2, ROW($AH$2:$AH$9999)-ROW($AH$2)+1),ROWS($Y$3:Y10))),"")} | Z10: {=IFERROR( INDEX($AK$2:$AK$9999,SMALL(IF($AF$2:$AF$9999=$Y$2, ROW($AK$2:$AK$9999)-ROW($AK$2)+1),ROWS($Y$3:Z10))),"")} | AA10: {=IFERROR( INDEX($AI$2:$AI$9999,SMALL(IF($AF$2:$AF$9999=$Y$2, ROW($AI$2:$AI$9999)-ROW($AI$2)+1),ROWS($AA$3:AA10))),"")} | AB10: {=IFERROR( INDEX($AH$2:$AH$9999,SMALL(IF($AF$2:$AF$9999=$AB$2, ROW($AH$2:$AH$9999)-ROW($AH$2)+1),ROWS($AB$3:AB10))),"")} | AC10: {=IFERROR( INDEX($AK$2:$AK$9999,SMALL(IF($AF$2:$AF$9999=$AB$2, ROW($AK$2:$AK$9999)-ROW($AK$2)+1),ROWS($AB$3:AC10))),"")} | AD10: {=IFERROR( INDEX($AI$2:$AI$9999,SMALL(IF($AF$2:$AF$9999=$AB$2, ROW($AI$2:$AI$9999)-ROW($AI$2)+1),ROWS($AD$3:AD10))),"")} | AE10: ='(1)예금승인내역'!H640 -> 45348 | AF10: =VALUE(AE10) -> 45348 | AG10: ='(1)예금승인내역'!G640 -> 45316 | AH10: ='(1)예금승인내역'!F640 -> ㈜와이투솔루션 | AI10: ='(1)예금승인내역'!L640 -> 1 | AJ10: ='(1)예금승인내역'!AG640 -> 0.0515 | AK10: ='(1)예금승인내역'!K640 -> 정기예금
A11: {=IFERROR( INDEX($AH$2:$AH$9999,SMALL(IF($AF$2:$AF$9999=$A$2, ROW($AH$2:$AH$9999)-ROW($AH$2)+1),ROWS(A$3:$A11))),"")} | B11: {=IFERROR( INDEX($AK$2:$AK$9999,SMALL(IF($AF$2:$AF$9999=$A$2, ROW($AK$2:$AK$9999)-ROW($AK$2)+1),ROWS($A$3:B11))),"")} | C11: {=IFERROR( INDEX($AI$2:$AI$9999,SMALL(IF($AF$2:$AF$9999=$A$2, ROW($AI$2:$AI$9999)-ROW($AI$2)+1),ROWS($A$3:C11))),"")} | D11: {=IFERROR( INDEX($AH$2:$AH$9999,SMALL(IF($AF$2:$AF$9999=$D$2, ROW($AH$2:$AH$9999)-ROW($AH$2)+1),ROWS($D$3:D11))),"")} | E11: {=IFERROR( INDEX($AK$2:$AK$9999,SMALL(IF($AF$2:$AF$9999=$D$2, ROW($AK$2:$AK$9999)-ROW($AK$2)+1),ROWS($D$3:E11))),"")} | F11: {=IFERROR( INDEX($AI$2:$AI$9999,SMALL(IF($AF$2:$AF$9999=$D$2, ROW($AI$2:$AI$9999)-ROW($AI$2)+1),ROWS($F$3:F11))),"")} | G11: {=IFERROR( INDEX($AH$2:$AH$9999,SMALL(IF($AF$2:$AF$9999=$G$2, ROW($AH$2:$AH$9999)-ROW($AH$2)+1),ROWS($G$3:G11))),"")} | H11: {=IFERROR( INDEX($AK$2:$AK$9999,SMALL(IF($AF$2:$AF$9999=$G$2, ROW($AK$2:$AK$9999)-ROW($AK$2)+1),ROWS($G$3:H11))),"")} | I11: {=IFERROR( INDEX($AI$2:$AI$9999,SMALL(IF($AF$2:$AF$9999=$G$2, ROW($AI$2:$AI$9999)-ROW($AI$2)+1),ROWS($I$3:I11))),"")} | J11: {=IFERROR( INDEX($AH$2:$AH$9999,SMALL(IF($AF$2:$AF$9999=$J$2, ROW($AH$2:$AH$9999)-ROW($AH$2)+1),ROWS($J$3:J11))),"")} | K11: {=IFERROR( INDEX($AK$2:$AK$9999,SMALL(IF($AF$2:$AF$9999=$J$2, ROW($AK$2:$AK$9999)-ROW($AK$2)+1),ROWS($J$3:K11))),"")} | L11: {=IFERROR( INDEX($AI$2:$AI$9999,SMALL(IF($AF$2:$AF$9999=$J$2, ROW($AI$2:$AI$9999)-ROW($AI$2)+1),ROWS($L$3:L11))),"")} | M11: {=IFERROR( INDEX($AH$2:$AH$9999,SMALL(IF($AF$2:$AF$9999=$M$2, ROW($AH$2:$AH$9999)-ROW($AH$2)+1),ROWS($M$3:M11))),"")} | N11: {=IFERROR( INDEX($AK$2:$AK$9999,SMALL(IF($AF$2:$AF$9999=$M$2, ROW($AK$2:$AK$9999)-ROW($AK$2)+1),ROWS($M$3:N11))),"")} | O11: {=IFERROR( INDEX($AI$2:$AI$9999,SMALL(IF($AF$2:$AF$9999=$M$2, ROW($AI$2:$AI$9999)-ROW($AI$2)+1),ROWS($O$3:O11))),"")} | P11: {=IFERROR( INDEX($AH$2:$AH$9999,SMALL(IF($AF$2:$AF$9999=$P$2, ROW($AH$2:$AH$9999)-ROW($AH$2)+1),ROWS($P$3:P11))),"")} | Q11: {=IFERROR( INDEX($AK$2:$AK$9999,SMALL(IF($AF$2:$AF$9999=$P$2, ROW($AK$2:$AK$9999)-ROW($AK$2)+1),ROWS($P$3:Q11))),"")} | R11: {=IFERROR( INDEX($AI$2:$AI$9999,SMALL(IF($AF$2:$AF$9999=$P$2, ROW($AI$2:$AI$9999)-ROW($AI$2)+1),ROWS($R$3:R11))),"")} | S11: {=IFERROR( INDEX($AH$2:$AH$9999,SMALL(IF($AF$2:$AF$9999=$S$2, ROW($AH$2:$AH$9999)-ROW($AH$2)+1),ROWS($S$3:S11))),"")} | T11: {=IFERROR( INDEX($AK$2:$AK$9999,SMALL(IF($AF$2:$AF$9999=$S$2, ROW($AK$2:$AK$9999)-ROW($AK$2)+1),ROWS($S$3:T11))),"")} | U11: {=IFERROR( INDEX($AI$2:$AI$9999,SMALL(IF($AF$2:$AF$9999=$S$2, ROW($AI$2:$AI$9999)-ROW($AI$2)+1),ROWS($U$3:U11))),"")} | V11: {=IFERROR( INDEX($AH$2:$AH$9999,SMALL(IF($AF$2:$AF$9999=$V$2, ROW($AH$2:$AH$9999)-ROW($AH$2)+1),ROWS($V$3:V11))),"")} | W11: {=IFERROR( INDEX($AK$2:$AK$9999,SMALL(IF($AF$2:$AF$9999=$V$2, ROW($AK$2:$AK$9999)-ROW($AK$2)+1),ROWS($V$3:W11))),"")} | X11: {=IFERROR( INDEX($AI$2:$AI$9999,SMALL(IF($AF$2:$AF$9999=$V$2, ROW($AI$2:$AI$9999)-ROW($AI$2)+1),ROWS($X$3:X11))),"")} | Y11: {=IFERROR( INDEX($AH$2:$AH$9999,SMALL(IF($AF$2:$AF$9999=$Y$2, ROW($AH$2:$AH$9999)-ROW($AH$2)+1),ROWS($Y$3:Y11))),"")} | Z11: {=IFERROR( INDEX($AK$2:$AK$9999,SMALL(IF($AF$2:$AF$9999=$Y$2, ROW($AK$2:$AK$9999)-ROW($AK$2)+1),ROWS($Y$3:Z11))),"")} | AA11: {=IFERROR( INDEX($AI$2:$AI$9999,SMALL(IF($AF$2:$AF$9999=$Y$2, ROW($AI$2:$AI$9999)-ROW($AI$2)+1),ROWS($AA$3:AA11))),"")} | AB11: {=IFERROR( INDEX($AH$2:$AH$9999,SMALL(IF($AF$2:$AF$9999=$AB$2, ROW($AH$2:$AH$9999)-ROW($AH$2)+1),ROWS($AB$3:AB11))),"")} | AC11: {=IFERROR( INDEX($AK$2:$AK$9999,SMALL(IF($AF$2:$AF$9999=$AB$2, ROW($AK$2:$AK$9999)-ROW($AK$2)+1),ROWS($AB$3:AC11))),"")} | AD11: {=IFERROR( INDEX($AI$2:$AI$9999,SMALL(IF($AF$2:$AF$9999=$AB$2, ROW($AI$2:$AI$9999)-ROW($AI$2)+1),ROWS($AD$3:AD11))),"")} | AE11: ='(1)예금승인내역'!H641 -> 45348 | AF11: =VALUE(AE11) -> 45348 | AG11: ='(1)예금승인내역'!G641 -> 45316 | AH11: ='(1)예금승인내역'!F641 -> ㈜와이투솔루션 | AI11: ='(1)예금승인내역'!L641 -> 1 | AJ11: ='(1)예금승인내역'!AG641 -> 0.0515 | AK11: ='(1)예금승인내역'!K641 -> 정기예금
A12: {=IFERROR( INDEX($AH$2:$AH$9999,SMALL(IF($AF$2:$AF$9999=$A$2, ROW($AH$2:$AH$9999)-ROW($AH$2)+1),ROWS(A$3:$A12))),"")} | B12: {=IFERROR( INDEX($AK$2:$AK$9999,SMALL(IF($AF$2:$AF$9999=$A$2, ROW($AK$2:$AK$9999)-ROW($AK$2)+1),ROWS($A$3:B12))),"")} | C12: {=IFERROR( INDEX($AI$2:$AI$9999,SMALL(IF($AF$2:$AF$9999=$A$2, ROW($AI$2:$AI$9999)-ROW($AI$2)+1),ROWS($A$3:C12))),"")} | D12: {=IFERROR( INDEX($AH$2:$AH$9999,SMALL(IF($AF$2:$AF$9999=$D$2, ROW($AH$2:$AH$9999)-ROW($AH$2)+1),ROWS($D$3:D12))),"")} | E12: {=IFERROR( INDEX($AK$2:$AK$9999,SMALL(IF($AF$2:$AF$9999=$D$2, ROW($AK$2:$AK$9999)-ROW($AK$2)+1),ROWS($D$3:E12))),"")} | F12: {=IFERROR( INDEX($AI$2:$AI$9999,SMALL(IF($AF$2:$AF$9999=$D$2, ROW($AI$2:$AI$9999)-ROW($AI$2)+1),ROWS($F$3:F12))),"")} | G12: {=IFERROR( INDEX($AH$2:$AH$9999,SMALL(IF($AF$2:$AF$9999=$G$2, ROW($AH$2:$AH$9999)-ROW($AH$2)+1),ROWS($G$3:G12))),"")} | H12: {=IFERROR( INDEX($AK$2:$AK$9999,SMALL(IF($AF$2:$AF$9999=$G$2, ROW($AK$2:$AK$9999)-ROW($AK$2)+1),ROWS($G$3:H12))),"")} | I12: {=IFERROR( INDEX($AI$2:$AI$9999,SMALL(IF($AF$2:$AF$9999=$G$2, ROW($AI$2:$AI$9999)-ROW($AI$2)+1),ROWS($I$3:I12))),"")} | J12: {=IFERROR( INDEX($AH$2:$AH$9999,SMALL(IF($AF$2:$AF$9999=$J$2, ROW($AH$2:$AH$9999)-ROW($AH$2)+1),ROWS($J$3:J12))),"")} | K12: {=IFERROR( INDEX($AK$2:$AK$9999,SMALL(IF($AF$2:$AF$9999=$J$2, ROW($AK$2:$AK$9999)-ROW($AK$2)+1),ROWS($J$3:K12))),"")} | L12: {=IFERROR( INDEX($AI$2:$AI$9999,SMALL(IF($AF$2:$AF$9999=$J$2, ROW($AI$2:$AI$9999)-ROW($AI$2)+1),ROWS($L$3:L12))),"")} | M12: {=IFERROR( INDEX($AH$2:$AH$9999,SMALL(IF($AF$2:$AF$9999=$M$2, ROW($AH$2:$AH$9999)-ROW($AH$2)+1),ROWS($M$3:M12))),"")} | N12: {=IFERROR( INDEX($AK$2:$AK$9999,SMALL(IF($AF$2:$AF$9999=$M$2, ROW($AK$2:$AK$9999)-ROW($AK$2)+1),ROWS($M$3:N12))),"")} | O12: {=IFERROR( INDEX($AI$2:$AI$9999,SMALL(IF($AF$2:$AF$9999=$M$2, ROW($AI$2:$AI$9999)-ROW($AI$2)+1),ROWS($O$3:O12))),"")} | P12: {=IFERROR( INDEX($AH$2:$AH$9999,SMALL(IF($AF$2:$AF$9999=$P$2, ROW($AH$2:$AH$9999)-ROW($AH$2)+1),ROWS($P$3:P12))),"")} | Q12: {=IFERROR( INDEX($AK$2:$AK$9999,SMALL(IF($AF$2:$AF$9999=$P$2, ROW($AK$2:$AK$9999)-ROW($AK$2)+1),ROWS($P$3:Q12))),"")} | R12: {=IFERROR( INDEX($AI$2:$AI$9999,SMALL(IF($AF$2:$AF$9999=$P$2, ROW($AI$2:$AI$9999)-ROW($AI$2)+1),ROWS($R$3:R12))),"")} | S12: {=IFERROR( INDEX($AH$2:$AH$9999,SMALL(IF($AF$2:$AF$9999=$S$2, ROW($AH$2:$AH$9999)-ROW($AH$2)+1),ROWS($S$3:S12))),"")} | T12: {=IFERROR( INDEX($AK$2:$AK$9999,SMALL(IF($AF$2:$AF$9999=$S$2, ROW($AK$2:$AK$9999)-ROW($AK$2)+1),ROWS($S$3:T12))),"")} | U12: {=IFERROR( INDEX($AI$2:$AI$9999,SMALL(IF($AF$2:$AF$9999=$S$2, ROW($AI$2:$AI$9999)-ROW($AI$2)+1),ROWS($U$3:U12))),"")} | V12: {=IFERROR( INDEX($AH$2:$AH$9999,SMALL(IF($AF$2:$AF$9999=$V$2, ROW($AH$2:$AH$9999)-ROW($AH$2)+1),ROWS($V$3:V12))),"")} | W12: {=IFERROR( INDEX($AK$2:$AK$9999,SMALL(IF($AF$2:$AF$9999=$V$2, ROW($AK$2:$AK$9999)-ROW($AK$2)+1),ROWS($V$3:W12))),"")} | X12: {=IFERROR( INDEX($AI$2:$AI$9999,SMALL(IF($AF$2:$AF$9999=$V$2, ROW($AI$2:$AI$9999)-ROW($AI$2)+1),ROWS($X$3:X12))),"")} | Y12: {=IFERROR( INDEX($AH$2:$AH$9999,SMALL(IF($AF$2:$AF$9999=$Y$2, ROW($AH$2:$AH$9999)-ROW($AH$2)+1),ROWS($Y$3:Y12))),"")} | Z12: {=IFERROR( INDEX($AK$2:$AK$9999,SMALL(IF($AF$2:$AF$9999=$Y$2, ROW($AK$2:$AK$9999)-ROW($AK$2)+1),ROWS($Y$3:Z12))),"")} | AA12: {=IFERROR( INDEX($AI$2:$AI$9999,SMALL(IF($AF$2:$AF$9999=$Y$2, ROW($AI$2:$AI$9999)-ROW($AI$2)+1),ROWS($AA$3:AA12))),"")} | AB12: {=IFERROR( INDEX($AH$2:$AH$9999,SMALL(IF($AF$2:$AF$9999=$AB$2, ROW($AH$2:$AH$9999)-ROW($AH$2)+1),ROWS($AB$3:AB12))),"")} | AC12: {=IFERROR( INDEX($AK$2:$AK$9999,SMALL(IF($AF$2:$AF$9999=$AB$2, ROW($AK$2:$AK$9999)-ROW($AK$2)+1),ROWS($AB$3:AC12))),"")} | AD12: {=IFERROR( INDEX($AI$2:$AI$9999,SMALL(IF($AF$2:$AF$9999=$AB$2, ROW($AI$2:$AI$9999)-ROW($AI$2)+1),ROWS($AD$3:AD12))),"")} | AE12: ='(1)예금승인내역'!H642 -> 45348 | AF12: =VALUE(AE12) -> 45348 | AG12: ='(1)예금승인내역'!G642 -> 45316 | AH12: ='(1)예금승인내역'!F642 -> ㈜와이투솔루션 | AI12: ='(1)예금승인내역'!L642 -> 1 | AJ12: ='(1)예금승인내역'!AG642 -> 0.0515 | AK12: ='(1)예금승인내역'!K642 -> 정기예금
