Workbook

Sheet Sheet1

Sheet 인디가격
A1: [최종가격 자동계산]
A2: 통화쌍 | B2: USD/KRW | F2: 스프레드/월 → | G2: -5 | J2: 이론가 허용오차(%) → | K2: 50
A3: USD/KRW 환율 | B3: 1483.1 | D3: 날짜 | F3: 가격(MID) | G3: 스프레드 | H3: 가격(스프레드감안) | I3: 이종(대미환) | J3: 이종가격 | K3: 비고
A4: 이종통화 환율(대미환) | C4: 표준 결제일 | D4: 1 | F4: -80 | G4: =IF(OR($G$2="",D4=""),"",$G$2*D4) -> -5 | H4: =IF(F4="","",F4+IF(G4="",0,G4)) -> -85 | J4: =IF($F4="","",IF($B$2="","",IF($B$2="USD/KRW",H4,IF(OR($B$3="",$B$4="",$I4=""),"",IF($B$5="곱셈",ROUNDDOWN(($B$3+H4/100)*($B$4+$I4/$B$6),$B$7)-ROUNDDOWN($B$3*$B$4,$B$7),ROUNDDOWN(($B$3+H4/100)/($B$4+$I4/$B$6),$B$7)-ROUNDDOWN($B$3/$B$4,$B$7))*$B$8)))) -> -85 | K4: =IF(OR(J4="",$B$9="",$K$2=""),"",IF(ABS(J4-($B$9/100)*IF($B$2="USD/KRW",$B$3*100,IF($B$5="곱셈",$B$3*$B$4,$B$3/$B$4)*$B$8)*(D4/12))>MAX(ABS(($B$9/100)*IF($B$2="USD/KRW",$B$3*100,IF($B$5="곱셈",$B$3*$B$4,$B$3/$B$4)*$B$8)*(D4/12))*$K$2/100,IF($B$2="USD/KRW",30,2)),"⚠ 입력확인(이론가 "&ROUND(($B$9/100)*IF($B$2="USD/KRW",$B$3*100,IF($B$5="곱셈",$B$3*$B$4,$B$3/$B$4)*$B$8)*(D4/12),1)&")",""))
A5: 계산방식 | B5: =IFERROR(INDEX(통화설정!$B$2:$B$13,MATCH($B$2,통화설정!$A$2:$A$13,0)),"") -> - | D5: 2 | F5: -190 | G5: =IF(OR($G$2="",D5=""),"",$G$2*D5) -> -10 | H5: =IF(F5="","",F5+IF(G5="",0,G5)) -> -200 | J5: =IF($F5="","",IF($B$2="","",IF($B$2="USD/KRW",H5,IF(OR($B$3="",$B$4="",$I5=""),"",IF($B$5="곱셈",ROUNDDOWN(($B$3+H5/100)*($B$4+$I5/$B$6),$B$7)-ROUNDDOWN($B$3*$B$4,$B$7),ROUNDDOWN(($B$3+H5/100)/($B$4+$I5/$B$6),$B$7)-ROUNDDOWN($B$3/$B$4,$B$7))*$B$8)))) -> -200 | K5: =IF(OR(J5="",$B$9="",$K$2=""),"",IF(ABS(J5-($B$9/100)*IF($B$2="USD/KRW",$B$3*100,IF($B$5="곱셈",$B$3*$B$4,$B$3/$B$4)*$B$8)*(D5/12))>MAX(ABS(($B$9/100)*IF($B$2="USD/KRW",$B$3*100,IF($B$5="곱셈",$B$3*$B$4,$B$3/$B$4)*$B$8)*(D5/12))*$K$2/100,IF($B$2="USD/KRW",30,2)),"⚠ 입력확인(이론가 "&ROUND(($B$9/100)*IF($B$2="USD/KRW",$B$3*100,IF($B$5="곱셈",$B$3*$B$4,$B$3/$B$4)*$B$8)*(D5/12),1)&")",""))
A6: 핍단위 | B6: =IFERROR(INDEX(통화설정!$C$2:$C$13,MATCH($B$2,통화설정!$A$2:$A$13,0)),"") -> - | D6: 3 | F6: -320 | G6: =IF(OR($G$2="",D6=""),"",$G$2*D6) -> -15 | H6: =IF(F6="","",F6+IF(G6="",0,G6)) -> -335 | J6: =IF($F6="","",IF($B$2="","",IF($B$2="USD/KRW",H6,IF(OR($B$3="",$B$4="",$I6=""),"",IF($B$5="곱셈",ROUNDDOWN(($B$3+H6/100)*($B$4+$I6/$B$6),$B$7)-ROUNDDOWN($B$3*$B$4,$B$7),ROUNDDOWN(($B$3+H6/100)/($B$4+$I6/$B$6),$B$7)-ROUNDDOWN($B$3/$B$4,$B$7))*$B$8)))) -> -335 | K6: =IF(OR(J6="",$B$9="",$K$2=""),"",IF(ABS(J6-($B$9/100)*IF($B$2="USD/KRW",$B$3*100,IF($B$5="곱셈",$B$3*$B$4,$B$3/$B$4)*$B$8)*(D6/12))>MAX(ABS(($B$9/100)*IF($B$2="USD/KRW",$B$3*100,IF($B$5="곱셈",$B$3*$B$4,$B$3/$B$4)*$B$8)*(D6/12))*$K$2/100,IF($B$2="USD/KRW",30,2)),"⚠ 입력확인(이론가 "&ROUND(($B$9/100)*IF($B$2="USD/KRW",$B$3*100,IF($B$5="곱셈",$B$3*$B$4,$B$3/$B$4)*$B$8)*(D6/12),1)&")",""))
A7: 자릿수 | B7: =IFERROR(INDEX(통화설정!$D$2:$D$13,MATCH($B$2,통화설정!$A$2:$A$13,0)),"") -> - | D7: 4 | F7: -460 | G7: =IF(OR($G$2="",D7=""),"",$G$2*D7) -> -20 | H7: =IF(F7="","",F7+IF(G7="",0,G7)) -> -480 | J7: =IF($F7="","",IF($B$2="","",IF($B$2="USD/KRW",H7,IF(OR($B$3="",$B$4="",$I7=""),"",IF($B$5="곱셈",ROUNDDOWN(($B$3+H7/100)*($B$4+$I7/$B$6),$B$7)-ROUNDDOWN($B$3*$B$4,$B$7),ROUNDDOWN(($B$3+H7/100)/($B$4+$I7/$B$6),$B$7)-ROUNDDOWN($B$3/$B$4,$B$7))*$B$8)))) -> -480 | K7: =IF(OR(J7="",$B$9="",$K$2=""),"",IF(ABS(J7-($B$9/100)*IF($B$2="USD/KRW",$B$3*100,IF($B$5="곱셈",$B$3*$B$4,$B$3/$B$4)*$B$8)*(D7/12))>MAX(ABS(($B$9/100)*IF($B$2="USD/KRW",$B$3*100,IF($B$5="곱셈",$B$3*$B$4,$B$3/$B$4)*$B$8)*(D7/12))*$K$2/100,IF($B$2="USD/KRW",30,2)),"⚠ 입력확인(이론가 "&ROUND(($B$9/100)*IF($B$2="USD/KRW",$B$3*100,IF($B$5="곱셈",$B$3*$B$4,$B$3/$B$4)*$B$8)*(D7/12),1)&")",""))
A8: 표시배수 | B8: =IFERROR(INDEX(통화설정!$E$2:$E$13,MATCH($B$2,통화설정!$A$2:$A$13,0)),"") -> 1 | D8: 5 | F8: -579 | G8: =IF(OR($G$2="",D8=""),"",$G$2*D8) -> -25 | H8: =IF(F8="","",F8+IF(G8="",0,G8)) -> -604 | J8: =IF($F8="","",IF($B$2="","",IF($B$2="USD/KRW",H8,IF(OR($B$3="",$B$4="",$I8=""),"",IF($B$5="곱셈",ROUNDDOWN(($B$3+H8/100)*($B$4+$I8/$B$6),$B$7)-ROUNDDOWN($B$3*$B$4,$B$7),ROUNDDOWN(($B$3+H8/100)/($B$4+$I8/$B$6),$B$7)-ROUNDDOWN($B$3/$B$4,$B$7))*$B$8)))) -> -604 | K8: =IF(OR(J8="",$B$9="",$K$2=""),"",IF(ABS(J8-($B$9/100)*IF($B$2="USD/KRW",$B$3*100,IF($B$5="곱셈",$B$3*$B$4,$B$3/$B$4)*$B$8)*(D8/12))>MAX(ABS(($B$9/100)*IF($B$2="USD/KRW",$B$3*100,IF($B$5="곱셈",$B$3*$B$4,$B$3/$B$4)*$B$8)*(D8/12))*$K$2/100,IF($B$2="USD/KRW",30,2)),"⚠ 입력확인(이론가 "&ROUND(($B$9/100)*IF($B$2="USD/KRW",$B$3*100,IF($B$5="곱셈",$B$3*$B$4,$B$3/$B$4)*$B$8)*(D8/12),1)&")",""))
A9: 금리차(KRW-이종,%p) | B9: =IFERROR(통화설정!$H$2-INDEX(통화설정!$G$2:$G$13,MATCH($B$2,통화설정!$A$2:$A$13,0)),"") -> -1.125 | D9: 6 | F9: -720 | G9: =IF(OR($G$2="",D9=""),"",$G$2*D9) -> -30 | H9: =IF(F9="","",F9+IF(G9="",0,G9)) -> -750 | J9: =IF($F9="","",IF($B$2="","",IF($B$2="USD/KRW",H9,IF(OR($B$3="",$B$4="",$I9=""),"",IF($B$5="곱셈",ROUNDDOWN(($B$3+H9/100)*($B$4+$I9/$B$6),$B$7)-ROUNDDOWN($B$3*$B$4,$B$7),ROUNDDOWN(($B$3+H9/100)/($B$4+$I9/$B$6),$B$7)-ROUNDDOWN($B$3/$B$4,$B$7))*$B$8)))) -> -750 | K9: =IF(OR(J9="",$B$9="",$K$2=""),"",IF(ABS(J9-($B$9/100)*IF($B$2="USD/KRW",$B$3*100,IF($B$5="곱셈",$B$3*$B$4,$B$3/$B$4)*$B$8)*(D9/12))>MAX(ABS(($B$9/100)*IF($B$2="USD/KRW",$B$3*100,IF($B$5="곱셈",$B$3*$B$4,$B$3/$B$4)*$B$8)*(D9/12))*$K$2/100,IF($B$2="USD/KRW",30,2)),"⚠ 입력확인(이론가 "&ROUND(($B$9/100)*IF($B$2="USD/KRW",$B$3*100,IF($B$5="곱셈",$B$3*$B$4,$B$3/$B$4)*$B$8)*(D9/12),1)&")",""))
A10: 키움 | B10: 15 | D10: 7 | F10: -831 | G10: =IF(OR($G$2="",D10=""),"",$G$2*D10) -> -35 | H10: =IF(F10="","",F10+IF(G10="",0,G10)) -> -866 | J10: =IF($F10="","",IF($B$2="","",IF($B$2="USD/KRW",H10,IF(OR($B$3="",$B$4="",$I10=""),"",IF($B$5="곱셈",ROUNDDOWN(($B$3+H10/100)*($B$4+$I10/$B$6),$B$7)-ROUNDDOWN($B$3*$B$4,$B$7),ROUNDDOWN(($B$3+H10/100)/($B$4+$I10/$B$6),$B$7)-ROUNDDOWN($B$3/$B$4,$B$7))*$B$8)))) -> -866 | K10: =IF(OR(J10="",$B$9="",$K$2=""),"",IF(ABS(J10-($B$9/100)*IF($B$2="USD/KRW",$B$3*100,IF($B$5="곱셈",$B$3*$B$4,$B$3/$B$4)*$B$8)*(D10/12))>MAX(ABS(($B$9/100)*IF($B$2="USD/KRW",$B$3*100,IF($B$5="곱셈",$B$3*$B$4,$B$3/$B$4)*$B$8)*(D10/12))*$K$2/100,IF($B$2="USD/KRW",30,2)),"⚠ 입력확인(이론가 "&ROUND(($B$9/100)*IF($B$2="USD/KRW",$B$3*100,IF($B$5="곱셈",$B$3*$B$4,$B$3/$B$4)*$B$8)*(D10/12),1)&")",""))
A11: 하나 | B11: 8 | D11: 8 | F11: -937 | G11: =IF(OR($G$2="",D11=""),"",$G$2*D11) -> -40 | H11: =IF(F11="","",F11+IF(G11="",0,G11)) -> -977 | J11: =IF($F11="","",IF($B$2="","",IF($B$2="USD/KRW",H11,IF(OR($B$3="",$B$4="",$I11=""),"",IF($B$5="곱셈",ROUNDDOWN(($B$3+H11/100)*($B$4+$I11/$B$6),$B$7)-ROUNDDOWN($B$3*$B$4,$B$7),ROUNDDOWN(($B$3+H11/100)/($B$4+$I11/$B$6),$B$7)-ROUNDDOWN($B$3/$B$4,$B$7))*$B$8)))) -> -977 | K11: =IF(OR(J11="",$B$9="",$K$2=""),"",IF(ABS(J11-($B$9/100)*IF($B$2="USD/KRW",$B$3*100,IF($B$5="곱셈",$B$3*$B$4,$B$3/$B$4)*$B$8)*(D11/12))>MAX(ABS(($B$9/100)*IF($B$2="USD/KRW",$B$3*100,IF($B$5="곱셈",$B$3*$B$4,$B$3/$B$4)*$B$8)*(D11/12))*$K$2/100,IF($B$2="USD/KRW",30,2)),"⚠ 입력확인(이론가 "&ROUND(($B$9/100)*IF($B$2="USD/KRW",$B$3*100,IF($B$5="곱셈",$B$3*$B$4,$B$3/$B$4)*$B$8)*(D11/12),1)&")","")) | L11: <사용법>
A12: 흥국 | B12: 12 | D12: 9 | F12: -1060 | G12: =IF(OR($G$2="",D12=""),"",$G$2*D12) -> -45 | H12: =IF(F12="","",F12+IF(G12="",0,G12)) -> -1105 | J12: =IF($F12="","",IF($B$2="","",IF($B$2="USD/KRW",H12,IF(OR($B$3="",$B$4="",$I12=""),"",IF($B$5="곱셈",ROUNDDOWN(($B$3+H12/100)*($B$4+$I12/$B$6),$B$7)-ROUNDDOWN($B$3*$B$4,$B$7),ROUNDDOWN(($B$3+H12/100)/($B$4+$I12/$B$6),$B$7)-ROUNDDOWN($B$3/$B$4,$B$7))*$B$8)))) -> -1105 | K12: =IF(OR(J12="",$B$9="",$K$2=""),"",IF(ABS(J12-($B$9/100)*IF($B$2="USD/KRW",$B$3*100,IF($B$5="곱셈",$B$3*$B$4,$B$3/$B$4)*$B$8)*(D12/12))>MAX(ABS(($B$9/100)*IF($B$2="USD/KRW",$B$3*100,IF($B$5="곱셈",$B$3*$B$4,$B$3/$B$4)*$B$8)*(D12/12))*$K$2/100,IF($B$2="USD/KRW",30,2)),"⚠ 입력확인(이론가 "&ROUND(($B$9/100)*IF($B$2="USD/KRW",$B$3*100,IF($B$5="곱셈",$B$3*$B$4,$B$3/$B$4)*$B$8)*(D12/12),1)&")","")) | L12: 1. 노란색 셀 입력: 통화쌍 선택, 현물환율 2개
A13: 우리(각각) | B13: 8 | D13: 10 | F13: -1159 | G13: =IF(OR($G$2="",D13=""),"",$G$2*D13) -> -50 | H13: =IF(F13="","",F13+IF(G13="",0,G13)) -> -1209 | J13: =IF($F13="","",IF($B$2="","",IF($B$2="USD/KRW",H13,IF(OR($B$3="",$B$4="",$I13=""),"",IF($B$5="곱셈",ROUNDDOWN(($B$3+H13/100)*($B$4+$I13/$B$6),$B$7)-ROUNDDOWN($B$3*$B$4,$B$7),ROUNDDOWN(($B$3+H13/100)/($B$4+$I13/$B$6),$B$7)-ROUNDDOWN($B$3/$B$4,$B$7))*$B$8)))) -> -1209 | K13: =IF(OR(J13="",$B$9="",$K$2=""),"",IF(ABS(J13-($B$9/100)*IF($B$2="USD/KRW",$B$3*100,IF($B$5="곱셈",$B$3*$B$4,$B$3/$B$4)*$B$8)*(D13/12))>MAX(ABS(($B$9/100)*IF($B$2="USD/KRW",$B$3*100,IF($B$5="곱셈",$B$3*$B$4,$B$3/$B$4)*$B$8)*(D13/12))*$K$2/100,IF($B$2="USD/KRW",30,2)),"⚠ 입력확인(이론가 "&ROUND(($B$9/100)*IF($B$2="USD/KRW",$B$3*100,IF($B$5="곱셈",$B$3*$B$4,$B$3/$B$4)*$B$8)*(D13/12),1)&")","")) | L13: 2. F열(MID)·G열(스프레드)·I열(이종 대미환 스왑포인트) 입력
A14: 카디안(각각) | B14: 13 | D14: 11 | F14: -1271 | G14: =IF(OR($G$2="",D14=""),"",$G$2*D14) -> -55 | H14: =IF(F14="","",F14+IF(G14="",0,G14)) -> -1326 | J14: =IF($F14="","",IF($B$2="","",IF($B$2="USD/KRW",H14,IF(OR($B$3="",$B$4="",$I14=""),"",IF($B$5="곱셈",ROUNDDOWN(($B$3+H14/100)*($B$4+$I14/$B$6),$B$7)-ROUNDDOWN($B$3*$B$4,$B$7),ROUNDDOWN(($B$3+H14/100)/($B$4+$I14/$B$6),$B$7)-ROUNDDOWN($B$3/$B$4,$B$7))*$B$8)))) -> -1326 | K14: =IF(OR(J14="",$B$9="",$K$2=""),"",IF(ABS(J14-($B$9/100)*IF($B$2="USD/KRW",$B$3*100,IF($B$5="곱셈",$B$3*$B$4,$B$3/$B$4)*$B$8)*(D14/12))>MAX(ABS(($B$9/100)*IF($B$2="USD/KRW",$B$3*100,IF($B$5="곱셈",$B$3*$B$4,$B$3/$B$4)*$B$8)*(D14/12))*$K$2/100,IF($B$2="USD/KRW",30,2)),"⚠ 입력확인(이론가 "&ROUND(($B$9/100)*IF($B$2="USD/KRW",$B$3*100,IF($B$5="곱셈",$B$3*$B$4,$B$3/$B$4)*$B$8)*(D14/12),1)&")","")) | L14: 3. H열(=F+G)과 J열(최종가격)은 자동 계산
A15: 한국투신 | B15: 5 | D15: 12 | F15: -1390 | G15: =IF(OR($G$2="",D15=""),"",$G$2*D15) -> -60 | H15: =IF(F15="","",F15+IF(G15="",0,G15)) -> -1450 | J15: =IF($F15="","",IF($B$2="","",IF($B$2="USD/KRW",H15,IF(OR($B$3="",$B$4="",$I15=""),"",IF($B$5="곱셈",ROUNDDOWN(($B$3+H15/100)*($B$4+$I15/$B$6),$B$7)-ROUNDDOWN($B$3*$B$4,$B$7),ROUNDDOWN(($B$3+H15/100)/($B$4+$I15/$B$6),$B$7)-ROUNDDOWN($B$3/$B$4,$B$7))*$B$8)))) -> -1450 | K15: =IF(OR(J15="",$B$9="",$K$2=""),"",IF(ABS(J15-($B$9/100)*IF($B$2="USD/KRW",$B$3*100,IF($B$5="곱셈",$B$3*$B$4,$B$3/$B$4)*$B$8)*(D15/12))>MAX(ABS(($B$9/100)*IF($B$2="USD/KRW",$B$3*100,IF($B$5="곱셈",$B$3*$B$4,$B$3/$B$4)*$B$8)*(D15/12))*$K$2/100,IF($B$2="USD/KRW",30,2)),"⚠ 입력확인(이론가 "&ROUND(($B$9/100)*IF($B$2="USD/KRW",$B$3*100,IF($B$5="곱셈",$B$3*$B$4,$B$3/$B$4)*$B$8)*(D15/12),1)&")","")) | L15: ※ USD/KRW 선택 시 이종환율·I열 불필요 (J=H)
A16: 유진 | B16: 15 | F16: 스프레드/월 → | L16: 4. 통화설정 시트에 정책금리 입력 시, 금리차 기반 이론가와 크게 다르면 K열(비고)에 ⚠ 경고
A17: IBK | C17: 비표준 결제일 | D17: 46255 | E17: =IF(D17="","",ROUND(YEARFRAC(TODAY(),D17,1)*12,0)&"M") -> 1M | F17: -80 | G17: =IF(OR($G$16="",E17=""),"",$G$16*VALUE(SUBSTITUTE(E17,"M",""))) | H17: =IF(F17="","",F17+IF(G17="",0,G17)) -> -80 | J17: =IF($F17="","",IF($B$2="","",IF($B$2="USD/KRW",H17,IF(OR($B$3="",$B$4="",$I17=""),"",IF($B$5="곱셈",ROUNDDOWN(($B$3+H17/100)*($B$4+$I17/$B$6),$B$7)-ROUNDDOWN($B$3*$B$4,$B$7),ROUNDDOWN(($B$3+H17/100)/($B$4+$I17/$B$6),$B$7)-ROUNDDOWN($B$3/$B$4,$B$7))*$B$8)))) -> -80 | K17: =IF(OR(J17="",$B$9="",$K$2="",E17=""),"",IF(ABS(J17-($B$9/100)*IF($B$2="USD/KRW",$B$3*100,IF($B$5="곱셈",$B$3*$B$4,$B$3/$B$4)*$B$8)*(VALUE(SUBSTITUTE(E17,"M",""))/12))>MAX(ABS(($B$9/100)*IF($B$2="USD/KRW",$B$3*100,IF($B$5="곱셈",$B$3*$B$4,$B$3/$B$4)*$B$8)*(VALUE(SUBSTITUTE(E17,"M",""))/12))*$K$2/100,IF($B$2="USD/KRW",30,2)),"⚠ 입력확인(이론가 "&ROUND(($B$9/100)*IF($B$2="USD/KRW",$B$3*100,IF($B$5="곱셈",$B$3*$B$4,$B$3/$B$4)*$B$8)*(VALUE(SUBSTITUTE(E17,"M",""))/12),1)&")",""))
A18: 다올 | B18: 10 | D18: 46286 | E18: =IF(D18="","",ROUND(YEARFRAC(TODAY(),D18,1)*12,0)&"M") -> 2M | F18: -190 | G18: =IF(OR($G$16="",E18=""),"",$G$16*VALUE(SUBSTITUTE(E18,"M",""))) | H18: =IF(F18="","",F18+IF(G18="",0,G18)) -> -190 | J18: =IF($F18="","",IF($B$2="","",IF($B$2="USD/KRW",H18,IF(OR($B$3="",$B$4="",$I18=""),"",IF($B$5="곱셈",ROUNDDOWN(($B$3+H18/100)*($B$4+$I18/$B$6),$B$7)-ROUNDDOWN($B$3*$B$4,$B$7),ROUNDDOWN(($B$3+H18/100)/($B$4+$I18/$B$6),$B$7)-ROUNDDOWN($B$3/$B$4,$B$7))*$B$8)))) -> -190 | K18: =IF(OR(J18="",$B$9="",$K$2="",E18=""),"",IF(ABS(J18-($B$9/100)*IF($B$2="USD/KRW",$B$3*100,IF($B$5="곱셈",$B$3*$B$4,$B$3/$B$4)*$B$8)*(VALUE(SUBSTITUTE(E18,"M",""))/12))>MAX(ABS(($B$9/100)*IF($B$2="USD/KRW",$B$3*100,IF($B$5="곱셈",$B$3*$B$4,$B$3/$B$4)*$B$8)*(VALUE(SUBSTITUTE(E18,"M",""))/12))*$K$2/100,IF($B$2="USD/KRW",30,2)),"⚠ 입력확인(이론가 "&ROUND(($B$9/100)*IF($B$2="USD/KRW",$B$3*100,IF($B$5="곱셈",$B$3*$B$4,$B$3/$B$4)*$B$8)*(VALUE(SUBSTITUTE(E18,"M",""))/12),1)&")",""))
A19: 삼성 | B19: 7 | D19: 46316 | E19: =IF(D19="","",ROUND(YEARFRAC(TODAY(),D19,1)*12,0)&"M") -> 3M | F19: -320 | G19: =IF(OR($G$16="",E19=""),"",$G$16*VALUE(SUBSTITUTE(E19,"M",""))) | H19: =IF(F19="","",F19+IF(G19="",0,G19)) -> -320 | J19: =IF($F19="","",IF($B$2="","",IF($B$2="USD/KRW",H19,IF(OR($B$3="",$B$4="",$I19=""),"",IF($B$5="곱셈",ROUNDDOWN(($B$3+H19/100)*($B$4+$I19/$B$6),$B$7)-ROUNDDOWN($B$3*$B$4,$B$7),ROUNDDOWN(($B$3+H19/100)/($B$4+$I19/$B$6),$B$7)-ROUNDDOWN($B$3/$B$4,$B$7))*$B$8)))) -> -320 | K19: =IF(OR(J19="",$B$9="",$K$2="",E19=""),"",IF(ABS(J19-($B$9/100)*IF($B$2="USD/KRW",$B$3*100,IF($B$5="곱셈",$B$3*$B$4,$B$3/$B$4)*$B$8)*(VALUE(SUBSTITUTE(E19,"M",""))/12))>MAX(ABS(($B$9/100)*IF($B$2="USD/KRW",$B$3*100,IF($B$5="곱셈",$B$3*$B$4,$B$3/$B$4)*$B$8)*(VALUE(SUBSTITUTE(E19,"M",""))/12))*$K$2/100,IF($B$2="USD/KRW",30,2)),"⚠ 입력확인(이론가 "&ROUND(($B$9/100)*IF($B$2="USD/KRW",$B$3*100,IF($B$5="곱셈",$B$3*$B$4,$B$3/$B$4)*$B$8)*(VALUE(SUBSTITUTE(E19,"M",""))/12),1)&")",""))
A20: 파인만 | D20: 46349 | E20: =IF(D20="","",ROUND(YEARFRAC(TODAY(),D20,1)*12,0)&"M") -> 4M | F20: -460 | G20: =IF(OR($G$16="",E20=""),"",$G$16*VALUE(SUBSTITUTE(E20,"M",""))) | H20: =IF(F20="","",F20+IF(G20="",0,G20)) -> -460 | J20: =IF($F20="","",IF($B$2="","",IF($B$2="USD/KRW",H20,IF(OR($B$3="",$B$4="",$I20=""),"",IF($B$5="곱셈",ROUNDDOWN(($B$3+H20/100)*($B$4+$I20/$B$6),$B$7)-ROUNDDOWN($B$3*$B$4,$B$7),ROUNDDOWN(($B$3+H20/100)/($B$4+$I20/$B$6),$B$7)-ROUNDDOWN($B$3/$B$4,$B$7))*$B$8)))) -> -460 | K20: =IF(OR(J20="",$B$9="",$K$2="",E20=""),"",IF(ABS(J20-($B$9/100)*IF($B$2="USD/KRW",$B$3*100,IF($B$5="곱셈",$B$3*$B$4,$B$3/$B$4)*$B$8)*(VALUE(SUBSTITUTE(E20,"M",""))/12))>MAX(ABS(($B$9/100)*IF($B$2="USD/KRW",$B$3*100,IF($B$5="곱셈",$B$3*$B$4,$B$3/$B$4)*$B$8)*(VALUE(SUBSTITUTE(E20,"M",""))/12))*$K$2/100,IF($B$2="USD/KRW",30,2)),"⚠ 입력확인(이론가 "&ROUND(($B$9/100)*IF($B$2="USD/KRW",$B$3*100,IF($B$5="곱셈",$B$3*$B$4,$B$3/$B$4)*$B$8)*(VALUE(SUBSTITUTE(E20,"M",""))/12),1)&")",""))
A21: 현대(각각) | B21: 10 | D21: 46377 | E21: =IF(D21="","",ROUND(YEARFRAC(TODAY(),D21,1)*12,0)&"M") -> 5M | F21: -579 | G21: =IF(OR($G$16="",E21=""),"",$G$16*VALUE(SUBSTITUTE(E21,"M",""))) | H21: =IF(F21="","",F21+IF(G21="",0,G21)) -> -579 | J21: =IF($F21="","",IF($B$2="","",IF($B$2="USD/KRW",H21,IF(OR($B$3="",$B$4="",$I21=""),"",IF($B$5="곱셈",ROUNDDOWN(($B$3+H21/100)*($B$4+$I21/$B$6),$B$7)-ROUNDDOWN($B$3*$B$4,$B$7),ROUNDDOWN(($B$3+H21/100)/($B$4+$I21/$B$6),$B$7)-ROUNDDOWN($B$3/$B$4,$B$7))*$B$8)))) -> -579 | K21: =IF(OR(J21="",$B$9="",$K$2="",E21=""),"",IF(ABS(J21-($B$9/100)*IF($B$2="USD/KRW",$B$3*100,IF($B$5="곱셈",$B$3*$B$4,$B$3/$B$4)*$B$8)*(VALUE(SUBSTITUTE(E21,"M",""))/12))>MAX(ABS(($B$9/100)*IF($B$2="USD/KRW",$B$3*100,IF($B$5="곱셈",$B$3*$B$4,$B$3/$B$4)*$B$8)*(VALUE(SUBSTITUTE(E21,"M",""))/12))*$K$2/100,IF($B$2="USD/KRW",30,2)),"⚠ 입력확인(이론가 "&ROUND(($B$9/100)*IF($B$2="USD/KRW",$B$3*100,IF($B$5="곱셈",$B$3*$B$4,$B$3/$B$4)*$B$8)*(VALUE(SUBSTITUTE(E21,"M",""))/12),1)&")",""))
A22: 한화(각각) | B22: 10 | D22: 46408 | E22: =IF(D22="","",ROUND(YEARFRAC(TODAY(),D22,1)*12,0)&"M") -> 6M | F22: -720 | G22: =IF(OR($G$16="",E22=""),"",$G$16*VALUE(SUBSTITUTE(E22,"M",""))) | H22: =IF(F22="","",F22+IF(G22="",0,G22)) -> -720 | J22: =IF($F22="","",IF($B$2="","",IF($B$2="USD/KRW",H22,IF(OR($B$3="",$B$4="",$I22=""),"",IF($B$5="곱셈",ROUNDDOWN(($B$3+H22/100)*($B$4+$I22/$B$6),$B$7)-ROUNDDOWN($B$3*$B$4,$B$7),ROUNDDOWN(($B$3+H22/100)/($B$4+$I22/$B$6),$B$7)-ROUNDDOWN($B$3/$B$4,$B$7))*$B$8)))) -> -720 | K22: =IF(OR(J22="",$B$9="",$K$2="",E22=""),"",IF(ABS(J22-($B$9/100)*IF($B$2="USD/KRW",$B$3*100,IF($B$5="곱셈",$B$3*$B$4,$B$3/$B$4)*$B$8)*(VALUE(SUBSTITUTE(E22,"M",""))/12))>MAX(ABS(($B$9/100)*IF($B$2="USD/KRW",$B$3*100,IF($B$5="곱셈",$B$3*$B$4,$B$3/$B$4)*$B$8)*(VALUE(SUBSTITUTE(E22,"M",""))/12))*$K$2/100,IF($B$2="USD/KRW",30,2)),"⚠ 입력확인(이론가 "&ROUND(($B$9/100)*IF($B$2="USD/KRW",$B$3*100,IF($B$5="곱셈",$B$3*$B$4,$B$3/$B$4)*$B$8)*(VALUE(SUBSTITUTE(E22,"M",""))/12),1)&")",""))
A23: KB(18개월) | B23: 10 | E23: =IF(D23="","",ROUND(YEARFRAC(TODAY(),D23,1)*12,0)&"M") | G23: =IF(OR($G$16="",E23=""),"",$G$16*VALUE(SUBSTITUTE(E23,"M",""))) | H23: =IF(F23="","",F23+IF(G23="",0,G23)) | J23: =IF($F23="","",IF($B$2="","",IF($B$2="USD/KRW",H23,IF(OR($B$3="",$B$4="",$I23=""),"",IF($B$5="곱셈",ROUNDDOWN(($B$3+H23/100)*($B$4+$I23/$B$6),$B$7)-ROUNDDOWN($B$3*$B$4,$B$7),ROUNDDOWN(($B$3+H23/100)/($B$4+$I23/$B$6),$B$7)-ROUNDDOWN($B$3/$B$4,$B$7))*$B$8)))) | K23: =IF(OR(J23="",$B$9="",$K$2="",E23=""),"",IF(ABS(J23-($B$9/100)*IF($B$2="USD/KRW",$B$3*100,IF($B$5="곱셈",$B$3*$B$4,$B$3/$B$4)*$B$8)*(VALUE(SUBSTITUTE(E23,"M",""))/12))>MAX(ABS(($B$9/100)*IF($B$2="USD/KRW",$B$3*100,IF($B$5="곱셈",$B$3*$B$4,$B$3/$B$4)*$B$8)*(VALUE(SUBSTITUTE(E23,"M",""))/12))*$K$2/100,IF($B$2="USD/KRW",30,2)),"⚠ 입력확인(이론가 "&ROUND(($B$9/100)*IF($B$2="USD/KRW",$B$3*100,IF($B$5="곱셈",$B$3*$B$4,$B$3/$B$4)*$B$8)*(VALUE(SUBSTITUTE(E23,"M",""))/12),1)&")",""))
A24: 신한 | E24: =IF(D24="","",ROUND(YEARFRAC(TODAY(),D24,1)*12,0)&"M") | G24: =IF(OR($G$16="",E24=""),"",$G$16*VALUE(SUBSTITUTE(E24,"M",""))) | H24: =IF(F24="","",F24+IF(G24="",0,G24)) | J24: =IF($F24="","",IF($B$2="","",IF($B$2="USD/KRW",H24,IF(OR($B$3="",$B$4="",$I24=""),"",IF($B$5="곱셈",ROUNDDOWN(($B$3+H24/100)*($B$4+$I24/$B$6),$B$7)-ROUNDDOWN($B$3*$B$4,$B$7),ROUNDDOWN(($B$3+H24/100)/($B$4+$I24/$B$6),$B$7)-ROUNDDOWN($B$3/$B$4,$B$7))*$B$8)))) | K24: =IF(OR(J24="",$B$9="",$K$2="",E24=""),"",IF(ABS(J24-($B$9/100)*IF($B$2="USD/KRW",$B$3*100,IF($B$5="곱셈",$B$3*$B$4,$B$3/$B$4)*$B$8)*(VALUE(SUBSTITUTE(E24,"M",""))/12))>MAX(ABS(($B$9/100)*IF($B$2="USD/KRW",$B$3*100,IF($B$5="곱셈",$B$3*$B$4,$B$3/$B$4)*$B$8)*(VALUE(SUBSTITUTE(E24,"M",""))/12))*$K$2/100,IF($B$2="USD/KRW",30,2)),"⚠ 입력확인(이론가 "&ROUND(($B$9/100)*IF($B$2="USD/KRW",$B$3*100,IF($B$5="곱셈",$B$3*$B$4,$B$3/$B$4)*$B$8)*(VALUE(SUBSTITUTE(E24,"M",""))/12),1)&")",""))
A25: 미래에셋 | B25: 5 | E25: =IF(D25="","",ROUND(YEARFRAC(TODAY(),D25,1)*12,0)&"M") | G25: =IF(OR($G$16="",E25=""),"",$G$16*VALUE(SUBSTITUTE(E25,"M",""))) | H25: =IF(F25="","",F25+IF(G25="",0,G25)) | J25: =IF($F25="","",IF($B$2="","",IF($B$2="USD/KRW",H25,IF(OR($B$3="",$B$4="",$I25=""),"",IF($B$5="곱셈",ROUNDDOWN(($B$3+H25/100)*($B$4+$I25/$B$6),$B$7)-ROUNDDOWN($B$3*$B$4,$B$7),ROUNDDOWN(($B$3+H25/100)/($B$4+$I25/$B$6),$B$7)-ROUNDDOWN($B$3/$B$4,$B$7))*$B$8)))) | K25: =IF(OR(J25="",$B$9="",$K$2="",E25=""),"",IF(ABS(J25-($B$9/100)*IF($B$2="USD/KRW",$B$3*100,IF($B$5="곱셈",$B$3*$B$4,$B$3/$B$4)*$B$8)*(VALUE(SUBSTITUTE(E25,"M",""))/12))>MAX(ABS(($B$9/100)*IF($B$2="USD/KRW",$B$3*100,IF($B$5="곱셈",$B$3*$B$4,$B$3/$B$4)*$B$8)*(VALUE(SUBSTITUTE(E25,"M",""))/12))*$K$2/100,IF($B$2="USD/KRW",30,2)),"⚠ 입력확인(이론가 "&ROUND(($B$9/100)*IF($B$2="USD/KRW",$B$3*100,IF($B$5="곱셈",$B$3*$B$4,$B$3/$B$4)*$B$8)*(VALUE(SUBSTITUTE(E25,"M",""))/12),1)&")",""))
A26: 유리(각각) | B26: 20/25/35 | E26: =IF(D26="","",ROUND(YEARFRAC(TODAY(),D26,1)*12,0)&"M") | G26: =IF(OR($G$16="",E26=""),"",$G$16*VALUE(SUBSTITUTE(E26,"M",""))) | H26: =IF(F26="","",F26+IF(G26="",0,G26)) | J26: =IF($F26="","",IF($B$2="","",IF($B$2="USD/KRW",H26,IF(OR($B$3="",$B$4="",$I26=""),"",IF($B$5="곱셈",ROUNDDOWN(($B$3+H26/100)*($B$4+$I26/$B$6),$B$7)-ROUNDDOWN($B$3*$B$4,$B$7),ROUNDDOWN(($B$3+H26/100)/($B$4+$I26/$B$6),$B$7)-ROUNDDOWN($B$3/$B$4,$B$7))*$B$8)))) | K26: =IF(OR(J26="",$B$9="",$K$2="",E26=""),"",IF(ABS(J26-($B$9/100)*IF($B$2="USD/KRW",$B$3*100,IF($B$5="곱셈",$B$3*$B$4,$B$3/$B$4)*$B$8)*(VALUE(SUBSTITUTE(E26,"M",""))/12))>MAX(ABS(($B$9/100)*IF($B$2="USD/KRW",$B$3*100,IF($B$5="곱셈",$B$3*$B$4,$B$3/$B$4)*$B$8)*(VALUE(SUBSTITUTE(E26,"M",""))/12))*$K$2/100,IF($B$2="USD/KRW",30,2)),"⚠ 입력확인(이론가 "&ROUND(($B$9/100)*IF($B$2="USD/KRW",$B$3*100,IF($B$5="곱셈",$B$3*$B$4,$B$3/$B$4)*$B$8)*(VALUE(SUBSTITUTE(E26,"M",""))/12),1)&")",""))
A27: DB | B27: 5 | E27: =IF(D27="","",ROUND(YEARFRAC(TODAY(),D27,1)*12,0)&"M") | G27: =IF(OR($G$16="",E27=""),"",$G$16*VALUE(SUBSTITUTE(E27,"M",""))) | H27: =IF(F27="","",F27+IF(G27="",0,G27)) | J27: =IF($F27="","",IF($B$2="","",IF($B$2="USD/KRW",H27,IF(OR($B$3="",$B$4="",$I27=""),"",IF($B$5="곱셈",ROUNDDOWN(($B$3+H27/100)*($B$4+$I27/$B$6),$B$7)-ROUNDDOWN($B$3*$B$4,$B$7),ROUNDDOWN(($B$3+H27/100)/($B$4+$I27/$B$6),$B$7)-ROUNDDOWN($B$3/$B$4,$B$7))*$B$8)))) | K27: =IF(OR(J27="",$B$9="",$K$2="",E27=""),"",IF(ABS(J27-($B$9/100)*IF($B$2="USD/KRW",$B$3*100,IF($B$5="곱셈",$B$3*$B$4,$B$3/$B$4)*$B$8)*(VALUE(SUBSTITUTE(E27,"M",""))/12))>MAX(ABS(($B$9/100)*IF($B$2="USD/KRW",$B$3*100,IF($B$5="곱셈",$B$3*$B$4,$B$3/$B$4)*$B$8)*(VALUE(SUBSTITUTE(E27,"M",""))/12))*$K$2/100,IF($B$2="USD/KRW",30,2)),"⚠ 입력확인(이론가 "&ROUND(($B$9/100)*IF($B$2="USD/KRW",$B$3*100,IF($B$5="곱셈",$B$3*$B$4,$B$3/$B$4)*$B$8)*(VALUE(SUBSTITUTE(E27,"M",""))/12),1)&")",""))
C28: 결제일 1년이내★(표준) | G28: USD가격 | J28: 이종가격 | M28: JPY/KRW
E29: =IF(F29="","",ROUND((F29-TODAY())/30.4,0)&"M") -> 1M | F29: 46255 | G29: -90 | H29: =IF(I29="","",ROUND((I29-TODAY())/30.4,0)&"M") -> 1M | I29: 46255 | J29: -118.85 | K29: =IF(L29="","",ROUND((L29-TODAY())/30.4,0)&"M") -> 3M | L29: 46316 | M29: =J29/100 -> -1.1885
E30: =IF(F30="","",ROUND((F30-TODAY())/30.4,0)&"M") -> 2M | F30: 46286 | G30: -208 | H30: =IF(I30="","",ROUND((I30-TODAY())/30.4,0)&"M") -> 2M | I30: 46286 | J30: -162.65 | K30: =IF(L30="","",ROUND((L30-TODAY())/30.4,0)&"M") -> 4M | L30: 46349 | M30: =J30/100 -> -1.6265
E31: =IF(F31="","",ROUND((F31-TODAY())/30.4,0)&"M") -> 3M | F31: 46316 | G31: -343 | H31: =IF(I31="","",ROUND((I31-TODAY())/30.4,0)&"M") -> 3M | I31: 46316 | J31: -197.43 | K31: =IF(L31="","",ROUND((L31-TODAY())/30.4,0)&"M") | M31: =J31/100 -> -1.9743
E32: =IF(F32="","",ROUND((F32-TODAY())/30.4,0)&"M") -> 4M | F32: 46349 | G32: -493 | H32: =IF(I32="","",ROUND((I32-TODAY())/30.4,0)&"M") -> 4M | I32: 46349 | J32: -240.9 | K32: =IF(L32="","",ROUND((L32-TODAY())/30.4,0)&"M") | M32: =J32/100 -> -2.409
E33: =IF(F33="","",ROUND((F33-TODAY())/30.4,0)&"M") -> 5M | F33: 46377 | G33: -622 | H33: =IF(I33="","",ROUND((I33-TODAY())/30.4,0)&"M") | K33: =IF(L33="","",ROUND((L33-TODAY())/30.4,0)&"M") | M33: =J33/100 -> 0
E34: =IF(F34="","",ROUND((F34-TODAY())/30.4,0)&"M") -> 6M | F34: 46408 | G34: -775 | H34: =IF(I34="","",ROUND((I34-TODAY())/30.4,0)&"M") | K34: =IF(L34="","",ROUND((L34-TODAY())/30.4,0)&"M") | M34: =J34/100 -> 0
H35: =IF(I35="","",ROUND((I35-TODAY())/30.4,0)&"M") | K35: =IF(L35="","",ROUND((L35-TODAY())/30.4,0)&"M") | M35: =J35/100 -> 0
E36: =IF(F36="","",ROUND((F36-TODAY())/30.4,0)&"M") | H36: =IF(I36="","",ROUND((I36-TODAY())/30.4,0)&"M") | K36: =IF(L36="","",ROUND((L36-TODAY())/30.4,0)&"M") | M36: =J36/100 -> 0
E37: =IF(F37="","",ROUND((F37-TODAY())/30.4,0)&"M") | H37: =IF(I37="","",ROUND((I37-TODAY())/30.4,0)&"M") | K37: =IF(L37="","",ROUND((L37-TODAY())/30.4,0)&"M") | M37: =J37/100 -> 0
E38: =IF(F38="","",ROUND((F38-TODAY())/30.4,0)&"M") | H38: =IF(I38="","",ROUND((I38-TODAY())/30.4,0)&"M") | K38: =IF(L38="","",ROUND((L38-TODAY())/30.4,0)&"M") | M38: =J38/100 -> 0
E39: =IF(F39="","",ROUND((F39-TODAY())/30.4,0)&"M") | H39: =IF(I39="","",ROUND((I39-TODAY())/30.4,0)&"M") | K39: =IF(L39="","",ROUND((L39-TODAY())/30.4,0)&"M") | M39: =J39/100 -> 0
E40: =IF(F40="","",ROUND((F40-TODAY())/30.4,0)&"M") | H40: =IF(I40="","",ROUND((I40-TODAY())/30.4,0)&"M") | K40: =IF(L40="","",ROUND((L40-TODAY())/30.4,0)&"M") | M40: =J40/100 -> 0
...

Sheet 통화설정
A1: 통화쌍 | B1: 계산방식 | C1: 이종 핍단위 | D1: 반올림 자릿수 | E1: 표시배수 | F1: 비고 | G1: 이종통화 정책금리(%) | H1: 한국 기준금리(%)
A2: USD/KRW | B2: - | C2: - | D2: - | E2: 1 | F2: 이종환율 불필요, 스프레드감안(H)가 최종가격 | G2: 3.625 | H2: 2.5
A3: CNH/KRW | B3: 나눗셈 | C3: 10000 | D3: 2 | E3: 1 | F3: USD/CNH 환율 입력 | G3: 1.4
A4: CNY/KRW | B4: 나눗셈 | C4: 10000 | D4: 2 | E4: 1 | F4: USD/CNY 환율 입력 | G4: 1.4
A5: JPY/KRW | B5: 나눗셈 | C5: 100 | D5: 4 | E5: 100 | F5: USD/JPY 환율 입력, 100엔당 표시 | G5: 0.75
A6: EUR/KRW | B6: 곱셈 | C6: 10000 | D6: 2 | E6: 1 | F6: EUR/USD 환율 입력 | G6: 2
A7: AUD/KRW | B7: 곱셈 | C7: 10000 | D7: 2 | E7: 1 | F7: AUD/USD 환율 입력 | G7: 3.6
A8: GBP/KRW | B8: 곱셈 | C8: 10000 | D8: 2 | E8: 1 | F8: GBP/USD 환율 입력 | G8: 3.75
A9: NZD/KRW | B9: 곱셈 | C9: 10000 | D9: 2 | E9: 1 | F9: NZD/USD 환율 입력 | G9: 2.25
A10: HKD/KRW | B10: 나눗셈 | C10: 10000 | D10: 2 | E10: 1 | F10: USD/HKD 환율 입력 | G10: 3.75
A11: SGD/KRW | B11: 나눗셈 | C11: 10000 | D11: 2 | E11: 1 | F11: USD/SGD 환율 입력 | G11: 1.5
A12: CHF/KRW | B12: 나눗셈 | C12: 10000 | D12: 2 | E12: 1 | F12: USD/CHF 환율 입력 | G12: 0
A13: CAD/KRW | B13: 나눗셈 | C13: 10000 | D13: 2 | E13: 1 | F13: USD/CAD 환율 입력 | G13: 2.25
A15: ※ 재정환율계산기의 계산식과 동일: 최종가격 = ROUNDDOWN(원화선물환/이종선물환) - ROUNDDOWN(원화현물/이종현물) | G15: ※ 정책금리는 참고용 예시값(2026.1 기준) — 반드시 최신 금리로 수정해서 사용
A16: ※ 곱셈 통화(EUR, AUD, GBP, NZD)는 대미환이 XXX/USD로 고시되므로 곱셈 적용
